File: Thesis/Heat_Treatment/DSC/ExpDat_Au_sample-2cooling.txt
#FILE:Au_samp.ngb-ds3
#FORMAT:NETZSCH5
#FTYPE:ASCII
#IDENTITY:pureAu
#DECIMAL:POINT
#SEPARATOR:SEMICOLON
#MTYPE:DSC
#INSTRUMENT:NETZSCH STA 449F3
#PROJECT:MET
#DATE/TIME:01.12.2017 17:26
#CORR. FILE:Au.ngb-bs3
#LABORATORY:DB
#OPERATOR:Shalini
#REMARK:
#SAMPLE:pureAu
#SAMPLE MASS /mg:37.480
#MATERIAL:
#REFERENCE:Shalini
#REFERENCE MASS /mg:0.002
#TYPE OF CRUCIBLE:DSC/TG pan Al2O3
#SAMPLE CRUCIBLE MASS /mg:0.0
#REFERENCE CRUCIBLE MASS /mg:0.0
#CORR. CODE:020
#EXO:+1
#RANGE:1100/10.0(K/min)/  25
#SEGMENT:S2/2

##Temp./oC;Time/min;DSC/(mW/mg);Sensit./(uV/mW)
  70.28300;212.49333;1.2282e-002;0.95137
  71.18391;212.27073;1.2456e-002;0.95098
  72.08481;212.05417;1.2394e-002;0.95058
  72.98572;211.84006;1.2704e-002;0.95019
  73.88663;211.62784;1.2878e-002;0.94979
  74.78754;211.42126;1.2959e-002;0.94939
  75.68845;211.21605;1.3125e-002;0.94899
  76.58936;211.01267;1.3434e-002;0.94860
  77.49027;210.81584;1.3291e-002;0.94820
  78.39118;210.61996;1.3467e-002;0.94780
  79.29208;210.42712;1.3820e-002;0.94740
  80.19299;210.23579;1.3917e-002;0.94700
  81.09390;210.04846;1.4107e-002;0.94660
  81.99481;209.86131;1.4454e-002;0.94619
  82.89572;209.67731;1.4550e-002;0.94579
  83.79663;209.49802;1.4667e-002;0.94539
  84.69754;209.31954;1.5140e-002;0.94498
  85.59845;209.14509;1.5002e-002;0.94458
  86.49935;208.97321;1.5111e-002;0.94418
  87.40026;208.80220;1.5318e-002;0.94377
  88.30117;208.63405;1.5551e-002;0.94336
  89.20208;208.46850;1.5840e-002;0.94296
  90.10299;208.30484;1.5960e-002;0.94255
  91.00390;208.14280;1.6228e-002;0.94214
  91.90481;207.98370;1.6863e-002;0.94174
  92.80571;207.82513;1.6864e-002;0.94133
  93.70662;207.66981;1.7203e-002;0.94092
  94.60753;207.51275;1.7427e-002;0.94051
  95.50844;207.35967;1.7823e-002;0.94010
  96.40935;207.20817;1.8342e-002;0.93969
  97.31026;207.05851;1.8453e-002;0.93928
  98.21117;206.90815;1.8461e-002;0.93886
  99.11208;206.76102;1.8714e-002;0.93845
 100.01298;206.61670;1.9118e-002;0.93804
 100.91389;206.47305;1.9476e-002;0.93763
 101.81480;206.33052;1.9849e-002;0.93721
 102.71571;206.18968;2.0057e-002;0.93680
 103.61662;206.04988;2.0434e-002;0.93638
 104.51753;205.91120;2.0511e-002;0.93597
 105.41844;205.77385;2.0671e-002;0.93555
 106.31935;205.63773;2.0884e-002;0.93513
 107.22025;205.50387;2.1067e-002;0.93472
 108.12116;205.37119;2.1310e-002;0.93430
 109.02207;205.23868;2.1454e-002;0.93388
 109.92298;205.10718;2.2063e-002;0.93346
 110.82389;204.97825;2.1934e-002;0.93304
 111.72480;204.84974;2.2219e-002;0.93262
 112.62571;204.72009;2.2274e-002;0.93220
 113.52661;204.59447;2.2657e-002;0.93178
 114.42752;204.46729;2.2993e-002;0.93136
 115.32843;204.34168;2.3424e-002;0.93094
 116.22934;204.21885;2.3105e-002;0.93051
 117.13025;204.09547;2.3385e-002;0.93009
 118.03116;203.97429;2.3404e-002;0.92967
 118.93207;203.85365;2.3897e-002;0.92924
 119.83298;203.73410;2.4063e-002;0.92882
 120.73388;203.61488;2.4249e-002;0.92839
 121.63479;203.49814;2.4316e-002;0.92797
 122.53570;203.38052;2.4602e-002;0.92754
 123.43661;203.26544;2.4824e-002;0.92711
 124.33752;203.15001;2.4888e-002;0.92669
 125.23843;203.03647;2.5162e-002;0.92626
 126.13934;202.92401;2.5592e-002;0.92583
 127.04025;202.81084;2.5393e-002;0.92540
 127.94115;202.70020;2.5241e-002;0.92497
 128.84206;202.58988;2.5212e-002;0.92454
 129.74297;202.47936;2.5324e-002;0.92411
 130.64388;202.37039;2.5318e-002;0.92368
 131.54479;202.26230;2.5580e-002;0.92325
 132.44570;202.15458;2.5690e-002;0.92282
 133.34661;202.04784;2.5791e-002;0.92239
 134.24752;201.94177;2.5797e-002;0.92196
 135.14842;201.83682;2.6112e-002;0.92152
 136.04933;201.73279;2.6163e-002;0.92109
 136.95024;201.62886;2.6241e-002;0.92066
 137.85115;201.52534;2.6308e-002;0.92022
 138.75206;201.42362;2.6429e-002;0.91979
 139.65297;201.32173;2.6812e-002;0.91935
 140.55388;201.22002;2.6959e-002;0.91891
 141.45478;201.12002;2.7238e-002;0.91848
 142.35569;201.02009;2.7405e-002;0.91804
 143.25660;200.92018;2.7796e-002;0.91760
 144.15751;200.82120;2.7891e-002;0.91717
 145.05842;200.72305;2.7823e-002;0.91673
 145.95933;200.62458;2.8192e-002;0.91629
 146.86024;200.52789;2.8279e-002;0.91585
 147.76115;200.43123;2.8457e-002;0.91541
 148.66205;200.33485;2.8688e-002;0.91497
 149.56296;200.23932;2.8806e-002;0.91453
 150.46387;200.14414;2.8924e-002;0.91409
 151.36478;200.04934;2.9155e-002;0.91365
 152.26569;199.95512;2.9188e-002;0.91320
 153.16660;199.86032;2.9234e-002;0.91276
 154.06751;199.76685;2.9478e-002;0.91232
 154.96842;199.67335;2.9489e-002;0.91188
 155.86932;199.58035;2.9413e-002;0.91143
 156.77023;199.48732;2.9738e-002;0.91099
 157.67114;199.39550;2.9621e-002;0.91054
 158.57205;199.30298;2.9971e-002;0.91010
 159.47296;199.21009;2.9896e-002;0.90965
 160.37387;199.11861;2.9912e-002;0.90921
 161.27478;199.02719;3.0211e-002;0.90876
 162.17568;198.93610;2.9999e-002;0.90831
 163.07659;198.84363;3.0201e-002;0.90787
 163.97750;198.75234;2.9996e-002;0.90742
 164.87841;198.66114;3.0203e-002;0.90697
 165.77932;198.57037;3.0339e-002;0.90652
 166.68023;198.47907;3.0335e-002;0.90607
 167.58114;198.38790;3.0444e-002;0.90562
 168.48205;198.29694;3.0493e-002;0.90517
 169.38295;198.20617;3.0535e-002;0.90472
 170.28386;198.11541;3.0666e-002;0.90427
 171.18477;198.02451;3.1042e-002;0.90382
 172.08568;197.93371;3.1115e-002;0.90337
 172.98659;197.84276;3.1386e-002;0.90292
 173.88750;197.75223;3.1216e-002;0.90246
 174.78841;197.66092;3.1246e-002;0.90201
 175.68932;197.57051;3.0861e-002;0.90156
 176.59022;197.47921;3.0818e-002;0.90110
 177.49113;197.38893;3.0366e-002;0.90065
 178.39204;197.29815;3.0175e-002;0.90020
 179.29295;197.20735;3.0406e-002;0.89974
 180.19386;197.11643;3.0062e-002;0.89929
 181.09477;197.02575;3.0112e-002;0.89883
 181.99568;196.93492;3.0197e-002;0.89837
 182.89659;196.84449;2.9856e-002;0.89792
 183.79749;196.75382;2.9777e-002;0.89746
 184.69840;196.66366;2.9794e-002;0.89700
 185.59931;196.57381;2.9804e-002;0.89655
 186.50022;196.48367;2.9916e-002;0.89609
 187.40113;196.39302;2.9798e-002;0.89563
 188.30204;196.30225;2.9954e-002;0.89517
 189.20295;196.21201;3.0073e-002;0.89471
 190.10385;196.12135;3.0268e-002;0.89425
 191.00476;196.03016;3.0430e-002;0.89379
 191.90567;195.94023;3.0560e-002;0.89333
 192.80658;195.84917;3.0756e-002;0.89287
 193.70749;195.75915;3.0597e-002;0.89241
 194.60840;195.66874;3.0873e-002;0.89195
 195.50931;195.57832;3.0855e-002;0.89148
 196.41022;195.48804;3.0908e-002;0.89102
 197.31112;195.39704;3.0789e-002;0.89056
 198.21203;195.30676;3.1239e-002;0.89010
 199.11294;195.21661;3.1142e-002;0.88963
 200.01385;195.12579;3.1321e-002;0.88917
 200.91476;195.03480;3.1490e-002;0.88870
 201.81567;194.94438;3.1726e-002;0.88824
 202.71658;194.85399;3.1848e-002;0.88777
 203.61749;194.76397;3.1820e-002;0.88731
 204.51839;194.67411;3.1969e-002;0.88684
 205.41930;194.58330;3.2060e-002;0.88638
 206.32021;194.49292;3.2397e-002;0.88591
 207.22112;194.40240;3.2513e-002;0.88544
 208.12203;194.31183;3.2765e-002;0.88498
 209.02294;194.22184;3.2838e-002;0.88451
 209.92385;194.13044;3.2991e-002;0.88404
 210.82475;194.03982;3.3177e-002;0.88357
 211.72566;193.94932;3.3060e-002;0.88310
 212.62657;193.85896;3.3106e-002;0.88263
 213.52748;193.76824;3.3095e-002;0.88217
 214.42839;193.67807;3.3273e-002;0.88170
 215.32930;193.58698;3.3221e-002;0.88123
 216.23021;193.49720;3.3167e-002;0.88075
 217.13112;193.40629;3.3470e-002;0.88028
 218.03202;193.31592;3.3643e-002;0.87981
 218.93293;193.22518;3.3912e-002;0.87934
 219.83384;193.13422;3.4321e-002;0.87887
 220.73475;193.04362;3.4823e-002;0.87840
 221.63566;192.95316;3.4800e-002;0.87793
 222.53657;192.86309;3.4893e-002;0.87745
 223.43748;192.77299;3.4749e-002;0.87698
 224.33839;192.68252;3.4467e-002;0.87651
 225.23929;192.59101;3.4468e-002;0.87603
 226.14020;192.50080;3.4252e-002;0.87556
 227.04111;192.41088;3.4002e-002;0.87508
 227.94202;192.32013;3.3910e-002;0.87461
 228.84293;192.22915;3.3811e-002;0.87413
 229.74384;192.13921;3.3975e-002;0.87366
 230.64475;192.04886;3.3680e-002;0.87318
 231.54566;191.95844;3.3321e-002;0.87271
 232.44656;191.86759;3.3045e-002;0.87223
 233.34747;191.77669;3.2995e-002;0.87175
 234.24838;191.68689;3.3198e-002;0.87128
 235.14929;191.59615;3.3233e-002;0.87080
 236.05020;191.50588;3.3225e-002;0.87032
 236.95111;191.41540;3.3344e-002;0.86984
 237.85202;191.32502;3.3191e-002;0.86936
 238.75292;191.23492;3.2948e-002;0.86889
 239.65383;191.14414;3.3188e-002;0.86841
 240.55474;191.05340;3.3280e-002;0.86793
 241.45565;190.96388;3.3392e-002;0.86745
 242.35656;190.87335;3.3928e-002;0.86697
 243.25747;190.78272;3.3796e-002;0.86649
 244.15838;190.69272;3.4222e-002;0.86601
 245.05929;190.60203;3.4263e-002;0.86553
 245.96019;190.51141;3.4257e-002;0.86505
 246.86110;190.42070;3.4444e-002;0.86456
 247.76201;190.33055;3.4303e-002;0.86408
 248.66292;190.24103;3.4134e-002;0.86360
 249.56383;190.14935;3.4143e-002;0.86312
 250.46474;190.05895;3.4452e-002;0.86264
 251.36565;189.96836;3.4310e-002;0.86215
 252.26656;189.87797;3.4587e-002;0.86167
 253.16746;189.78714;3.4814e-002;0.86119
 254.06837;189.69704;3.5055e-002;0.86070
 254.96928;189.60736;3.5392e-002;0.86022
 255.87019;189.51678;3.5394e-002;0.85974
 256.77110;189.42582;3.5264e-002;0.85925
 257.67201;189.33500;3.5630e-002;0.85877
 258.57292;189.24452;3.5517e-002;0.85828
 259.47382;189.15396;3.5413e-002;0.85780
 260.37473;189.06311;3.5403e-002;0.85731
 261.27564;188.97295;3.5477e-002;0.85682
 262.17655;188.88376;3.5534e-002;0.85634
 263.07746;188.79255;3.5637e-002;0.85585
 263.97837;188.70203;3.6071e-002;0.85536
 264.87928;188.61217;3.6298e-002;0.85488
 265.78019;188.52222;3.6350e-002;0.85439
 266.68109;188.43197;3.6694e-002;0.85390
 267.58200;188.34186;3.6719e-002;0.85341
 268.48291;188.25165;3.6724e-002;0.85293
 269.38382;188.16146;3.6487e-002;0.85244
 270.28473;188.07055;3.6811e-002;0.85195
 271.18564;187.98094;3.6823e-002;0.85146
 272.08655;187.89068;3.6527e-002;0.85097
 272.98746;187.80060;3.6634e-002;0.85048
 273.88836;187.71015;3.6640e-002;0.84999
 274.78927;187.61981;3.6639e-002;0.84950
 275.69018;187.52916;3.7081e-002;0.84901
 276.59109;187.43872;3.7258e-002;0.84852
 277.49200;187.34849;3.6889e-002;0.84803
 278.39291;187.25832;3.7095e-002;0.84754
 279.29382;187.16852;3.7150e-002;0.84705
 280.19473;187.07822;3.7388e-002;0.84656
 281.09563;186.98763;3.7243e-002;0.84607
 281.99654;186.89709;3.7238e-002;0.84558
 282.89745;186.80716;3.7002e-002;0.84508
 283.79836;186.71689;3.7216e-002;0.84459
 284.69927;186.62649;3.6897e-002;0.84410
 285.60018;186.53616;3.6915e-002;0.84361
 286.50109;186.44540;3.6635e-002;0.84311
 287.40199;186.35489;3.6887e-002;0.84262
 288.30290;186.26504;3.7135e-002;0.84213
 289.20381;186.17471;3.7193e-002;0.84163
 290.10472;186.08416;3.7318e-002;0.84114
 291.00563;185.99382;3.7237e-002;0.84064
 291.90654;185.90307;3.7383e-002;0.84015
 292.80745;185.81236;3.7526e-002;0.83965
 293.70836;185.72209;3.7474e-002;0.83916
 294.60926;185.63189;3.7435e-002;0.83866
 295.51017;185.54168;3.7697e-002;0.83817
 296.41108;185.45086;3.7599e-002;0.83767
 297.31199;185.36066;3.7396e-002;0.83718
 298.21290;185.27059;3.7785e-002;0.83668
 299.11381;185.17986;3.7733e-002;0.83619
 300.01472;185.08903;3.7877e-002;0.83569
 300.91563;184.99911;3.8108e-002;0.83519
 301.81653;184.90916;3.7802e-002;0.83470
 302.71744;184.81868;3.7907e-002;0.83420
 303.61835;184.72874;3.7713e-002;0.83370
 304.51926;184.63865;3.7655e-002;0.83320
 305.42017;184.54786;3.7981e-002;0.83271
 306.32108;184.45768;3.7868e-002;0.83221
 307.22199;184.36722;3.7796e-002;0.83171
 308.12289;184.27632;3.8180e-002;0.83121
 309.02380;184.18614;3.8353e-002;0.83071
 309.92471;184.09614;3.8418e-002;0.83022
 310.82562;184.00621;3.8516e-002;0.82972
 311.72653;183.91576;3.8799e-002;0.82922
 312.62744;183.82520;3.8903e-002;0.82872
 313.52835;183.73463;3.8719e-002;0.82822
 314.42926;183.64406;3.8793e-002;0.82772
 315.33016;183.55440;3.8990e-002;0.82722
 316.23107;183.46379;3.8737e-002;0.82672
 317.13198;183.37303;3.8634e-002;0.82622
 318.03289;183.28296;3.8905e-002;0.82572
 318.93380;183.19286;3.9067e-002;0.82522
 319.83471;183.10308;3.8829e-002;0.82472
 320.73562;183.01270;3.9166e-002;0.82422
 321.63653;182.92231;3.9420e-002;0.82371
 322.53743;182.83179;3.9558e-002;0.82321
 323.43834;182.74145;3.9472e-002;0.82271
 324.33925;182.65111;3.9764e-002;0.82221
 325.24016;182.56077;3.9591e-002;0.82171
 326.14107;182.47074;3.9759e-002;0.82121
 327.04198;182.38037;3.9954e-002;0.82070
 327.94289;182.28976;3.9708e-002;0.82020
 328.84380;182.19957;3.9485e-002;0.81970
 329.74470;182.11006;3.9634e-002;0.81920
 330.64561;182.01977;3.9483e-002;0.81869
 331.54652;181.92890;3.9597e-002;0.81819
 332.44743;181.83909;3.9907e-002;0.81769
 333.34834;181.74898;4.0205e-002;0.81718
 334.24925;181.65902;4.0378e-002;0.81668
 335.15016;181.56863;4.0104e-002;0.81618
 336.05106;181.47867;4.0330e-002;0.81567
 336.95197;181.38814;4.0608e-002;0.81517
 337.85288;181.29790;4.0845e-002;0.81466
 338.75379;181.20713;4.1376e-002;0.81416
 339.65470;181.11699;4.1458e-002;0.81365
 340.55561;181.02644;4.1329e-002;0.81315
 341.45652;180.93603;4.1551e-002;0.81265
 342.35743;180.84521;4.1679e-002;0.81214
 343.25833;180.75485;4.1584e-002;0.81164
 344.15924;180.66427;4.1926e-002;0.81113
 345.06015;180.57386;4.2215e-002;0.81062
 345.96106;180.48440;4.2095e-002;0.81012
 346.86197;180.39380;4.2006e-002;0.80961
 347.76288;180.30365;4.2191e-002;0.80911
 348.66379;180.21394;4.2318e-002;0.80860
 349.56470;180.12371;4.2397e-002;0.80809
 350.46560;180.03308;4.2268e-002;0.80759
 351.36651;179.94282;4.2929e-002;0.80708
 352.26742;179.85330;4.3105e-002;0.80658
 353.16833;179.76262;4.3346e-002;0.80607
 354.06924;179.67256;4.3739e-002;0.80556
 354.97015;179.58196;4.4249e-002;0.80505
 355.87106;179.49150;4.4439e-002;0.80455
 356.77196;179.40101;4.4765e-002;0.80404
 357.67287;179.31049;4.5113e-002;0.80353
 358.57378;179.22014;4.5298e-002;0.80303
 359.47469;179.13014;4.5531e-002;0.80252
 360.37560;179.03949;4.5554e-002;0.80201
 361.27651;178.94929;4.5849e-002;0.80150
 362.17742;178.85927;4.5929e-002;0.80099
 363.07833;178.76920;4.6186e-002;0.80049
 363.97923;178.67869;4.6231e-002;0.79998
 364.88014;178.58869;4.6740e-002;0.79947
 365.78105;178.49759;4.6676e-002;0.79896
 366.68196;178.40771;4.7142e-002;0.79845
 367.58287;178.31774;4.6960e-002;0.79794
 368.48378;178.22770;4.6887e-002;0.79743
 369.38469;178.13732;4.6675e-002;0.79692
 370.28560;178.04757;4.6189e-002;0.79642
 371.18650;177.95748;4.5704e-002;0.79591
 372.08741;177.86724;4.5892e-002;0.79540
 372.98832;177.77695;4.5612e-002;0.79489
 373.88923;177.68628;4.5841e-002;0.79438
 374.79014;177.59614;4.5577e-002;0.79387
 375.69105;177.50611;4.5732e-002;0.79336
 376.59196;177.41613;4.5567e-002;0.79285
 377.49287;177.32614;4.5241e-002;0.79234
 378.39377;177.23566;4.5008e-002;0.79183
 379.29468;177.14504;4.5148e-002;0.79132
 380.19559;177.05511;4.5046e-002;0.79081
 381.09650;176.96431;4.4992e-002;0.79030
 381.99741;176.87438;4.5309e-002;0.78979
 382.89832;176.78471;4.4975e-002;0.78928
 383.79923;176.69445;4.5284e-002;0.78876
 384.70013;176.60425;4.5090e-002;0.78825
 385.60104;176.51356;4.5040e-002;0.78774
 386.50195;176.42372;4.5220e-002;0.78723
 387.40286;176.33368;4.5318e-002;0.78672
 388.30377;176.24344;4.5492e-002;0.78621
 389.20468;176.15271;4.5612e-002;0.78570
 390.10559;176.06283;4.5537e-002;0.78519
 391.00650;175.97326;4.5554e-002;0.78468
 391.90740;175.88232;4.5604e-002;0.78416
 392.80831;175.79197;4.5522e-002;0.78365
 393.70922;175.70220;4.5472e-002;0.78314
 394.61013;175.61212;4.5418e-002;0.78263
 395.51104;175.52143;4.5765e-002;0.78212
 396.41195;175.43127;4.5599e-002;0.78161
 397.31286;175.34081;4.5449e-002;0.78109
 398.21377;175.25066;4.5781e-002;0.78058
 399.11467;175.16021;4.5878e-002;0.78007
 400.01558;175.07004;4.6062e-002;0.77956
 400.91649;174.97904;4.6046e-002;0.77904
 401.81740;174.88904;4.5958e-002;0.77853
 402.71831;174.79912;4.6234e-002;0.77802
 403.61922;174.70855;4.6643e-002;0.77751
 404.52013;174.61846;4.6714e-002;0.77699
 405.42103;174.52824;4.7059e-002;0.77648
 406.32194;174.43746;4.7108e-002;0.77597
 407.22285;174.34739;4.7341e-002;0.77546
 408.12376;174.25756;4.7530e-002;0.77494
 409.02467;174.16808;4.7294e-002;0.77443
 409.92558;174.07746;4.7607e-002;0.77392
 410.82649;173.98789;4.7845e-002;0.77340
 411.72740;173.89757;4.8522e-002;0.77289
 412.62830;173.80769;4.8470e-002;0.77238
 413.52921;173.71721;4.8684e-002;0.77186
 414.43012;173.62757;4.9071e-002;0.77135
 415.33103;173.53651;4.9277e-002;0.77084
 416.23194;173.44699;4.9601e-002;0.77032
 417.13285;173.35721;4.9557e-002;0.76981
 418.03376;173.26682;4.9641e-002;0.76930
 418.93467;173.17634;4.9460e-002;0.76878
 419.83557;173.08644;4.9469e-002;0.76827
 420.73648;172.99577;4.9632e-002;0.76776
 421.63739;172.90497;4.9470e-002;0.76724
 422.53830;172.81519;4.9646e-002;0.76673
 423.43921;172.72500;4.9745e-002;0.76621
 424.34012;172.63431;4.9791e-002;0.76570
 425.24103;172.54335;5.0039e-002;0.76519
 426.14194;172.45292;5.0475e-002;0.76467
 427.04284;172.36307;5.0453e-002;0.76416
 427.94375;172.27266;5.0407e-002;0.76364
 428.84466;172.18250;5.0546e-002;0.76313
 429.74557;172.09255;5.0782e-002;0.76261
 430.64648;172.00251;5.0610e-002;0.76210
 431.54739;171.91214;5.0598e-002;0.76159
 432.44830;171.82225;5.0747e-002;0.76107
 433.34920;171.73207;5.0757e-002;0.76056
 434.25011;171.64235;5.1017e-002;0.76004
 435.15102;171.55174;5.0853e-002;0.75953
 436.05193;171.46086;5.0767e-002;0.75901
 436.95284;171.37023;5.0855e-002;0.75850
 437.85375;171.28049;5.1085e-002;0.75799
 438.75466;171.19007;5.1275e-002;0.75747
 439.65557;171.10016;5.1391e-002;0.75696
 440.55647;171.00972;5.1400e-002;0.75644
 441.45738;170.91943;5.1625e-002;0.75593
 442.35829;170.82930;5.1913e-002;0.75541
 443.25920;170.73815;5.1771e-002;0.75490
 444.16011;170.64742;5.1647e-002;0.75438
 445.06102;170.55719;5.1761e-002;0.75387
 445.96193;170.46728;5.2177e-002;0.75335
 446.86284;170.37668;5.2239e-002;0.75284
 447.76374;170.28654;5.2277e-002;0.75232
 448.66465;170.19638;5.2910e-002;0.75181
 449.56556;170.10649;5.2947e-002;0.75129
 450.46647;170.01648;5.3036e-002;0.75078
 451.36738;169.92637;5.3014e-002;0.75026
 452.26829;169.83615;5.3167e-002;0.74975
 453.16920;169.74573;5.3029e-002;0.74923
 454.07010;169.65567;5.3117e-002;0.74872
 454.97101;169.56512;5.3596e-002;0.74821
 455.87192;169.47477;5.3642e-002;0.74769
 456.77283;169.38484;5.3666e-002;0.74718
 457.67374;169.29408;5.3489e-002;0.74666
 458.57465;169.20371;5.3555e-002;0.74615
 459.47556;169.11346;5.3619e-002;0.74563
 460.37647;169.02384;5.3576e-002;0.74512
 461.27737;168.93403;5.3854e-002;0.74460
 462.17828;168.84296;5.3678e-002;0.74409
 463.07919;168.75300;5.3743e-002;0.74357
 463.98010;168.66319;5.3613e-002;0.74306
 464.88101;168.57301;5.4060e-002;0.74254
 465.78192;168.48252;5.3930e-002;0.74203
 466.68283;168.39249;5.4109e-002;0.74151
 467.58374;168.30264;5.4063e-002;0.74100
 468.48464;168.21186;5.4426e-002;0.74048
 469.38555;168.12161;5.4677e-002;0.73997
 470.28646;168.03050;5.4447e-002;0.73945
 471.18737;167.94054;5.4758e-002;0.73894
 472.08828;167.85086;5.4811e-002;0.73842
 472.98919;167.76049;5.4935e-002;0.73791
 473.89010;167.67045;5.5155e-002;0.73739
 474.79101;167.58045;5.4901e-002;0.73688
 475.69191;167.49057;5.5397e-002;0.73636
 476.59282;167.39990;5.5384e-002;0.73585
 477.49373;167.30976;5.5444e-002;0.73533
 478.39464;167.21938;5.5403e-002;0.73482
 479.29555;167.12942;5.5729e-002;0.73430
 480.19646;167.03924;5.6134e-002;0.73379
 481.09737;166.94955;5.6023e-002;0.73327
 481.99827;166.85954;5.6258e-002;0.73276
 482.89918;166.76942;5.6211e-002;0.73224
 483.80009;166.67919;5.6235e-002;0.73173
 484.70100;166.58941;5.6457e-002;0.73121
 485.60191;166.49960;5.6553e-002;0.73070
 486.50282;166.40932;5.6509e-002;0.73018
 487.40373;166.31938;5.6521e-002;0.72967
 488.30464;166.22908;5.6009e-002;0.72915
 489.20554;166.13875;5.6002e-002;0.72864
 490.10645;166.04888;5.6172e-002;0.72812
 491.00736;165.95866;5.6059e-002;0.72761
 491.90827;165.86860;5.6623e-002;0.72710
 492.80918;165.77853;5.6538e-002;0.72658
 493.71009;165.68791;5.6812e-002;0.72607
 494.61100;165.59776;5.7027e-002;0.72555
 495.51191;165.50775;5.7078e-002;0.72504
 496.41281;165.41746;5.7262e-002;0.72452
 497.31372;165.32696;5.8201e-002;0.72401
 498.21463;165.23681;5.8045e-002;0.72349
 499.11554;165.14583;5.8199e-002;0.72298
 500.01645;165.05569;5.8319e-002;0.72247
 500.91736;164.96569;5.8175e-002;0.72195
 501.81827;164.87504;5.8287e-002;0.72144
 502.71917;164.78454;5.8437e-002;0.72092
 503.62008;164.69440;5.8604e-002;0.72041
 504.52099;164.60448;5.8773e-002;0.71989
 505.42190;164.51381;5.8913e-002;0.71938
 506.32281;164.42363;5.8728e-002;0.71887
 507.22372;164.33341;5.9109e-002;0.71835
 508.12463;164.24346;5.9296e-002;0.71784
 509.02554;164.15357;5.9368e-002;0.71732
 509.92644;164.06378;5.9666e-002;0.71681
 510.82735;163.97327;5.9708e-002;0.71630
 511.72826;163.88369;5.9950e-002;0.71578
 512.62917;163.79279;5.9883e-002;0.71527
 513.53008;163.70306;5.9665e-002;0.71476
 514.43099;163.61324;5.9791e-002;0.71424
 515.33190;163.52292;5.9801e-002;0.71373
 516.23281;163.43310;5.9797e-002;0.71322
 517.13371;163.34320;5.9865e-002;0.71270
 518.03462;163.25306;5.9827e-002;0.71219
 518.93553;163.16255;5.9771e-002;0.71168
 519.83644;163.07221;6.0070e-002;0.71116
 520.73735;162.98192;6.0135e-002;0.71065
 521.63826;162.89206;6.0943e-002;0.71014
 522.53917;162.80159;6.1228e-002;0.70962
 523.44008;162.71142;6.1037e-002;0.70911
 524.34098;162.62099;6.1351e-002;0.70860
 525.24189;162.53051;6.1091e-002;0.70808
 526.14280;162.44101;6.1065e-002;0.70757
 527.04371;162.35076;6.1212e-002;0.70706
 527.94462;162.26032;6.1539e-002;0.70654
 528.84553;162.17021;6.1470e-002;0.70603
 529.74644;162.08003;6.1456e-002;0.70552
 530.64734;161.98975;6.1763e-002;0.70501
 531.54825;161.89925;6.1836e-002;0.70449
 532.44916;161.80887;6.1579e-002;0.70398
 533.35007;161.71815;6.1790e-002;0.70347
 534.25098;161.62805;6.2083e-002;0.70296
 535.15189;161.53771;6.2263e-002;0.70244
 536.05280;161.44749;6.2082e-002;0.70193
 536.95371;161.35736;6.2323e-002;0.70142
 537.85461;161.26680;6.2469e-002;0.70091
 538.75552;161.17697;6.2434e-002;0.70040
 539.65643;161.08666;6.2736e-002;0.69988
 540.55734;160.99678;6.2520e-002;0.69937
 541.45825;160.90661;6.2943e-002;0.69886
 542.35916;160.81700;6.2785e-002;0.69835
 543.26007;160.72648;6.3214e-002;0.69784
 544.16098;160.63666;6.3258e-002;0.69733
 545.06188;160.54620;6.3354e-002;0.69681
 545.96279;160.45643;6.3183e-002;0.69630
 546.86370;160.36721;6.3580e-002;0.69579
 547.76461;160.27682;6.3678e-002;0.69528
 548.66552;160.18723;6.4109e-002;0.69477
 549.56643;160.09704;6.4063e-002;0.69426
 550.46734;160.00720;6.4154e-002;0.69375
 551.36824;159.91711;6.4074e-002;0.69324
 552.26915;159.82684;6.4091e-002;0.69272
 553.17006;159.73668;6.4225e-002;0.69221
 554.07097;159.64661;6.4037e-002;0.69170
 554.97188;159.55613;6.3822e-002;0.69119
 555.87279;159.46612;6.3682e-002;0.69068
 556.77370;159.37631;6.3885e-002;0.69017
 557.67461;159.28566;6.4055e-002;0.68966
 558.57551;159.19578;6.4201e-002;0.68915
 559.47642;159.10562;6.4275e-002;0.68864
 560.37733;159.01456;6.4540e-002;0.68813
 561.27824;158.92433;6.4485e-002;0.68762
 562.17915;158.83430;6.4935e-002;0.68711
 563.08006;158.74396;6.5146e-002;0.68660
 563.98097;158.65340;6.5186e-002;0.68609
 564.88188;158.56274;6.5228e-002;0.68558
 565.78278;158.47310;6.5371e-002;0.68507
 566.68369;158.38281;6.5772e-002;0.68456
 567.58460;158.29221;6.6158e-002;0.68405
 568.48551;158.20221;6.6207e-002;0.68354
 569.38642;158.11238;6.6663e-002;0.68304
 570.28733;158.02176;6.6329e-002;0.68253
 571.18824;157.93134;6.7591e-002;0.68202
 572.08915;157.84078;6.7871e-002;0.68151
 572.99005;157.75127;6.7635e-002;0.68100
 573.89096;157.66071;6.8177e-002;0.68049
 574.79187;157.57063;6.8068e-002;0.67998
 575.69278;157.48063;6.7983e-002;0.67947
 576.59369;157.39029;6.7971e-002;0.67897
 577.49460;157.29999;6.7897e-002;0.67846
 578.39551;157.21057;6.8094e-002;0.67795
 579.29641;157.12009;6.7937e-002;0.67744
 580.19732;157.02995;6.8170e-002;0.67693
 581.09823;156.94002;6.8132e-002;0.67642
 581.99914;156.84983;6.8484e-002;0.67592
 582.90005;156.75975;6.8411e-002;0.67541
 583.80096;156.66893;6.8183e-002;0.67490
 584.70187;156.57875;6.8678e-002;0.67439
 585.60278;156.48853;6.8822e-002;0.67389
 586.50368;156.39824;6.8806e-002;0.67338
 587.40459;156.30793;6.9249e-002;0.67287
 588.30550;156.21744;6.8930e-002;0.67237
 589.20641;156.12681;6.8747e-002;0.67186
 590.10732;156.03669;6.8737e-002;0.67135
 591.00823;155.94618;6.9157e-002;0.67084
 591.90914;155.85587;6.9836e-002;0.67034
 592.81005;155.76551;6.9630e-002;0.66983
 593.71095;155.67510;6.9807e-002;0.66933
 594.61186;155.58438;7.0322e-002;0.66882
 595.51277;155.49457;7.0911e-002;0.66831
 596.41368;155.40433;7.0716e-002;0.66781
 597.31459;155.31440;7.0772e-002;0.66730
 598.21550;155.22398;7.0684e-002;0.66680
 599.11641;155.13357;7.1547e-002;0.66629
 600.01731;155.04398;7.1552e-002;0.66578
 600.91822;154.95402;7.1404e-002;0.66528
 601.81913;154.86407;7.1444e-002;0.66477
 602.72004;154.77404;7.1514e-002;0.66427
 603.62095;154.68419;7.1668e-002;0.66376
 604.52186;154.59419;7.1814e-002;0.66326
 605.42277;154.50378;7.1995e-002;0.66275
 606.32368;154.41372;7.1590e-002;0.66225
 607.22458;154.32377;7.1665e-002;0.66174
 608.12549;154.23334;7.2005e-002;0.66124
 609.02640;154.14355;7.1626e-002;0.66074
 609.92731;154.05298;7.2024e-002;0.66023
 610.82822;153.96320;7.1956e-002;0.65973
 611.72913;153.87268;7.2042e-002;0.65922
 612.63004;153.78250;7.1958e-002;0.65872
 613.53095;153.69227;7.2448e-002;0.65822
 614.43185;153.60236;7.2673e-002;0.65771
 615.33276;153.51140;7.2494e-002;0.65721
 616.23367;153.42137;7.2624e-002;0.65670
 617.13458;153.33115;7.2777e-002;0.65620
 618.03549;153.24100;7.2573e-002;0.65570
 618.93640;153.15098;7.2706e-002;0.65520
 619.83731;153.06098;7.2871e-002;0.65469
 620.73822;152.97076;7.3464e-002;0.65419
 621.63912;152.88062;7.3198e-002;0.65369
 622.54003;152.79074;7.3363e-002;0.65319
 623.44094;152.70048;7.3467e-002;0.65268
 624.34185;152.60980;7.4157e-002;0.65218
 625.24276;152.51971;7.3910e-002;0.65168
 626.14367;152.42997;7.3993e-002;0.65118
 627.04458;152.33971;7.3702e-002;0.65067
 627.94548;152.24973;7.4072e-002;0.65017
 628.84639;152.15971;7.4038e-002;0.64967
 629.74730;152.06953;7.3922e-002;0.64917
 630.64821;151.98010;7.4090e-002;0.64867
 631.54912;151.88914;7.4534e-002;0.64817
 632.45003;151.79943;7.4484e-002;0.64767
 633.35094;151.70979;7.4764e-002;0.64717
 634.25185;151.61938;7.5048e-002;0.64667
 635.15275;151.52901;7.5324e-002;0.64616
 636.05366;151.43850;7.5450e-002;0.64566
 636.95457;151.34841;7.6019e-002;0.64516
 637.85548;151.25786;7.6067e-002;0.64466
 638.75639;151.16799;7.6211e-002;0.64416
 639.65730;151.07701;7.6883e-002;0.64366
 640.55821;150.98732;7.6614e-002;0.64316
 641.45912;150.89742;7.6541e-002;0.64267
 642.36002;150.80723;7.6813e-002;0.64217
 643.26093;150.71652;7.6898e-002;0.64167
 644.16184;150.62651;7.7056e-002;0.64117
 645.06275;150.53592;7.6672e-002;0.64067
 645.96366;150.44636;7.7079e-002;0.64017
 646.86457;150.35646;7.6885e-002;0.63967
 647.76548;150.26592;7.7376e-002;0.63917
 648.66638;150.17565;7.7373e-002;0.63867
 649.56729;150.08544;7.7793e-002;0.63818
 650.46820;149.99530;7.7591e-002;0.63768
 651.36911;149.90525;7.7941e-002;0.63718
 652.27002;149.81510;7.8010e-002;0.63668
 653.17093;149.72436;7.8343e-002;0.63618
 654.07184;149.63420;7.8233e-002;0.63569
 654.97275;149.54431;7.8384e-002;0.63519
 655.87365;149.45376;7.8410e-002;0.63469
 656.77456;149.36374;7.8438e-002;0.63419
 657.67547;149.27351;7.8765e-002;0.63370
 658.57638;149.18401;7.8897e-002;0.63320
 659.47729;149.09327;7.8758e-002;0.63270
 660.37820;149.00335;7.8757e-002;0.63221
 661.27911;148.91276;7.8974e-002;0.63171
 662.18002;148.82276;7.9072e-002;0.63122
 663.08092;148.73262;7.9859e-002;0.63072
 663.98183;148.64289;7.9620e-002;0.63022
 664.88274;148.55288;8.0283e-002;0.62973
 665.78365;148.46296;8.0054e-002;0.62923
 666.68456;148.37253;8.0167e-002;0.62874
 667.58547;148.28206;8.0638e-002;0.62824
 668.48638;148.19219;8.0901e-002;0.62775
 669.38729;148.10194;8.0801e-002;0.62725
 670.28819;148.01181;8.1093e-002;0.62676
 671.18910;147.92101;8.0905e-002;0.62626
 672.09001;147.83065;8.0996e-002;0.62577
 672.99092;147.74024;8.0833e-002;0.62527
 673.89183;147.65022;8.0704e-002;0.62478
 674.79274;147.56011;8.0863e-002;0.62429
 675.69365;147.46984;8.0893e-002;0.62379
 676.59455;147.37919;8.1335e-002;0.62330
 677.49546;147.28899;8.1250e-002;0.62281
 678.39637;147.19885;8.1095e-002;0.62231
 679.29728;147.10837;8.1338e-002;0.62182
 680.19819;147.01836;8.1340e-002;0.62133
 681.09910;146.92800;8.1525e-002;0.62083
 682.00001;146.83753;8.1639e-002;0.62034
 682.90092;146.74722;8.1676e-002;0.61985
 683.80182;146.65708;8.1963e-002;0.61936
 684.70273;146.56716;8.1854e-002;0.61886
 685.60364;146.47710;8.1937e-002;0.61837
 686.50455;146.38690;8.2131e-002;0.61788
 687.40546;146.29719;8.2040e-002;0.61739
 688.30637;146.20720;8.1898e-002;0.61690
 689.20728;146.11711;8.1919e-002;0.61641
 690.10819;146.02673;8.2030e-002;0.61591
 691.00909;145.93648;8.2360e-002;0.61542
 691.91000;145.84683;8.2394e-002;0.61493
 692.81091;145.75658;8.2788e-002;0.61444
 693.71182;145.66673;8.3055e-002;0.61395
 694.61273;145.57654;8.2859e-002;0.61346
 695.51364;145.48643;8.2852e-002;0.61297
 696.41455;145.39611;8.3225e-002;0.61248
 697.31545;145.30601;8.3245e-002;0.61199
 698.21636;145.21616;8.3600e-002;0.61150
 699.11727;145.12540;8.3850e-002;0.61101
 700.01818;145.03548;8.4095e-002;0.61052
 700.91909;144.94524;8.4283e-002;0.61003
 701.82000;144.85451;8.4576e-002;0.60954
 702.72091;144.76470;8.4524e-002;0.60906
 703.62182;144.67482;8.5037e-002;0.60857
 704.52272;144.58416;8.4897e-002;0.60808
 705.42363;144.49334;8.5164e-002;0.60759
 706.32454;144.40302;8.5164e-002;0.60710
 707.22545;144.31299;8.5235e-002;0.60661
 708.12636;144.22330;8.5269e-002;0.60613
 709.02727;144.13250;8.5343e-002;0.60564
 709.92818;144.04274;8.5218e-002;0.60515
 710.82909;143.95261;8.5026e-002;0.60466
 711.72999;143.86295;8.5242e-002;0.60418
 712.63090;143.77305;8.5404e-002;0.60369
 713.53181;143.68307;8.5388e-002;0.60320
 714.43272;143.59300;8.5615e-002;0.60272
 715.33363;143.50292;8.5926e-002;0.60223
 716.23454;143.41265;8.6068e-002;0.60174
 717.13545;143.32293;8.6098e-002;0.60126
 718.03636;143.23269;8.6514e-002;0.60077
 718.93726;143.14231;8.6672e-002;0.60029
 719.83817;143.05194;8.7035e-002;0.59980
 720.73908;142.96178;8.7071e-002;0.59932
 721.63999;142.87117;8.7092e-002;0.59883
 722.54090;142.78143;8.7128e-002;0.59835
 723.44181;142.69089;8.7121e-002;0.59786
 724.34272;142.60126;8.7591e-002;0.59738
 725.24362;142.51080;8.7704e-002;0.59689
 726.14453;142.42055;8.7628e-002;0.59641
 727.04544;142.33041;8.8223e-002;0.59592
 727.94635;142.24054;8.7935e-002;0.59544
 728.84726;142.15007;8.8410e-002;0.59496
 729.74817;142.06012;8.8242e-002;0.59447
 730.64908;141.96998;8.8485e-002;0.59399
 731.54999;141.87970;8.8525e-002;0.59351
 732.45089;141.78927;8.8126e-002;0.59302
 733.35180;141.69921;8.8408e-002;0.59254
 734.25271;141.60885;8.8438e-002;0.59206
 735.15362;141.51907;8.8616e-002;0.59158
 736.05453;141.42929;8.8832e-002;0.59109
 736.95544;141.33926;8.9189e-002;0.59061
 737.85635;141.24885;8.9110e-002;0.59013
 738.75726;141.15860;8.9102e-002;0.58965
 739.65816;141.06882;8.9043e-002;0.58917
 740.55907;140.97818;8.9227e-002;0.58869
 741.45998;140.88844;8.9390e-002;0.58821
 742.36089;140.79840;8.9353e-002;0.58772
 743.26180;140.70858;8.9254e-002;0.58724
 744.16271;140.61799;8.9609e-002;0.58676
 745.06362;140.52768;8.9479e-002;0.58628
 745.96452;140.43784;8.9510e-002;0.58580
 746.86543;140.34811;8.9344e-002;0.58532
 747.76634;140.25805;8.9609e-002;0.58484
 748.66725;140.16786;8.9622e-002;0.58436
 749.56816;140.07740;8.9768e-002;0.58388
 750.46907;139.98671;8.9986e-002;0.58340
 751.36998;139.89663;8.9920e-002;0.58293
 752.27089;139.80642;9.0075e-002;0.58245
 753.17179;139.71604;8.9964e-002;0.58197
 754.07270;139.62571;9.0348e-002;0.58149
 754.97361;139.53578;9.0256e-002;0.58101
 755.87452;139.44550;9.0620e-002;0.58053
 756.77543;139.35538;9.0716e-002;0.58006
 757.67634;139.26552;9.0609e-002;0.57958
 758.57725;139.17533;9.0623e-002;0.57910
 759.47816;139.08536;9.0841e-002;0.57862
 760.37906;138.99519;9.0953e-002;0.57815
 761.27997;138.90503;9.1038e-002;0.57767
 762.18088;138.81504;9.1137e-002;0.57719
 763.08179;138.72473;9.1005e-002;0.57672
 763.98270;138.63456;9.1412e-002;0.57624
 764.88361;138.54518;9.1506e-002;0.57576
 765.78452;138.45452;9.2026e-002;0.57529
 766.68543;138.36442;9.1761e-002;0.57481
 767.58633;138.27408;9.1679e-002;0.57434
 768.48724;138.18438;9.1612e-002;0.57386
 769.38815;138.09397;9.2196e-002;0.57339
 770.28906;138.00368;9.1880e-002;0.57291
 771.18997;137.91305;9.2247e-002;0.57244
 772.09088;137.82261;9.2183e-002;0.57196
 772.99179;137.73238;9.2261e-002;0.57149
 773.89269;137.64163;9.2821e-002;0.57101
 774.79360;137.55131;9.2466e-002;0.57054
 775.69451;137.46075;9.2874e-002;0.57006
 776.59542;137.37090;9.2647e-002;0.56959
 777.49633;137.28071;9.2957e-002;0.56912
 778.39724;137.19037;9.2861e-002;0.56864
 779.29815;137.10055;9.3332e-002;0.56817
 780.19906;137.00965;9.3343e-002;0.56770
 781.09996;136.92037;9.3624e-002;0.56723
 782.00087;136.82964;9.3822e-002;0.56675
 782.90178;136.73971;9.3346e-002;0.56628
 783.80269;136.64978;9.3465e-002;0.56581
 784.70360;136.55979;9.3556e-002;0.56534
 785.60451;136.46957;9.3840e-002;0.56487
 786.50542;136.37946;9.3682e-002;0.56439
 787.40633;136.28951;9.3564e-002;0.56392
 788.30723;136.19917;9.4076e-002;0.56345
 789.20814;136.10880;9.4247e-002;0.56298
 790.10905;136.01854;9.4012e-002;0.56251
 791.00996;135.92838;9.4621e-002;0.56204
 791.91087;135.83834;9.4789e-002;0.56157
 792.81178;135.74826;9.4593e-002;0.56110
 793.71269;135.65790;9.4822e-002;0.56063
 794.61359;135.56740;9.4630e-002;0.56016
 795.51450;135.47772;9.4586e-002;0.55969
 796.41541;135.38762;9.4795e-002;0.55922
 797.31632;135.29777;9.5078e-002;0.55875
 798.21723;135.20728;9.5252e-002;0.55828
 799.11814;135.11659;9.5498e-002;0.55781
 800.01905;135.02725;9.5494e-002;0.55735
 800.91996;134.93690;9.5439e-002;0.55688
 801.82086;134.84698;9.5670e-002;0.55641
 802.72177;134.75676;9.5640e-002;0.55594
 803.62268;134.66693;9.5828e-002;0.55547
 804.52359;134.57592;9.5396e-002;0.55501
 805.42450;134.48615;9.5759e-002;0.55454
 806.32541;134.39599;9.5782e-002;0.55407
 807.22632;134.30607;9.5974e-002;0.55361
 808.12723;134.21549;9.6072e-002;0.55314
 809.02813;134.12522;9.6077e-002;0.55267
 809.92904;134.03524;9.6409e-002;0.55221
 810.82995;133.94486;9.6643e-002;0.55174
 811.73086;133.85437;9.6647e-002;0.55127
 812.63177;133.76401;9.6526e-002;0.55081
 813.53268;133.67361;9.6751e-002;0.55034
 814.43359;133.58370;9.6661e-002;0.54988
 815.33450;133.49323;9.6296e-002;0.54941
 816.23540;133.40310;9.6555e-002;0.54895
 817.13631;133.31288;9.6908e-002;0.54848
 818.03722;133.22258;9.7137e-002;0.54802
 818.93813;133.13246;9.7361e-002;0.54756
 819.83904;133.04202;9.7952e-002;0.54709
 820.73995;132.95204;9.7890e-002;0.54663
 821.64086;132.86167;9.8113e-002;0.54616
 822.54176;132.77162;9.8234e-002;0.54570
 823.44267;132.68118;9.8401e-002;0.54524
 824.34358;132.59114;9.8469e-002;0.54477
 825.24449;132.50092;9.8608e-002;0.54431
 826.14540;132.41061;9.9162e-002;0.54385
 827.04631;132.32026;9.9047e-002;0.54339
 827.94722;132.23017;9.9358e-002;0.54292
 828.84813;132.13992;9.9067e-002;0.54246
 829.74903;132.04991;9.9750e-002;0.54200
 830.64994;131.95987;9.9348e-002;0.54154
 831.55085;131.86948;9.9399e-002;0.54108
 832.45176;131.77913;9.9431e-002;0.54062
 833.35267;131.68891;9.9346e-002;0.54016
 834.25358;131.59884;9.9434e-002;0.53970
 835.15449;131.50939;9.9540e-002;0.53923
 836.05540;131.41863;9.9531e-002;0.53877
 836.95630;131.32864;9.9639e-002;0.53831
 837.85721;131.23858;9.9457e-002;0.53785
 838.75812;131.14893;9.9720e-002;0.53739
 839.65903;131.05789;9.9603e-002;0.53694
 840.55994;130.96776;9.9981e-002;0.53648
 841.46085;130.87739;9.9798e-002;0.53602
 842.36176;130.78680;9.9698e-002;0.53556
 843.26266;130.69697;9.9939e-002;0.53510
 844.16357;130.60636;    0.10022;0.53464
 845.06448;130.51636;    0.10041;0.53418
 845.96539;130.42620;9.9894e-002;0.53373
 846.86630;130.33624;    0.10027;0.53327
 847.76721;130.24627;    0.10033;0.53281
 848.66812;130.15595;    0.10053;0.53235
 849.56903;130.06558;    0.10091;0.53190
 850.46993;129.97545;    0.10079;0.53144
 851.37084;129.88574;    0.10098;0.53098
 852.27175;129.79536;    0.10095;0.53052
 853.17266;129.70554;    0.10065;0.53007
 854.07357;129.61560;    0.10078;0.52961
 854.97448;129.52549;    0.10072;0.52916
 855.87539;129.43529;    0.10073;0.52870
 856.77630;129.34495;    0.10066;0.52825
 857.67720;129.25492;    0.10064;0.52779
 858.57811;129.16451;    0.10091;0.52733
 859.47902;129.07433;    0.10085;0.52688
 860.37993;128.98445;    0.10076;0.52643
 861.28084;128.89408;    0.10054;0.52597
 862.18175;128.80389;    0.10063;0.52552
 863.08266;128.71397;    0.10113;0.52506
 863.98357;128.62362;    0.10100;0.52461
 864.88447;128.53339;    0.10101;0.52415
 865.78538;128.44291;    0.10108;0.52370
 866.68629;128.35281;    0.10119;0.52325
 867.58720;128.26259;    0.10103;0.52280
 868.48811;128.17252;    0.10110;0.52234
 869.38902;128.08202;    0.10147;0.52189
 870.28993;127.99194;    0.10216;0.52144
 871.19083;127.90175;    0.10172;0.52099
 872.09174;127.81163;    0.10213;0.52053
 872.99265;127.72109;    0.10207;0.52008
 873.89356;127.63100;    0.10217;0.51963
 874.79447;127.54109;    0.10178;0.51918
 875.69538;127.45118;    0.10181;0.51873
 876.59629;127.36117;    0.10199;0.51828
 877.49720;127.27084;    0.10195;0.51783
 878.39810;127.18099;    0.10181;0.51738
 879.29901;127.09129;    0.10184;0.51693
 880.19992;127.00157;    0.10175;0.51648
 881.10083;126.91112;    0.10178;0.51603
 882.00174;126.82064;    0.10225;0.51558
 882.90265;126.73062;    0.10207;0.51513
 883.80356;126.64092;    0.10247;0.51468
 884.70447;126.55079;    0.10229;0.51423
 885.60537;126.45999;    0.10238;0.51378
 886.50628;126.36980;    0.10266;0.51333
 887.40719;126.27997;    0.10280;0.51288
 888.30810;126.19011;    0.10265;0.51243
 889.20901;126.09966;    0.10282;0.51199
 890.10992;126.00936;    0.10310;0.51154
 891.01083;125.92001;    0.10292;0.51109
 891.91174;125.82934;    0.10313;0.51064
 892.81264;125.73904;    0.10349;0.51020
 893.71355;125.64923;    0.10346;0.50975
 894.61446;125.55884;    0.10342;0.50930
 895.51537;125.46825;    0.10340;0.50886
 896.41628;125.37823;    0.10400;0.50841
 897.31719;125.28825;    0.10376;0.50796
 898.21810;125.19854;    0.10391;0.50752
 899.11900;125.10841;    0.10429;0.50707
 900.01991;125.01774;    0.10414;0.50663
 900.92082;124.92794;    0.10419;0.50618
 901.82173;124.83801;    0.10424;0.50574
 902.72264;124.74779;    0.10424;0.50529
 903.62355;124.65716;    0.10440;0.50485
 904.52446;124.56749;    0.10426;0.50440
 905.42537;124.47631;    0.10450;0.50396
 906.32627;124.38654;    0.10462;0.50352
 907.22718;124.29598;    0.10468;0.50307
 908.12809;124.20568;    0.10482;0.50263
 909.02900;124.11547;    0.10493;0.50219
 909.92991;124.02546;    0.10496;0.50174
 910.83082;123.93608;    0.10493;0.50130
 911.73173;123.84636;    0.10623;0.50086
 912.63264;123.75598;    0.10620;0.50041
 913.53354;123.66567;    0.10640;0.49997
 914.43445;123.57572;    0.10651;0.49953
 915.33536;123.48576;    0.10675;0.49909
 916.23627;123.39593;    0.10731;0.49865
 917.13718;123.30589;    0.10693;0.49821
 918.03809;123.21622;    0.10719;0.49776
 918.93900;123.12610;    0.10704;0.49732
 919.83990;123.03576;    0.10675;0.49688
 920.74081;122.94601;    0.10715;0.49644
 921.64172;122.85554;    0.10710;0.49600
 922.54263;122.76529;    0.10688;0.49556
 923.44354;122.67538;    0.10702;0.49512
 924.34445;122.58490;    0.10763;0.49468
 925.24536;122.49485;    0.10783;0.49424
 926.14627;122.40422;    0.10814;0.49380
 927.04717;122.31418;    0.10803;0.49336
 927.94808;122.22363;    0.10778;0.49293
 928.84899;122.13360;    0.10812;0.49249
 929.74990;122.04340;    0.10789;0.49205
 930.65081;121.95314;    0.10848;0.49161
 931.55172;121.86308;    0.10855;0.49117
 932.45263;121.77338;    0.10872;0.49074
 933.35354;121.68374;    0.10881;0.49030
 934.25444;121.59314;    0.10891;0.48986
 935.15535;121.50338;    0.10939;0.48942
 936.05626;121.41325;    0.10936;0.48899
 936.95717;121.32282;    0.10903;0.48855
 937.85808;121.23349;    0.10955;0.48811
 938.75899;121.14299;    0.10941;0.48768
 939.65990;121.05361;    0.10979;0.48724
 940.56081;120.96300;    0.10972;0.48681
 941.46171;120.87340;    0.10991;0.48637
 942.36262;120.78347;    0.11009;0.48593
 943.26353;120.69327;    0.11019;0.48550
 944.16444;120.60339;    0.11050;0.48506
 945.06535;120.51326;    0.11055;0.48463
 945.96626;120.42341;    0.11048;0.48419
 946.86717;120.33354;    0.11025;0.48376
 947.76807;120.24299;    0.11093;0.48333
 948.66898;120.15239;    0.11099;0.48289
 949.56989;120.06226;    0.11108;0.48246
 950.47080;119.97197;    0.11121;0.48203
 951.37171;119.88129;    0.11091;0.48159
 952.27262;119.79104;    0.11130;0.48116
 953.17353;119.70124;    0.11160;0.48073
 954.07444;119.61113;    0.11157;0.48029
 954.97534;119.52116;    0.11139;0.47986
 955.87625;119.43068;    0.11143;0.47943
 956.77716;119.34079;    0.11154;0.47900
 957.67807;119.25068;    0.11153;0.47857
 958.57898;119.16098;    0.11168;0.47813
 959.47989;119.07120;    0.11158;0.47770
 960.38080;118.98146;    0.11148;0.47727
 961.28171;118.89099;    0.11133;0.47684
 962.18261;118.80074;    0.11132;0.47641
 963.08352;118.71080;    0.11138;0.47598
 963.98443;118.62033;    0.11143;0.47555
 964.88534;118.53039;    0.11140;0.47512
 965.78625;118.44061;    0.11144;0.47469
 966.68716;118.35042;    0.11132;0.47426
 967.58807;118.26037;    0.11110;0.47383
 968.48897;118.17083;    0.11130;0.47340
 969.38988;118.08078;    0.11143;0.47297
 970.29079;117.99091;    0.11161;0.47254
 971.19170;117.90082;    0.11188;0.47211
 972.09261;117.81002;    0.11177;0.47169
 972.99352;117.71960;    0.11204;0.47126
 973.89443;117.62964;    0.11215;0.47083
 974.79534;117.53877;    0.11247;0.47040
 975.69624;117.44829;    0.11289;0.46997
 976.59715;117.35835;    0.11339;0.46955
 977.49806;117.26788;    0.11269;0.46912
 978.39897;117.17758;    0.11274;0.46869
 979.29988;117.08772;    0.11299;0.46827
 980.20079;116.99767;    0.11331;0.46784
 981.10170;116.90687;    0.11302;0.46741
 982.00261;116.81660;    0.11268;0.46699
 982.90351;116.72633;    0.11331;0.46656
 983.80442;116.63571;    0.11306;0.46614
 984.70533;116.54556;    0.11354;0.46571
 985.60624;116.45572;    0.11328;0.46529
 986.50715;116.36500;    0.11324;0.46486
 987.40806;116.27473;    0.11367;0.46444
 988.30897;116.18490;    0.11420;0.46401
 989.20988;116.09476;    0.11357;0.46359
 990.11078;116.00398;    0.11364;0.46316
 991.01169;115.91416;    0.11343;0.46274
 991.91260;115.82457;    0.11326;0.46232
 992.81351;115.73427;    0.11332;0.46189
 993.71442;115.64457;    0.11310;0.46147
 994.61533;115.55471;    0.11348;0.46105
 995.51624;115.46554;    0.11377;0.46062
 996.41714;115.37598;    0.11381;0.46020
 997.31805;115.28563;    0.11385;0.45978
 998.21896;115.19521;    0.11400;0.45935
 999.11987;115.10510;    0.11443;0.45893
1000.02078;115.01449;    0.11496;0.45851
1000.92169;114.92450;    0.11483;0.45809
1001.82260;114.83421;    0.11497;0.45767
1002.72351;114.74407;    0.11467;0.45725
1003.62441;114.65370;    0.11439;0.45683
1004.52532;114.56352;    0.11420;0.45641
1005.42623;114.47351;    0.11402;0.45598
1006.32714;114.38299;    0.11395;0.45556
1007.22805;114.29249;    0.11408;0.45514
1008.12896;114.20237;    0.11376;0.45472
1009.02987;114.11244;    0.11388;0.45430
1009.93078;114.02276;    0.11396;0.45389
1010.83168;113.93279;    0.11407;0.45347
1011.73259;113.84263;    0.11421;0.45305
1012.63350;113.75237;    0.11377;0.45263
1013.53441;113.66259;    0.11442;0.45221
1014.43532;113.57202;    0.11463;0.45179
1015.33623;113.48207;    0.11447;0.45137
1016.23714;113.39166;    0.11458;0.45095
1017.13804;113.30168;    0.11505;0.45054
1018.03895;113.21165;    0.11494;0.45012
1018.93986;113.12185;    0.11511;0.44970
1019.84077;113.03271;    0.11503;0.44928
1020.74168;112.94285;    0.11542;0.44887
1021.64259;112.85285;    0.11612;0.44845
1022.54350;112.76256;    0.11618;0.44803
1023.44441;112.67280;    0.11619;0.44762
1024.34531;112.58269;    0.11645;0.44720
1025.24622;112.49290;    0.11668;0.44679
1026.14713;112.40298;    0.11694;0.44637
1027.04804;112.31308;    0.11828;0.44595
1027.94895;112.22317;    0.11829;0.44554
1028.84986;112.13329;    0.11853;0.44512
1029.75077;112.04267;    0.11905;0.44471
1030.65168;111.95269;    0.11914;0.44429
1031.55258;111.86219;    0.11977;0.44388
1032.45349;111.77177;    0.12118;0.44347
1033.35440;111.68166;    0.12346;0.44305
1034.25531;111.59097;    0.12450;0.44264
1035.15622;111.50024;    0.12804;0.44222
1036.05713;111.40955;    0.13129;0.44181
1036.95804;111.31905;    0.13720;0.44140
1037.85895;111.22880;    0.14572;0.44099
1038.75985;111.13831;    0.15775;0.44057
1039.66076;111.04827;    0.17439;0.44016
1040.56167;110.95916;    0.19824;0.43975
1041.46258;110.86955;    0.23298;0.43934
1042.36349;110.78049;    0.28451;0.43892
1043.26440;110.69202;    0.35857;0.43851
1044.16531;110.60408;    0.47220;0.43810
1045.06621;110.51575;    0.65384;0.43769
1045.96712;110.42837;    0.97321;0.43728
1046.86803;110.33926;    1.46226;0.43687
1047.76894;110.24829;    1.34187;0.43646
1048.66985;110.15649;    1.19983;0.43605
1049.57076;110.06449;    1.03381;0.43564
1050.47167;109.97232;    0.82020;0.43523
1051.37258;109.87926;    0.43599;0.43482
1052.27348;109.78877;    0.10520;0.43441
1053.17439;109.69842;    0.10520;0.43400
1054.07530;109.60819;    0.10478;0.43359
1054.97621;109.51795;    0.10554;0.43318
1055.87712;109.42805;    0.10468;0.43277
1056.77803;109.33792;    0.10516;0.43236
1057.67894;109.24808;    0.10541;0.43195
1058.57985;109.15878;    0.10554;0.43154
1059.48075;109.06963;    0.10572;0.43114
1060.38166;108.98037;    0.10614;0.43073
1061.28257;108.89130;    0.10664;0.43032
1062.18348;108.80258;    0.10659;0.42991
1063.08439;108.71351;    0.10683;0.42951
1063.98530;108.62435;    0.10757;0.42910
1064.88621;108.53511;    0.10779;0.42869
1065.78711;108.44605;    0.10811;0.42829
1066.68802;108.35671;    0.10861;0.42788
1067.58893;108.26634;    0.10848;0.42747
1068.48984;108.17627;    0.10823;0.42707
1069.39075;108.08460;    0.10836;0.42666
1070.29166;107.99229;    0.10747;0.42626
1071.19257;107.89934;    0.10701;0.42585
1072.09348;107.80573;    0.10735;0.42545
1072.99438;107.71043;    0.10642;0.42504
1073.89529;107.61374;    0.10586;0.42464
1074.79620;107.51554;    0.10456;0.42423
1075.69711;107.41698;    0.10409;0.42383
1076.59802;107.31811;    0.10372;0.42342
1077.49893;107.21892;    0.10311;0.42302
1078.39984;107.12036;    0.10270;0.42262
1079.30075;107.02253;    0.10255;0.42221
1080.20165;106.92804;    0.10274;0.42181
1081.10256;106.83596;    0.10392;0.42141
1082.00347;106.74688;    0.10474;0.42100
1082.90438;106.66188;    0.10597;0.42060
1083.80529;106.57983;    0.10876;0.42020
1084.70620;106.50167;    0.11064;0.41980
1085.60711;106.42679;    0.11246;0.41940
1086.50802;106.35461;    0.11623;0.41899
1087.40892;106.28557;    0.11841;0.41859
1088.30983;106.21879;    0.12212;0.41819
1089.21074;106.15350;    0.12526;0.41779
1090.11165;106.08952;    0.12829;0.41739
1091.01256;106.02707;    0.13150;0.41699
1091.91347;105.96516;    0.13409;0.41659
1092.81438;105.90377;    0.13700;0.41619
1093.71528;105.84184;    0.13951;0.41579
1094.61619;105.77914;    0.14154;0.41539
1095.51710;105.71499;    0.14245;0.41499
1096.41801;105.64802;    0.14292;0.41459
1097.31892;105.57639;    0.14253;0.41419
1098.21983;105.49813;    0.14076;0.41379
1099.12074;105.40492;    0.13531;0.41339
1100.02165;105.29848;    0.12519;0.41299
1100.40775;105.29848;    0.12519;0.41282