File: Thesis/DSC/ExpDat_Au_sample-1heating.txt
#FILE:Au_samp.ngb-ds3
#FORMAT:NETZSCH5
#FTYPE:ASCII
#IDENTITY:pureAu
#DECIMAL:POINT
#SEPARATOR:SEMICOLON
#MTYPE:DSC
#INSTRUMENT:NETZSCH STA 449F3
#PROJECT:MET
#DATE/TIME:01.12.2017 17:26
#CORR. FILE:Au.ngb-bs3
#LABORATORY:DB
#OPERATOR:Shalini
#REMARK:
#SAMPLE:pureAu
#SAMPLE MASS /mg:37.480
#MATERIAL:
#REFERENCE:Shalini
#REFERENCE MASS /mg:0.002
#TYPE OF CRUCIBLE:DSC/TG pan Al2O3
#SAMPLE CRUCIBLE MASS /mg:0.0
#REFERENCE CRUCIBLE MASS /mg:0.0
#CORR. CODE:020
#EXO:+1
#RANGE:  50/10.0(K/min)/1100
#SEGMENT:S1/2

##Temp./oC;Time/min;DSC/(mW/mg);Sensit./(uV/mW)
  49.19600;0.0000e+000;-1.0597e-002;0.96044
  50.18099;    0.21293;-1.0502e-002;0.96002
  51.16598;    0.40641;-1.0632e-002;0.95961
  52.15096;    0.57333;-1.1524e-002;0.95919
  53.13595;    0.72393;-1.2536e-002;0.95877
  54.12094;    0.86434;-1.3065e-002;0.95835
  55.10593;    0.99652;-1.1873e-002;0.95793
  56.09092;    1.12251;-1.2494e-002;0.95751
  57.07590;    1.24385;-1.3188e-002;0.95709
  58.06089;    1.36104;-1.3780e-002;0.95667
  59.04588;    1.47436;-1.3986e-002;0.95624
  60.03087;    1.58434;-1.4692e-002;0.95582
  61.01586;    1.69134;-1.5036e-002;0.95540
  62.00084;    1.79564;-1.5393e-002;0.95497
  62.98583;    1.89773;-1.6053e-002;0.95455
  63.97082;    1.99791;-1.6232e-002;0.95412
  64.95581;    2.09628;-1.6913e-002;0.95369
  65.94080;    2.19297;-1.7036e-002;0.95327
  66.92578;    2.28825;-1.7300e-002;0.95284
  67.91077;    2.38238;-1.7780e-002;0.95241
  68.89576;    2.47543;-1.7958e-002;0.95198
  69.88075;    2.56733;-1.8037e-002;0.95155
  70.86574;    2.65814;-1.8490e-002;0.95112
  71.85073;    2.74803;-1.8679e-002;0.95068
  72.83571;    2.83705;-1.8899e-002;0.95025
  73.82070;    2.92540;-1.9117e-002;0.94982
  74.80569;    3.01314;-1.9213e-002;0.94938
  75.79068;    3.10034;-1.9177e-002;0.94895
  76.77567;    3.18712;-1.9365e-002;0.94851
  77.76065;    3.27347;-1.9259e-002;0.94808
  78.74564;    3.35938;-1.8768e-002;0.94764
  79.73063;    3.44493;-1.8855e-002;0.94720
  80.71562;    3.53018;-1.9095e-002;0.94676
  81.70061;    3.61519;-1.8949e-002;0.94632
  82.68559;    3.69997;-1.9046e-002;0.94589
  83.67058;    3.78450;-1.9382e-002;0.94544
  84.65557;    3.86881;-1.9365e-002;0.94500
  85.64056;    3.95285;-2.0607e-002;0.94456
  86.62555;    4.03656;-2.0915e-002;0.94412
  87.61054;    4.11996;-2.0966e-002;0.94368
  88.59552;    4.20342;-2.0822e-002;0.94323
  89.58051;    4.28715;-2.1153e-002;0.94279
  90.56550;    4.37079;-2.1221e-002;0.94234
  91.55049;    4.45425;-2.1337e-002;0.94190
  92.53548;    4.53790;-2.1481e-002;0.94145
  93.52046;    4.62185;-2.1645e-002;0.94100
  94.50545;    4.70605;-2.1471e-002;0.94056
  95.49044;    4.79032;-2.1455e-002;0.94011
  96.47543;    4.87469;-2.1206e-002;0.93966
  97.46042;    4.95930;-2.1192e-002;0.93921
  98.44540;    5.04429;-2.0751e-002;0.93876
  99.43039;    5.12954;-2.0550e-002;0.93831
 100.41538;    5.21506;-2.0108e-002;0.93785
 101.40037;    5.30090;-1.9801e-002;0.93740
 102.38536;    5.38723;-1.9379e-002;0.93695
 103.37034;    5.47397;-1.9404e-002;0.93649
 104.35533;    5.56100;-1.9336e-002;0.93604
 105.34032;    5.64835;-1.9449e-002;0.93559
 106.32531;    5.73623;-1.9117e-002;0.93513
 107.31030;    5.82468;-1.9215e-002;0.93467
 108.29529;    5.91338;-1.9240e-002;0.93422
 109.28027;    6.00242;-1.9287e-002;0.93376
 110.26526;    6.09193;-1.8960e-002;0.93330
 111.25025;    6.18185;-1.8883e-002;0.93284
 112.23524;    6.27225;-1.8718e-002;0.93238
 113.22023;    6.36313;-1.8459e-002;0.93192
 114.20521;    6.45439;-1.8401e-002;0.93146
 115.19020;    6.54617;-1.8388e-002;0.93100
 116.17519;    6.63845;-1.8265e-002;0.93054
 117.16018;    6.73093;-1.8461e-002;0.93008
 118.14517;    6.82363;-1.8740e-002;0.92961
 119.13015;    6.91695;-1.8444e-002;0.92915
 120.11514;    7.01090;-1.8152e-002;0.92868
 121.10013;    7.10523;-1.7765e-002;0.92822
 122.08512;    7.19980;-1.7639e-002;0.92775
 123.07011;    7.29460;-1.7631e-002;0.92729
 124.05509;    7.38967;-1.7376e-002;0.92682
 125.04008;    7.48511;-1.6993e-002;0.92635
 126.02507;    7.58091;-1.7112e-002;0.92589
 127.01006;    7.67700;-1.6621e-002;0.92542
 127.99505;    7.77320;-1.6330e-002;0.92495
 128.98004;    7.86954;-1.5720e-002;0.92448
 129.96502;    7.96627;-1.5766e-002;0.92401
 130.95001;    8.06327;-1.5650e-002;0.92354
 131.93500;    8.16033;-1.5370e-002;0.92307
 132.91999;    8.25757;-1.5025e-002;0.92259
 133.90498;    8.35530;-1.4844e-002;0.92212
 134.88996;    8.45348;-1.4796e-002;0.92165
 135.87495;    8.55166;-1.4683e-002;0.92117
 136.85994;    8.64967;-1.4613e-002;0.92070
 137.84493;    8.74787;-1.4549e-002;0.92022
 138.82992;    8.84646;-1.4454e-002;0.91975
 139.81490;    8.94503;-1.4679e-002;0.91927
 140.79989;    9.04353;-1.4710e-002;0.91880
 141.78488;    9.14224;-1.4388e-002;0.91832
 142.76987;    9.24113;-1.4498e-002;0.91784
 143.75486;    9.34013;-1.4336e-002;0.91736
 144.73985;    9.43908;-1.4387e-002;0.91688
 145.72483;    9.53798;-1.3916e-002;0.91640
 146.70982;    9.63689;-1.3936e-002;0.91592
 147.69481;    9.73616;-1.3954e-002;0.91544
 148.67980;    9.83575;-1.3786e-002;0.91496
 149.66479;    9.93528;-1.4028e-002;0.91448
 150.64977;   10.03467;-1.4396e-002;0.91400
 151.63476;   10.13391;-1.4694e-002;0.91351
 152.61975;   10.23330;-1.4960e-002;0.91303
 153.60474;   10.33304;-1.4946e-002;0.91255
 154.58973;   10.43292;-1.5091e-002;0.91206
 155.57471;   10.53278;-1.5009e-002;0.91158
 156.55970;   10.63254;-1.5072e-002;0.91109
 157.54469;   10.73235;-1.4893e-002;0.91061
 158.52968;   10.83219;-1.5137e-002;0.91012
 159.51467;   10.93207;-1.5507e-002;0.90963
 160.49965;   11.03188;-1.5754e-002;0.90914
 161.48464;   11.13163;-1.5746e-002;0.90866
 162.46963;   11.23158;-1.5893e-002;0.90817
 163.45462;   11.33157;-1.5934e-002;0.90768
 164.43961;   11.43146;-1.5906e-002;0.90719
 165.42460;   11.53133;-1.5772e-002;0.90670
 166.40958;   11.63114;-1.5945e-002;0.90621
 167.39457;   11.73096;-1.5775e-002;0.90572
 168.37956;   11.83074;-1.5735e-002;0.90522
 169.36455;   11.93031;-1.5889e-002;0.90473
 170.34954;   12.02969;-1.6142e-002;0.90424
 171.33452;   12.12910;-1.6103e-002;0.90375
 172.31951;   12.22852;-1.6240e-002;0.90325
 173.30450;   12.32782;-1.6433e-002;0.90276
 174.28949;   12.42705;-1.6718e-002;0.90226
 175.27448;   12.52623;-1.6497e-002;0.90177
 176.25946;   12.62546;-1.6309e-002;0.90127
 177.24445;   12.72476;-1.6273e-002;0.90077
 178.22944;   12.82393;-1.5933e-002;0.90028
 179.21443;   12.92296;-1.5723e-002;0.89978
 180.19942;   13.02178;-1.5755e-002;0.89928
 181.18440;   13.12037;-1.5781e-002;0.89878
 182.16939;   13.21907;-1.6014e-002;0.89829
 183.15438;   13.31799;-1.6332e-002;0.89779
 184.13937;   13.41695;-1.6194e-002;0.89729
 185.12436;   13.51567;-1.6189e-002;0.89679
 186.10935;   13.61426;-1.6139e-002;0.89629
 187.09433;   13.71288;-1.5673e-002;0.89578
 188.07932;   13.81144;-1.5861e-002;0.89528
 189.06431;   13.90994;-1.5719e-002;0.89478
 190.04930;   14.00846;-1.5690e-002;0.89428
 191.03429;   14.10695;-1.5901e-002;0.89378
 192.01927;   14.20532;-1.5840e-002;0.89327
 193.00426;   14.30360;-1.6120e-002;0.89277
 193.98925;   14.40189;-1.6100e-002;0.89226
 194.97424;   14.50026;-1.6092e-002;0.89176
 195.95923;   14.59871;-1.6010e-002;0.89125
 196.94421;   14.69728;-1.6126e-002;0.89075
 197.92920;   14.79579;-1.5871e-002;0.89024
 198.91419;   14.89399;-1.5910e-002;0.88973
 199.89918;   14.99215;-1.5929e-002;0.88923
 200.88417;   15.09064;-1.5853e-002;0.88872
 201.86916;   15.18923;-1.6075e-002;0.88821
 202.85414;   15.28771;-1.5872e-002;0.88770
 203.83913;   15.38618;-1.5942e-002;0.88719
 204.82412;   15.48462;-1.5840e-002;0.88668
 205.80911;   15.58319;-1.5826e-002;0.88617
 206.79410;   15.68193;-1.5706e-002;0.88566
 207.77908;   15.78059;-1.5666e-002;0.88515
 208.76407;   15.87916;-1.5815e-002;0.88464
 209.74906;   15.97775;-1.5552e-002;0.88413
 210.73405;   16.07637;-1.5892e-002;0.88362
 211.71904;   16.17498;-1.5739e-002;0.88311
 212.70402;   16.27368;-1.5653e-002;0.88259
 213.68901;   16.37243;-1.5706e-002;0.88208
 214.67400;   16.47103;-1.5384e-002;0.88157
 215.65899;   16.56957;-1.5453e-002;0.88105
 216.64398;   16.66817;-1.5214e-002;0.88054
 217.62896;   16.76682;-1.5081e-002;0.88002
 218.61395;   16.86548;-1.5002e-002;0.87951
 219.59894;   16.96412;-1.5001e-002;0.87899
 220.58393;   17.06275;-1.5038e-002;0.87848
 221.56892;   17.16138;-1.5030e-002;0.87796
 222.55391;   17.26002;-1.5010e-002;0.87744
 223.53889;   17.35855;-1.4777e-002;0.87693
 224.52388;   17.45706;-1.4789e-002;0.87641
 225.50887;   17.55568;-1.5046e-002;0.87589
 226.49386;   17.65434;-1.5009e-002;0.87537
 227.47885;   17.75296;-1.5066e-002;0.87485
 228.46383;   17.85154;-1.5004e-002;0.87433
 229.44882;   17.95031;-1.5143e-002;0.87381
 230.43381;   18.04930;-1.4845e-002;0.87329
 231.41880;   18.14823;-1.4907e-002;0.87277
 232.40379;   18.24690;-1.4729e-002;0.87225
 233.38877;   18.34553;-1.4714e-002;0.87173
 234.37376;   18.44429;-1.4486e-002;0.87121
 235.35875;   18.54311;-1.4870e-002;0.87069
 236.34374;   18.64183;-1.4570e-002;0.87017
 237.32873;   18.74039;-1.4606e-002;0.86964
 238.31371;   18.83897;-1.4761e-002;0.86912
 239.29870;   18.93757;-1.4714e-002;0.86860
 240.28369;   19.03611;-1.4304e-002;0.86807
 241.26868;   19.13456;-1.4337e-002;0.86755
 242.25367;   19.23299;-1.4651e-002;0.86702
 243.23866;   19.33143;-1.4650e-002;0.86650
 244.22364;   19.42977;-1.4550e-002;0.86597
 245.20863;   19.52813;-1.4561e-002;0.86545
 246.19362;   19.62661;-1.4568e-002;0.86492
 247.17861;   19.72515;-1.4381e-002;0.86440
 248.16360;   19.82378;-1.4495e-002;0.86387
 249.14858;   19.92238;-1.4578e-002;0.86334
 250.13357;   20.02088;-1.4477e-002;0.86281
 251.11856;   20.11937;-1.4429e-002;0.86229
 252.10355;   20.21778;-1.4550e-002;0.86176
 253.08854;   20.31616;-1.4614e-002;0.86123
 254.07352;   20.41466;-1.4605e-002;0.86070
 255.05851;   20.51327;-1.4341e-002;0.86017
 256.04350;   20.61181;-1.4496e-002;0.85964
 257.02849;   20.71031;-1.4568e-002;0.85911
 258.01348;   20.80902;-1.4470e-002;0.85858
 258.99847;   20.90780;-1.4587e-002;0.85805
 259.98345;   21.00636;-1.4500e-002;0.85752
 260.96844;   21.10487;-1.4401e-002;0.85699
 261.95343;   21.20352;-1.4356e-002;0.85646
 262.93842;   21.30226;-1.4123e-002;0.85593
 263.92341;   21.40106;-1.4398e-002;0.85539
 264.90839;   21.49983;-1.4406e-002;0.85486
 265.89338;   21.59841;-1.4033e-002;0.85433
 266.87837;   21.69691;-1.4163e-002;0.85380
 267.86336;   21.79563;-1.4100e-002;0.85326
 268.84835;   21.89449;-1.4078e-002;0.85273
 269.83333;   21.99325;-1.3880e-002;0.85219
 270.81832;   22.09191;-1.3671e-002;0.85166
 271.80331;   22.19054;-1.3633e-002;0.85113
 272.78830;   22.28916;-1.3808e-002;0.85059
 273.77329;   22.38795;-1.3754e-002;0.85006
 274.75827;   22.48688;-1.3463e-002;0.84952
 275.74326;   22.58567;-1.3341e-002;0.84898
 276.72825;   22.68434;-1.3196e-002;0.84845
 277.71324;   22.78301;-1.3303e-002;0.84791
 278.69823;   22.88172;-1.3117e-002;0.84737
 279.68322;   22.98037;-1.3263e-002;0.84684
 280.66820;   23.07886;-1.2916e-002;0.84630
 281.65319;   23.17728;-1.2826e-002;0.84576
 282.63818;   23.27584;-1.2672e-002;0.84522
 283.62317;   23.37446;-1.2593e-002;0.84469
 284.60816;   23.47296;-1.2856e-002;0.84415
 285.59314;   23.57148;-1.2514e-002;0.84361
 286.57813;   23.67008;-1.2506e-002;0.84307
 287.56312;   23.76854;-1.2535e-002;0.84253
 288.54811;   23.86682;-1.2573e-002;0.84199
 289.53310;   23.96523;-1.2588e-002;0.84145
 290.51808;   24.06393;-1.2709e-002;0.84091
 291.50307;   24.16266;-1.2619e-002;0.84037
 292.48806;   24.26116;-1.2652e-002;0.83983
 293.47305;   24.35959;-1.2660e-002;0.83929
 294.45804;   24.45811;-1.2851e-002;0.83875
 295.44302;   24.55670;-1.2652e-002;0.83821
 296.42801;   24.65536;-1.2631e-002;0.83766
 297.41300;   24.75410;-1.2510e-002;0.83712
 298.39799;   24.85290;-1.2452e-002;0.83658
 299.38298;   24.95160;-1.2494e-002;0.83604
 300.36797;   25.05018;-1.2838e-002;0.83549
 301.35295;   25.14875;-1.2793e-002;0.83495
 302.33794;   25.24732;-1.2656e-002;0.83441
 303.32293;   25.34592;-1.2566e-002;0.83386
 304.30792;   25.44461;-1.2566e-002;0.83332
 305.29291;   25.54325;-1.2319e-002;0.83278
 306.27789;   25.64183;-1.2659e-002;0.83223
 307.26288;   25.74059;-1.2462e-002;0.83169
 308.24787;   25.83941;-1.2608e-002;0.83114
 309.23286;   25.93803;-1.2438e-002;0.83060
 310.21785;   26.03651;-1.2408e-002;0.83005
 311.20283;   26.13500;-1.2469e-002;0.82951
 312.18782;   26.23368;-1.2320e-002;0.82896
 313.17281;   26.33241;-1.2078e-002;0.82842
 314.15780;   26.43101;-1.2324e-002;0.82787
 315.14279;   26.52961;-1.2376e-002;0.82732
 316.12778;   26.62817;-1.2077e-002;0.82678
 317.11276;   26.72665;-1.2097e-002;0.82623
 318.09775;   26.82512;-1.1864e-002;0.82568
 319.08274;   26.92354;-1.2010e-002;0.82513
 320.06773;   27.02193;-1.1699e-002;0.82459
 321.05272;   27.12047;-1.1560e-002;0.82404
 322.03770;   27.21903;-1.1691e-002;0.82349
 323.02269;   27.31758;-1.1491e-002;0.82294
 324.00768;   27.41620;-1.1334e-002;0.82239
 324.99267;   27.51485;-1.1074e-002;0.82185
 325.97766;   27.61357;-1.1150e-002;0.82130
 326.96264;   27.71221;-1.0978e-002;0.82075
 327.94763;   27.81069;-1.0909e-002;0.82020
 328.93262;   27.90920;-1.0794e-002;0.81965
 329.91761;   28.00793;-1.0816e-002;0.81910
 330.90260;   28.10678;-1.0493e-002;0.81855
 331.88758;   28.20551;-1.0644e-002;0.81800
 332.87257;   28.30422;-1.0464e-002;0.81745
 333.85756;   28.40292;-1.0394e-002;0.81690
 334.84255;   28.50141;-1.0293e-002;0.81635
 335.82754;   28.59979;-1.0607e-002;0.81580
 336.81253;   28.69821;-1.0478e-002;0.81525
 337.79751;   28.79671;-1.0394e-002;0.81469
 338.78250;   28.89516;-1.0460e-002;0.81414
 339.76749;   28.99346;-1.0357e-002;0.81359
 340.75248;   29.09181;-1.0229e-002;0.81304
 341.73747;   29.19025;-1.0067e-002;0.81249
 342.72245;   29.28881;-1.0138e-002;0.81194
 343.70744;   29.38749;-1.0178e-002;0.81138
 344.69243;   29.48607;-1.0083e-002;0.81083
 345.67742;   29.58456;-1.0025e-002;0.81028
 346.66241;   29.68303;-1.0053e-002;0.80972
 347.64739;   29.78142;-9.9337e-003;0.80917
 348.63238;   29.87980;-9.7705e-003;0.80862
 349.61737;   29.97817;-9.9434e-003;0.80807
 350.60236;   30.07661;-9.7316e-003;0.80751
 351.58735;   30.17526;-9.7552e-003;0.80696
 352.57233;   30.27392;-9.7028e-003;0.80640
 353.55732;   30.37236;-1.0149e-002;0.80585
 354.54231;   30.47083;-9.6685e-003;0.80530
 355.52730;   30.56948;-9.6936e-003;0.80474
 356.51229;   30.66810;-9.5914e-003;0.80419
 357.49728;   30.76671;-9.4735e-003;0.80363
 358.48226;   30.86532;-9.2694e-003;0.80308
 359.46725;   30.96386;-9.3340e-003;0.80252
 360.45224;   31.06247;-9.2068e-003;0.80197
 361.43723;   31.16115;-9.3087e-003;0.80141
 362.42222;   31.25985;-9.3018e-003;0.80086
 363.40720;   31.35863;-9.1006e-003;0.80030
 364.39219;   31.45742;-8.8519e-003;0.79974
 365.37718;   31.55609;-8.7656e-003;0.79919
 366.36217;   31.65479;-8.5380e-003;0.79863
 367.34716;   31.75363;-8.4420e-003;0.79808
 368.33214;   31.85246;-8.2234e-003;0.79752
 369.31713;   31.95133;-8.0539e-003;0.79696
 370.30212;   32.05025;-8.1754e-003;0.79641
 371.28711;   32.14909;-8.0426e-003;0.79585
 372.27210;   32.24783;-8.0907e-003;0.79529
 373.25709;   32.34650;-7.6344e-003;0.79474
 374.24207;   32.44510;-7.5256e-003;0.79418
 375.22706;   32.54370;-7.4365e-003;0.79362
 376.21205;   32.64232;-7.4558e-003;0.79306
 377.19704;   32.74089;-7.5144e-003;0.79251
 378.18203;   32.83939;-7.4548e-003;0.79195
 379.16701;   32.93773;-7.5277e-003;0.79139
 380.15200;   33.03607;-7.3845e-003;0.79083
 381.13699;   33.13462;-7.3824e-003;0.79027
 382.12198;   33.23331;-7.2435e-003;0.78972
 383.10697;   33.33194;-6.9811e-003;0.78916
 384.09195;   33.43039;-6.9714e-003;0.78860
 385.07694;   33.52886;-6.8919e-003;0.78804
 386.06193;   33.62744;-7.3239e-003;0.78748
 387.04692;   33.72607;-7.4467e-003;0.78692
 388.03191;   33.82486;-7.3279e-003;0.78636
 389.01689;   33.92381;-6.9174e-003;0.78581
 390.00188;   34.02264;-6.8396e-003;0.78525
 390.98687;   34.12128;-6.8742e-003;0.78469
 391.97186;   34.21986;-6.3355e-003;0.78413
 392.95685;   34.31856;-6.4946e-003;0.78357
 393.94184;   34.41724;-6.7397e-003;0.78301
 394.92682;   34.51580;-6.6016e-003;0.78245
 395.91181;   34.61442;-7.1310e-003;0.78189
 396.89680;   34.71310;-7.6313e-003;0.78133
 397.88179;   34.81182;-7.2527e-003;0.78077
 398.86678;   34.91052;-7.2713e-003;0.78021
 399.85176;   35.00904;-7.0961e-003;0.77965
 400.83675;   35.10760;-6.9433e-003;0.77909
 401.82174;   35.20632;-7.2698e-003;0.77853
 402.80673;   35.30489;-7.3643e-003;0.77797
 403.79172;   35.40341;-7.4632e-003;0.77741
 404.77670;   35.50203;-7.2907e-003;0.77685
 405.76169;   35.60070;-7.3156e-003;0.77629
 406.74668;   35.69929;-6.8320e-003;0.77573
 407.73167;   35.79772;-6.6283e-003;0.77517
 408.71666;   35.89622;-6.8864e-003;0.77460
 409.70164;   35.99468;-6.8067e-003;0.77404
 410.68663;   36.09291;-7.0344e-003;0.77348
 411.67162;   36.19110;-7.0872e-003;0.77292
 412.65661;   36.28933;-7.1626e-003;0.77236
 413.64160;   36.38770;-7.1125e-003;0.77180
 414.62659;   36.48629;-6.8141e-003;0.77124
 415.61157;   36.58482;-6.5991e-003;0.77068
 416.59656;   36.68312;-6.3435e-003;0.77012
 417.58155;   36.78143;-6.1791e-003;0.76955
 418.56654;   36.87991;-6.3515e-003;0.76899
 419.55153;   36.97838;-6.3756e-003;0.76843
 420.53651;   37.07678;-6.3868e-003;0.76787
 421.52150;   37.17518;-6.3380e-003;0.76731
 422.50649;   37.27354;-6.1097e-003;0.76675
 423.49148;   37.37200;-6.1594e-003;0.76618
 424.47647;   37.47059;-5.8505e-003;0.76562
 425.46145;   37.56904;-6.0166e-003;0.76506
 426.44644;   37.66747;-6.0477e-003;0.76450
 427.43143;   37.76598;-6.1771e-003;0.76394
 428.41642;   37.86437;-5.9499e-003;0.76337
 429.40141;   37.96279;-5.5565e-003;0.76281
 430.38639;   38.06133;-5.5160e-003;0.76225
 431.37138;   38.15987;-5.3451e-003;0.76169
 432.35637;   38.25842;-5.1145e-003;0.76112
 433.34136;   38.35710;-5.1366e-003;0.76056
 434.32635;   38.45585;-4.8979e-003;0.76000
 435.31134;   38.55455;-5.1155e-003;0.75944
 436.29632;   38.65317;-4.6674e-003;0.75887
 437.28131;   38.75178;-4.4117e-003;0.75831
 438.26630;   38.85061;-4.4406e-003;0.75775
 439.25129;   38.94958;-4.2349e-003;0.75719
 440.23628;   39.04825;-3.1955e-003;0.75662
 441.22126;   39.14674;-3.0162e-003;0.75606
 442.20625;   39.24533;-3.1515e-003;0.75550
 443.19124;   39.34379;-3.2585e-003;0.75494
 444.17623;   39.44206;-2.9181e-003;0.75437
 445.16122;   39.54037;-2.6378e-003;0.75381
 446.14620;   39.63875;-2.3585e-003;0.75325
 447.13119;   39.73718;-2.7319e-003;0.75269
 448.11618;   39.83582;-2.6079e-003;0.75212
 449.10117;   39.93455;-2.7005e-003;0.75156
 450.08616;   40.03312;-2.7392e-003;0.75100
 451.07115;   40.13145;-2.5751e-003;0.75043
 452.05613;   40.22989;-2.5251e-003;0.74987
 453.04112;   40.32850;-2.3050e-003;0.74931
 454.02611;   40.42711;-2.2036e-003;0.74875
 455.01110;   40.52574;-2.3327e-003;0.74818
 455.99609;   40.62439;-2.1089e-003;0.74762
 456.98107;   40.72301;-2.4066e-003;0.74706
 457.96606;   40.82153;-2.5307e-003;0.74649
 458.95105;   40.91995;-2.1833e-003;0.74593
 459.93604;   41.01843;-2.4845e-003;0.74537
 460.92103;   41.11705;-2.5616e-003;0.74480
 461.90601;   41.21574;-2.2690e-003;0.74424
 462.89100;   41.31446;-2.3745e-003;0.74368
 463.87599;   41.41302;-2.4098e-003;0.74312
 464.86098;   41.51160;-2.4380e-003;0.74255
 465.84597;   41.61034;-2.5550e-003;0.74199
 466.83095;   41.70896;-2.6490e-003;0.74143
 467.81594;   41.80747;-2.2662e-003;0.74086
 468.80093;   41.90597;-2.5925e-003;0.74030
 469.78592;   42.00450;-2.2472e-003;0.73974
 470.77091;   42.10304;-2.3700e-003;0.73917
 471.75590;   42.20153;-2.4951e-003;0.73861
 472.74088;   42.30002;-2.4268e-003;0.73805
 473.72587;   42.39857;-1.8974e-003;0.73748
 474.71086;   42.49714;-1.6612e-003;0.73692
 475.69585;   42.59571;-1.5889e-003;0.73636
 476.68084;   42.69423;-1.8153e-003;0.73580
 477.66582;   42.79261;-1.9014e-003;0.73523
 478.65081;   42.89103;-2.0470e-003;0.73467
 479.63580;   42.98958;-1.6665e-003;0.73411
 480.62079;   43.08810;-1.7055e-003;0.73354
 481.60578;   43.18646;-1.3873e-003;0.73298
 482.59076;   43.28479;-1.1077e-003;0.73242
 483.57575;   43.38330;-1.0021e-003;0.73186
 484.56074;   43.48199;-1.0687e-003;0.73129
 485.54573;   43.58076;-8.9192e-004;0.73073
 486.53072;   43.67951;-9.8098e-004;0.73017
 487.51570;   43.77812;-7.1821e-004;0.72960
 488.50069;   43.87663;-5.0294e-004;0.72904
 489.48568;   43.97534; 9.2416e-005;0.72848
 490.47067;   44.07418; 7.1655e-004;0.72792
 491.45566;   44.17287; 6.7884e-004;0.72735
 492.44065;   44.27130; 7.9788e-004;0.72679
 493.42563;   44.36972; 9.8176e-004;0.72623
 494.41062;   44.46832; 1.3603e-003;0.72567
 495.39561;   44.56700; 1.5417e-003;0.72510
 496.38060;   44.66571; 1.3046e-003;0.72454
 497.36559;   44.76444; 1.1291e-003;0.72398
 498.35057;   44.86301; 9.8475e-004;0.72342
 499.33556;   44.96135; 1.0809e-003;0.72285
 500.32055;   45.05962; 1.3798e-003;0.72229
 501.30554;   45.15802; 1.6234e-003;0.72173
 502.29053;   45.25643; 1.9222e-003;0.72117
 503.27551;   45.35481; 2.0886e-003;0.72061
 504.26050;   45.45323; 2.1758e-003;0.72004
 505.24549;   45.55175; 2.1069e-003;0.71948
 506.23048;   45.65033; 2.3212e-003;0.71892
 507.21547;   45.74886; 2.2768e-003;0.71836
 508.20046;   45.84740; 2.4644e-003;0.71780
 509.18544;   45.94602; 2.7368e-003;0.71723
 510.17043;   46.04463; 2.8223e-003;0.71667
 511.15542;   46.14300; 3.0113e-003;0.71611
 512.14041;   46.24135; 2.8602e-003;0.71555
 513.12540;   46.33998; 3.1602e-003;0.71499
 514.11038;   46.43862; 3.0182e-003;0.71443
 515.09537;   46.53706; 3.1293e-003;0.71386
 516.08036;   46.63541; 3.4187e-003;0.71330
 517.06535;   46.73358; 3.5417e-003;0.71274
 518.05034;   46.83166; 3.6349e-003;0.71218
 519.03532;   46.92985; 3.8043e-003;0.71162
 520.02031;   47.02802; 3.9190e-003;0.71106
 521.00530;   47.12611; 4.2709e-003;0.71050
 521.99029;   47.22419; 3.9518e-003;0.70993
 522.97528;   47.32234; 4.3741e-003;0.70937
 523.96026;   47.42065; 4.1508e-003;0.70881
 524.94525;   47.51907; 4.2746e-003;0.70825
 525.93024;   47.61749; 4.3440e-003;0.70769
 526.91523;   47.71596; 4.2397e-003;0.70713
 527.90022;   47.81454; 4.3366e-003;0.70657
 528.88521;   47.91314; 4.4963e-003;0.70601
 529.87019;   48.01158; 4.8269e-003;0.70545
 530.85518;   48.10982; 4.8799e-003;0.70489
 531.84017;   48.20808; 5.0982e-003;0.70433
 532.82516;   48.30663; 5.3809e-003;0.70377
 533.81015;   48.40533; 5.3347e-003;0.70321
 534.79513;   48.50415; 5.6006e-003;0.70265
 535.78012;   48.60320; 5.7408e-003;0.70209
 536.76511;   48.70204; 5.9893e-003;0.70153
 537.75010;   48.80059; 5.8909e-003;0.70097
 538.73509;   48.89923; 6.0703e-003;0.70041
 539.72007;   48.99784; 6.0514e-003;0.69985
 540.70506;   49.09618; 6.2264e-003;0.69929
 541.69005;   49.19438; 6.2611e-003;0.69873
 542.67504;   49.29265; 5.8582e-003;0.69817
 543.66003;   49.39083; 6.0259e-003;0.69761
 544.64501;   49.48891; 6.0399e-003;0.69705
 545.63000;   49.58718; 5.8464e-003;0.69649
 546.61499;   49.68560; 6.2466e-003;0.69593
 547.59998;   49.78393; 6.1148e-003;0.69537
 548.58497;   49.88215; 6.2132e-003;0.69481
 549.56996;   49.98050; 6.7152e-003;0.69426
 550.55494;   50.07907; 6.5662e-003;0.69370
 551.53993;   50.17770; 6.7073e-003;0.69314
 552.52492;   50.27632; 6.6116e-003;0.69258
 553.50991;   50.37490; 6.9971e-003;0.69202
 554.49490;   50.47354; 7.0946e-003;0.69146
 555.47988;   50.57218; 7.0917e-003;0.69090
 556.46487;   50.67078; 7.2173e-003;0.69035
 557.44986;   50.76951; 7.3503e-003;0.68979
 558.43485;   50.86837; 7.3642e-003;0.68923
 559.41984;   50.96713; 7.5655e-003;0.68867
 560.40482;   51.06580; 7.4807e-003;0.68812
 561.38981;   51.16462; 7.6072e-003;0.68756
 562.37480;   51.26350; 7.2000e-003;0.68700
 563.35979;   51.36217; 7.5344e-003;0.68644
 564.34478;   51.46078; 7.6255e-003;0.68589
 565.32977;   51.55945; 7.4908e-003;0.68533
 566.31475;   51.65810; 7.5432e-003;0.68477
 567.29974;   51.75676; 7.3788e-003;0.68421
 568.28473;   51.85552; 7.5255e-003;0.68366
 569.26972;   51.95426; 7.5105e-003;0.68310
 570.25471;   52.05289; 7.6906e-003;0.68254
 571.23969;   52.15142; 7.7945e-003;0.68199
 572.22468;   52.24987; 8.1238e-003;0.68143
 573.20967;   52.34842; 8.7639e-003;0.68088
 574.19466;   52.44707; 8.8598e-003;0.68032
 575.17965;   52.54561; 9.2909e-003;0.67976
 576.16463;   52.64401; 9.4079e-003;0.67921
 577.14962;   52.74230; 9.3724e-003;0.67865
 578.13461;   52.84065; 9.4227e-003;0.67810
 579.11960;   52.93910; 9.5188e-003;0.67754
 580.10459;   53.03732; 9.1148e-003;0.67698
 581.08957;   53.13533; 8.8168e-003;0.67643
 582.07456;   53.23338; 9.0641e-003;0.67587
 583.05955;   53.33169; 8.8980e-003;0.67532
 584.04454;   53.43022; 8.9914e-003;0.67476
 585.02953;   53.52869; 9.1966e-003;0.67421
 586.01452;   53.62700; 9.3424e-003;0.67365
 586.99950;   53.72518; 9.6479e-003;0.67310
 587.98449;   53.82342; 9.7137e-003;0.67255
 588.96948;   53.92181; 9.6135e-003;0.67199
 589.95447;   54.02020; 9.6997e-003;0.67144
 590.93946;   54.11849; 9.6969e-003;0.67088
 591.92444;   54.21680; 9.9928e-003;0.67033
 592.90943;   54.31524; 1.0352e-002;0.66978
 593.89442;   54.41365; 1.0251e-002;0.66922
 594.87941;   54.51201; 1.0483e-002;0.66867
 595.86440;   54.61037; 1.0263e-002;0.66812
 596.84938;   54.70879; 1.0231e-002;0.66756
 597.83437;   54.80729; 1.0282e-002;0.66701
 598.81936;   54.90568; 1.0073e-002;0.66646
 599.80435;   55.00407; 1.0278e-002;0.66590
 600.78934;   55.10249; 1.0265e-002;0.66535
 601.77432;   55.20085; 1.0154e-002;0.66480
 602.75931;   55.29937; 9.8488e-003;0.66425
 603.74430;   55.39801; 1.0026e-002;0.66369
 604.72929;   55.49657; 9.9446e-003;0.66314
 605.71428;   55.59508; 1.0355e-002;0.66259
 606.69927;   55.69368; 1.0664e-002;0.66204
 607.68425;   55.79218; 1.0633e-002;0.66149
 608.66924;   55.89049; 1.0964e-002;0.66094
 609.65423;   55.98894; 1.0666e-002;0.66038
 610.63922;   56.08759; 1.0582e-002;0.65983
 611.62421;   56.18611; 1.0873e-002;0.65928
 612.60919;   56.28447; 1.1071e-002;0.65873
 613.59418;   56.38286; 1.1185e-002;0.65818
 614.57917;   56.48129; 1.1247e-002;0.65763
 615.56416;   56.57977; 1.1213e-002;0.65708
 616.54915;   56.67842; 1.0924e-002;0.65653
 617.53413;   56.77716; 1.1349e-002;0.65598
 618.51912;   56.87584; 1.1193e-002;0.65543
 619.50411;   56.97429; 1.0979e-002;0.65488
 620.48910;   57.07274; 1.0858e-002;0.65433
 621.47409;   57.17146; 1.1278e-002;0.65378
 622.45908;   57.27011; 1.1281e-002;0.65323
 623.44406;   57.36849; 1.1318e-002;0.65268
 624.42905;   57.46685; 1.1055e-002;0.65213
 625.41404;   57.56524; 1.1314e-002;0.65158
 626.39903;   57.66361; 1.1381e-002;0.65103
 627.38402;   57.76196; 1.1657e-002;0.65049
 628.36900;   57.86017; 1.1342e-002;0.64994
 629.35399;   57.95830; 1.1175e-002;0.64939
 630.33898;   58.05659; 1.1547e-002;0.64884
 631.32397;   58.15509; 1.1642e-002;0.64829
 632.30896;   58.25364; 1.1820e-002;0.64775
 633.29394;   58.35215; 1.1526e-002;0.64720
 634.27893;   58.45063; 1.2010e-002;0.64665
 635.26392;   58.54896; 1.2125e-002;0.64610
 636.24891;   58.64720; 1.2296e-002;0.64556
 637.23390;   58.74553; 1.2272e-002;0.64501
 638.21888;   58.84387; 1.2301e-002;0.64446
 639.20387;   58.94209; 1.2484e-002;0.64392
 640.18886;   59.04011; 1.2716e-002;0.64337
 641.17385;   59.13792; 1.2595e-002;0.64282
 642.15884;   59.23556; 1.2567e-002;0.64228
 643.14383;   59.33306; 1.2528e-002;0.64173
 644.12881;   59.43053; 1.2511e-002;0.64119
 645.11380;   59.52812; 1.2390e-002;0.64064
 646.09879;   59.62596; 1.2386e-002;0.64009
 647.08378;   59.72407; 1.2018e-002;0.63955
 648.06877;   59.82231; 1.2081e-002;0.63900
 649.05375;   59.92057; 1.2019e-002;0.63846
 650.03874;   60.01882; 1.2115e-002;0.63791
 651.02373;   60.11703; 1.2355e-002;0.63737
 652.00872;   60.21538; 1.2318e-002;0.63683
 652.99371;   60.31411; 1.2320e-002;0.63628
 653.97869;   60.41301; 1.2522e-002;0.63574
 654.96368;   60.51197; 1.2948e-002;0.63519
 655.94867;   60.61105; 1.3269e-002;0.63465
 656.93366;   60.71015; 1.3323e-002;0.63411
 657.91865;   60.80921; 1.3633e-002;0.63356
 658.90363;   60.90820; 1.3833e-002;0.63302
 659.88862;   61.00730; 1.4128e-002;0.63248
 660.87361;   61.10652; 1.4232e-002;0.63194
 661.85860;   61.20556; 1.4278e-002;0.63139
 662.84359;   61.30455; 1.4310e-002;0.63085
 663.82858;   61.40346; 1.4307e-002;0.63031
 664.81356;   61.50209; 1.4569e-002;0.62977
 665.79855;   61.60070; 1.4522e-002;0.62922
 666.78354;   61.69955; 1.4670e-002;0.62868
 667.76853;   61.79840; 1.4627e-002;0.62814
 668.75352;   61.89703; 1.4756e-002;0.62760
 669.73850;   61.99557; 1.5394e-002;0.62706
 670.72349;   62.09412; 1.7363e-002;0.62652
 671.70848;   62.19263; 1.4666e-002;0.62598
 672.69347;   62.29120; 1.4276e-002;0.62544
 673.67846;   62.39002; 1.4724e-002;0.62490
 674.66344;   62.48875; 1.4802e-002;0.62436
 675.64843;   62.58717; 1.5107e-002;0.62382
 676.63342;   62.68553; 1.4593e-002;0.62328
 677.61841;   62.78385; 1.4417e-002;0.62274
 678.60340;   62.88206; 1.4641e-002;0.62220
 679.58839;   62.98036; 1.4372e-002;0.62166
 680.57337;   63.07886; 1.4139e-002;0.62112
 681.55836;   63.17744; 1.4228e-002;0.62058
 682.54335;   63.27594; 1.4640e-002;0.62004
 683.52834;   63.37428; 1.5244e-002;0.61951
 684.51333;   63.47256; 1.5539e-002;0.61897
 685.49831;   63.57102; 1.5522e-002;0.61843
 686.48330;   63.66968; 1.5487e-002;0.61789
 687.46829;   63.76835; 1.5363e-002;0.61735
 688.45328;   63.86712; 1.5440e-002;0.61682
 689.43827;   63.96610; 1.5917e-002;0.61628
 690.42325;   64.06507; 1.6158e-002;0.61574
 691.40824;   64.16385; 1.6713e-002;0.61521
 692.39323;   64.26256; 1.7196e-002;0.61467
 693.37822;   64.36122; 1.6768e-002;0.61413
 694.36321;   64.45983; 1.6386e-002;0.61360
 695.34819;   64.55849; 1.5327e-002;0.61306
 696.33318;   64.65714; 1.4458e-002;0.61252
 697.31817;   64.75560; 1.3900e-002;0.61199
 698.30316;   64.85383; 1.3713e-002;0.61145
 699.28815;   64.95196; 1.3910e-002;0.61092
 700.27314;   65.05011; 1.4073e-002;0.61038
 701.25812;   65.14833; 1.5750e-002;0.60985
 702.24311;   65.24648; 1.6133e-002;0.60931
 703.22810;   65.34444; 1.6189e-002;0.60878
 704.21309;   65.44244; 1.6267e-002;0.60825
 705.19808;   65.54076; 1.5911e-002;0.60771
 706.18306;   65.63921; 1.6190e-002;0.60718
 707.16805;   65.73743; 1.6632e-002;0.60665
 708.15304;   65.83566; 1.7068e-002;0.60611
 709.13803;   65.93408; 1.7143e-002;0.60558
 710.12302;   66.03269; 1.7355e-002;0.60505
 711.10800;   66.13148; 1.7837e-002;0.60451
 712.09299;   66.23026; 1.7863e-002;0.60398
 713.07798;   66.32887; 1.8137e-002;0.60345
 714.06297;   66.42729; 1.8448e-002;0.60292
 715.04796;   66.52570; 1.8326e-002;0.60238
 716.03294;   66.62435; 1.8467e-002;0.60185
 717.01793;   66.72309; 1.8209e-002;0.60132
 718.00292;   66.82172; 1.8274e-002;0.60079
 718.98791;   66.92028; 1.8686e-002;0.60026
 719.97290;   67.01889; 1.8370e-002;0.59973
 720.95789;   67.11761; 1.8475e-002;0.59920
 721.94287;   67.21634; 1.8417e-002;0.59867
 722.92786;   67.31508; 1.8057e-002;0.59814
 723.91285;   67.41390; 1.8349e-002;0.59761
 724.89784;   67.51278; 1.8611e-002;0.59708
 725.88283;   67.61164; 1.8851e-002;0.59655
 726.86781;   67.71031; 1.8446e-002;0.59602
 727.85280;   67.80881; 1.7999e-002;0.59549
 728.83779;   67.90723; 1.8850e-002;0.59496
 729.82278;   68.00565; 1.9221e-002;0.59443
 730.80777;   68.10414; 1.9085e-002;0.59390
 731.79275;   68.20260; 1.8641e-002;0.59338
 732.77774;   68.30094; 1.8766e-002;0.59285
 733.76273;   68.39931; 1.8443e-002;0.59232
 734.74772;   68.49787; 1.8352e-002;0.59179
 735.73271;   68.59646; 1.8590e-002;0.59127
 736.71769;   68.69498; 1.8035e-002;0.59074
 737.70268;   68.79348; 1.8107e-002;0.59021
 738.68767;   68.89187; 1.7909e-002;0.58969
 739.67266;   68.99003; 1.7586e-002;0.58916
 740.65765;   69.08803; 1.7306e-002;0.58863
 741.64264;   69.18590; 1.7172e-002;0.58811
 742.62762;   69.28361; 1.7223e-002;0.58758
 743.61261;   69.38131; 1.6920e-002;0.58706
 744.59760;   69.47921; 1.7830e-002;0.58653
 745.58259;   69.57739; 1.7409e-002;0.58601
 746.56758;   69.67569; 1.7146e-002;0.58548
 747.55256;   69.77391; 1.6979e-002;0.58496
 748.53755;   69.87222; 1.6895e-002;0.58443
 749.52254;   69.97069; 1.6919e-002;0.58391
 750.50753;   70.06916; 1.7169e-002;0.58338
 751.49252;   70.16765; 1.7006e-002;0.58286
 752.47750;   70.26620; 1.6779e-002;0.58234
 753.46249;   70.36478; 1.7004e-002;0.58181
 754.44748;   70.46353; 1.6844e-002;0.58129
 755.43247;   70.56247; 1.7719e-002;0.58077
 756.41746;   70.66140; 1.7933e-002;0.58025
 757.40245;   70.76025; 1.7905e-002;0.57972
 758.38743;   70.85905; 1.8057e-002;0.57920
 759.37242;   70.95785; 1.7749e-002;0.57868
 760.35741;   71.05661; 1.7357e-002;0.57816
 761.34240;   71.15537; 1.7645e-002;0.57764
 762.32739;   71.25413; 1.8174e-002;0.57711
 763.31237;   71.35277; 1.8570e-002;0.57659
 764.29736;   71.45128; 1.8793e-002;0.57607
 765.28235;   71.54979; 1.9096e-002;0.57555
 766.26734;   71.64834; 1.9619e-002;0.57503
 767.25233;   71.74671; 1.9700e-002;0.57451
 768.23731;   71.84503; 1.9865e-002;0.57399
 769.22230;   71.94362; 2.0232e-002;0.57347
 770.20729;   72.04232; 1.9339e-002;0.57295
 771.19228;   72.14097; 1.9558e-002;0.57243
 772.17727;   72.23963; 1.9706e-002;0.57192
 773.16225;   72.33837; 1.9672e-002;0.57140
 774.14724;   72.43709; 1.9611e-002;0.57088
 775.13223;   72.53559; 2.0182e-002;0.57036
 776.11722;   72.63390; 2.0112e-002;0.56984
 777.10221;   72.73221; 1.9942e-002;0.56932
 778.08720;   72.83073; 2.0081e-002;0.56881
 779.07218;   72.93016; 1.9990e-002;0.56829
 780.05717;   73.03100; 1.9550e-002;0.56777
 781.04216;   73.13269; 1.9759e-002;0.56726
 782.02715;   73.23466; 2.0161e-002;0.56674
 783.01214;   73.33680; 2.0527e-002;0.56622
 783.99712;   73.43859; 2.0947e-002;0.56571
 784.98211;   73.53980; 2.1648e-002;0.56519
 785.96710;   73.64051; 2.1957e-002;0.56468
 786.95209;   73.74072; 2.1807e-002;0.56416
 787.93708;   73.84027; 2.1779e-002;0.56365
 788.92206;   73.93914; 2.2024e-002;0.56313
 789.90705;   74.03740; 2.2541e-002;0.56262
 790.89204;   74.13513; 2.2430e-002;0.56210
 791.87703;   74.23253; 2.2727e-002;0.56159
 792.86202;   74.32964; 2.2682e-002;0.56107
 793.84700;   74.42637; 2.2091e-002;0.56056
 794.83199;   74.52297; 2.1908e-002;0.56005
 795.81698;   74.61966; 2.1645e-002;0.55953
 796.80197;   74.71639; 2.1491e-002;0.55902
 797.78696;   74.81315; 2.1176e-002;0.55851
 798.77195;   74.90989; 2.1486e-002;0.55799
 799.75693;   75.00673; 2.1397e-002;0.55748
 800.74192;   75.10382; 2.1159e-002;0.55697
 801.72691;   75.20117; 2.1447e-002;0.55646
 802.71190;   75.29869; 2.1539e-002;0.55595
 803.69689;   75.39637; 2.1296e-002;0.55544
 804.68187;   75.49413; 2.1200e-002;0.55493
 805.66686;   75.59207; 2.1317e-002;0.55441
 806.65185;   75.69022; 2.1792e-002;0.55390
 807.63684;   75.78844; 2.2432e-002;0.55339
 808.62183;   75.88672; 2.2164e-002;0.55288
 809.60681;   75.98506; 2.1151e-002;0.55237
 810.59180;   76.08355; 2.0951e-002;0.55186
 811.57679;   76.18215; 2.0933e-002;0.55135
 812.56178;   76.28066; 2.0846e-002;0.55085
 813.54677;   76.37906; 2.0591e-002;0.55034
 814.53176;   76.47738; 2.0517e-002;0.54983
 815.51674;   76.57558; 2.0477e-002;0.54932
 816.50173;   76.67369; 2.0909e-002;0.54881
 817.48672;   76.77192; 2.0635e-002;0.54830
 818.47171;   76.87033; 2.0885e-002;0.54780
 819.45670;   76.96876; 2.0540e-002;0.54729
 820.44168;   77.06705; 2.0337e-002;0.54678
 821.42667;   77.16526; 2.0726e-002;0.54627
 822.41166;   77.26366; 2.0816e-002;0.54577
 823.39665;   77.36216; 2.0407e-002;0.54526
 824.38164;   77.46051; 2.0706e-002;0.54475
 825.36662;   77.55880; 2.0544e-002;0.54425
 826.35161;   77.65729; 2.0396e-002;0.54374
 827.33660;   77.75588; 2.0680e-002;0.54324
 828.32159;   77.85432; 2.0577e-002;0.54273
 829.30658;   77.95260; 2.0712e-002;0.54223
 830.29156;   78.05095; 2.0632e-002;0.54172
 831.27655;   78.14949; 2.0798e-002;0.54122
 832.26154;   78.24795; 2.1130e-002;0.54071
 833.24653;   78.34621; 2.1866e-002;0.54021
 834.23152;   78.44446; 2.1986e-002;0.53971
 835.21651;   78.54280; 2.2220e-002;0.53920
 836.20149;   78.64112; 2.2764e-002;0.53870
 837.18648;   78.73940; 2.3261e-002;0.53820
 838.17147;   78.83776; 2.3113e-002;0.53769
 839.15646;   78.93620; 2.3113e-002;0.53719
 840.14145;   79.03471; 2.3175e-002;0.53669
 841.12643;   79.13322; 2.3537e-002;0.53619
 842.11142;   79.23171; 2.3536e-002;0.53569
 843.09641;   79.33020; 2.3623e-002;0.53518
 844.08140;   79.42872; 2.4147e-002;0.53468
 845.06639;   79.52733; 2.4050e-002;0.53418
 846.05137;   79.62601; 2.4188e-002;0.53368
 847.03636;   79.72462; 2.4493e-002;0.53318
 848.02135;   79.82309; 2.4722e-002;0.53268
 849.00634;   79.92152; 2.5551e-002;0.53218
 849.99133;   80.02002; 2.5881e-002;0.53168
 850.97631;   80.11853; 2.5786e-002;0.53118
 851.96130;   80.21686; 2.5745e-002;0.53068
 852.94629;   80.31511; 2.5467e-002;0.53018
 853.93128;   80.41360; 2.5323e-002;0.52968
 854.91627;   80.51228; 2.5560e-002;0.52919
 855.90126;   80.61089; 2.5918e-002;0.52869
 856.88624;   80.70936; 2.5997e-002;0.52819
 857.87123;   80.80787; 2.5949e-002;0.52769
 858.85622;   80.90636; 2.5370e-002;0.52719
 859.84121;   81.00467; 2.5882e-002;0.52670
 860.82620;   81.10300; 2.5615e-002;0.52620
 861.81118;   81.20153; 2.5662e-002;0.52570
 862.79617;   81.30011; 2.6085e-002;0.52521
 863.78116;   81.39858; 2.5509e-002;0.52471
 864.76615;   81.49705; 2.5584e-002;0.52421
 865.75114;   81.59563; 2.5554e-002;0.52372
 866.73612;   81.69424; 2.5833e-002;0.52322
 867.72111;   81.79275; 2.5806e-002;0.52273
 868.70610;   81.89110; 2.5240e-002;0.52223
 869.69109;   81.98928; 2.5232e-002;0.52174
 870.67608;   82.08748; 2.5642e-002;0.52124
 871.66107;   82.18580; 2.5764e-002;0.52075
 872.64605;   82.28413; 2.5992e-002;0.52026
 873.63104;   82.38244; 2.5869e-002;0.51976
 874.61603;   82.48082; 2.6310e-002;0.51927
 875.60102;   82.57920; 2.6352e-002;0.51878
 876.58601;   82.67756; 2.6450e-002;0.51828
 877.57099;   82.77593; 2.6183e-002;0.51779
 878.55598;   82.87425; 2.6886e-002;0.51730
 879.54097;   82.97253; 2.7433e-002;0.51680
 880.52596;   83.07082; 2.7092e-002;0.51631
 881.51095;   83.16913; 2.7194e-002;0.51582
 882.49593;   83.26745; 2.7281e-002;0.51533
 883.48092;   83.36590; 2.7013e-002;0.51484
 884.46591;   83.46454; 2.7672e-002;0.51435
 885.45090;   83.56327; 2.7374e-002;0.51386
 886.43589;   83.66191; 2.7534e-002;0.51337
 887.42087;   83.76041; 2.7460e-002;0.51288
 888.40586;   83.85892; 2.7136e-002;0.51239
 889.39085;   83.95760; 2.7180e-002;0.51190
 890.37584;   84.05641; 2.6600e-002;0.51141
 891.36083;   84.15514; 2.6560e-002;0.51092
 892.34582;   84.25381; 2.6400e-002;0.51043
 893.33080;   84.35247; 2.6490e-002;0.50994
 894.31579;   84.45099; 2.6680e-002;0.50945
 895.30078;   84.54937; 2.6514e-002;0.50896
 896.28577;   84.64778; 2.7064e-002;0.50848
 897.27076;   84.74625; 2.6882e-002;0.50799
 898.25574;   84.84470; 2.7485e-002;0.50750
 899.24073;   84.94321; 2.7783e-002;0.50701
 900.22572;   85.04180; 2.8164e-002;0.50653
 901.21071;   85.14028; 2.8435e-002;0.50604
 902.19570;   85.23876; 2.8420e-002;0.50555
 903.18068;   85.33741; 2.8886e-002;0.50507
 904.16567;   85.43621; 2.8678e-002;0.50458
 905.15066;   85.53500; 2.9047e-002;0.50410
 906.13565;   85.63364; 2.9299e-002;0.50361
 907.12064;   85.73217; 2.9726e-002;0.50312
 908.10562;   85.83068; 2.9664e-002;0.50264
 909.09061;   85.92929; 2.9751e-002;0.50216
 910.07560;   86.02792; 2.9215e-002;0.50167
 911.06059;   86.12638; 2.9403e-002;0.50119
 912.04558;   86.22463; 2.9708e-002;0.50070
 913.03057;   86.32272; 3.0448e-002;0.50022
 914.01555;   86.42066; 2.9862e-002;0.49974
 915.00054;   86.51849; 3.0238e-002;0.49925
 915.98553;   86.61619; 3.0161e-002;0.49877
 916.97052;   86.71379; 3.0278e-002;0.49829
 917.95551;   86.81131; 3.0298e-002;0.49781
 918.94049;   86.90891; 2.9915e-002;0.49732
 919.92548;   87.00682; 2.9865e-002;0.49684
 920.91047;   87.10501; 3.0072e-002;0.49636
 921.89546;   87.20320; 3.0500e-002;0.49588
 922.88045;   87.30134; 3.0682e-002;0.49540
 923.86543;   87.39958; 3.0296e-002;0.49492
 924.85042;   87.49795; 3.0636e-002;0.49444
 925.83541;   87.59642; 3.0291e-002;0.49396
 926.82040;   87.69505; 3.0813e-002;0.49348
 927.80539;   87.79381; 3.1259e-002;0.49300
 928.79038;   87.89263; 3.2556e-002;0.49252
 929.77536;   87.99146; 3.3079e-002;0.49204
 930.76035;   88.09027; 3.3292e-002;0.49156
 931.74534;   88.18906; 3.4402e-002;0.49108
 932.73033;   88.28769; 3.5372e-002;0.49060
 933.71532;   88.38617; 3.5672e-002;0.49012
 934.70030;   88.48463; 3.5096e-002;0.48964
 935.68529;   88.58309; 3.5452e-002;0.48917
 936.67028;   88.68166; 3.5963e-002;0.48869
 937.65527;   88.78031; 3.6397e-002;0.48821
 938.64026;   88.87880; 3.6772e-002;0.48773
 939.62524;   88.97715; 3.6314e-002;0.48726
 940.61023;   89.07547; 3.6087e-002;0.48678
 941.59522;   89.17375; 3.6452e-002;0.48631
 942.58021;   89.27204; 3.6331e-002;0.48583
 943.56520;   89.37036; 3.6662e-002;0.48535
 944.55018;   89.46874; 3.7259e-002;0.48488
 945.53517;   89.56722; 3.6872e-002;0.48440
 946.52016;   89.66576; 3.7478e-002;0.48393
 947.50515;   89.76427; 3.7380e-002;0.48345
 948.49014;   89.86276; 3.7586e-002;0.48298
 949.47513;   89.96126; 3.7586e-002;0.48250
 950.46011;   90.05982; 3.7840e-002;0.48203
 951.44510;   90.15845; 3.8491e-002;0.48156
 952.43009;   90.25697; 3.8423e-002;0.48108
 953.41508;   90.35539; 3.8266e-002;0.48061
 954.40007;   90.45393; 3.8545e-002;0.48014
 955.38505;   90.55252; 3.8608e-002;0.47966
 956.37004;   90.65109; 3.8456e-002;0.47919
 957.35503;   90.74965; 3.8484e-002;0.47872
 958.34002;   90.84820; 3.8551e-002;0.47825
 959.32501;   90.94683; 3.8686e-002;0.47778
 960.30999;   91.04553; 3.8053e-002;0.47730
 961.29498;   91.14420; 3.8370e-002;0.47683
 962.27997;   91.24279; 3.7760e-002;0.47636
 963.26496;   91.34134; 3.7965e-002;0.47589
 964.24995;   91.43998; 3.7550e-002;0.47542
 965.23493;   91.53871; 3.7282e-002;0.47495
 966.21992;   91.63747; 3.6796e-002;0.47448
 967.20491;   91.73621; 3.6974e-002;0.47401
 968.18990;   91.83482; 3.6024e-002;0.47354
 969.17489;   91.93335; 3.6446e-002;0.47307
 970.15988;   92.03186; 3.6199e-002;0.47260
 971.14486;   92.13046; 3.5519e-002;0.47214
 972.12985;   92.22906; 3.6004e-002;0.47167
 973.11484;   92.32746; 3.5897e-002;0.47120
 974.09983;   92.42582; 3.5604e-002;0.47073
 975.08482;   92.52427; 3.5837e-002;0.47026
 976.06980;   92.62270; 3.6010e-002;0.46980
 977.05479;   92.72124; 3.5701e-002;0.46933
 978.03978;   92.81992; 3.5079e-002;0.46886
 979.02477;   92.91865; 3.5198e-002;0.46840
 980.00976;   93.01749; 3.5451e-002;0.46793
 980.99474;   93.11629; 3.5353e-002;0.46746
 981.97973;   93.21491; 3.5085e-002;0.46700
 982.96472;   93.31344; 3.5080e-002;0.46653
 983.94971;   93.41199; 3.5523e-002;0.46607
 984.93470;   93.51064; 3.5015e-002;0.46560
 985.91969;   93.60928; 3.4747e-002;0.46514
 986.90467;   93.70789; 3.4980e-002;0.46467
 987.88966;   93.80647; 3.4907e-002;0.46421
 988.87465;   93.90503; 3.5279e-002;0.46374
 989.85964;   94.00358; 3.4406e-002;0.46328
 990.84463;   94.10212; 3.4516e-002;0.46282
 991.82961;   94.20061; 3.5483e-002;0.46235
 992.81460;   94.29907; 3.5283e-002;0.46189
 993.79959;   94.39764; 3.5513e-002;0.46143
 994.78458;   94.49651; 3.5589e-002;0.46097
 995.76957;   94.59553; 3.5820e-002;0.46050
 996.75455;   94.69446; 3.5667e-002;0.46004
 997.73954;   94.79322; 3.5080e-002;0.45958
 998.72453;   94.89172; 3.5461e-002;0.45912
 999.70952;   94.99004; 3.6037e-002;0.45866
1000.69451;   95.08830; 3.5709e-002;0.45820
1001.67949;   95.18647; 3.5488e-002;0.45774
1002.66448;   95.28447; 3.5798e-002;0.45727
1003.64947;   95.38240; 3.5991e-002;0.45681
1004.63446;   95.48044; 3.5888e-002;0.45635
1005.61945;   95.57855; 3.5270e-002;0.45589
1006.60444;   95.67668; 3.6471e-002;0.45544
1007.58942;   95.77479; 3.6379e-002;0.45498
1008.57441;   95.87284; 3.6327e-002;0.45452
1009.55940;   95.97090; 3.6635e-002;0.45406
1010.54439;   96.06904; 3.6687e-002;0.45360
1011.52938;   96.16747; 3.7202e-002;0.45314
1012.51436;   96.26599; 3.6841e-002;0.45268
1013.49935;   96.36428; 3.6860e-002;0.45223
1014.48434;   96.46253; 3.6654e-002;0.45177
1015.46933;   96.56099; 3.7386e-002;0.45131
1016.45432;   96.65944; 3.8686e-002;0.45085
1017.43930;   96.75776; 3.7974e-002;0.45040
1018.42429;   96.85618; 3.8315e-002;0.44994
1019.40928;   96.95468; 3.7898e-002;0.44948
1020.39427;   97.05329; 3.8986e-002;0.44903
1021.37926;   97.15201; 3.9484e-002;0.44857
1022.36424;   97.25066; 3.8847e-002;0.44812
1023.34923;   97.34928; 3.9040e-002;0.44766
1024.33422;   97.44792; 3.8647e-002;0.44721
1025.31921;   97.54655; 3.8455e-002;0.44675
1026.30420;   97.64518; 3.8309e-002;0.44630
1027.28919;   97.74382; 3.8536e-002;0.44584
1028.27417;   97.84236; 3.8967e-002;0.44539
1029.25916;   97.94088; 3.8894e-002;0.44494
1030.24415;   98.03943; 3.9054e-002;0.44448
1031.22914;   98.13795; 3.8998e-002;0.44403
1032.21413;   98.23642; 3.9331e-002;0.44358
1033.19911;   98.33493; 3.9438e-002;0.44312
1034.18410;   98.43356; 3.9861e-002;0.44267
1035.16909;   98.53225; 3.9702e-002;0.44222
1036.15408;   98.63086; 3.9985e-002;0.44177
1037.13907;   98.72935; 3.9656e-002;0.44132
1038.12405;   98.82784; 4.0239e-002;0.44086
1039.10904;   98.92637; 4.0166e-002;0.44041
1040.09403;   99.02478; 4.1057e-002;0.43996
1041.07902;   99.12311; 4.0618e-002;0.43951
1042.06401;   99.22150; 4.0863e-002;0.43906
1043.04899;   99.31995; 4.0749e-002;0.43861
1044.03398;   99.41838; 4.0814e-002;0.43816
1045.01897;   99.51684; 4.0873e-002;0.43771
1046.00396;   99.61533; 4.1261e-002;0.43726
1046.98895;   99.71377; 4.1805e-002;0.43681
1047.97394;   99.81212; 4.1701e-002;0.43636
1048.95892;   99.91055; 4.1939e-002;0.43591
1049.94391;  100.00910; 4.0959e-002;0.43547
1050.92890;  100.10766; 4.1022e-002;0.43502
1051.91389;  100.20609; 4.1407e-002;0.43457
1052.89888;  100.30452; 4.1415e-002;0.43412
1053.88386;  100.40312; 4.1037e-002;0.43367
1054.86885;  100.50169; 4.1046e-002;0.43323
1055.85384;  100.60017; 4.0638e-002;0.43278
1056.83883;  100.69874; 4.0787e-002;0.43233
1057.82382;  100.79737; 3.8939e-002;0.43189
1058.80880;  100.89600; 3.4436e-002;0.43144
1059.79379;  100.99474; 1.3325e-002;0.43099
1060.77878;  101.09367;-5.0828e-002;0.43055
1061.76377;  101.19275;    -0.15375;0.43010
1062.74876;  101.29201;    -0.28213;0.42966
1063.73375;  101.39132;    -0.42564;0.42921
1064.71873;  101.49060;    -0.56597;0.42877
1065.70372;  101.58977;    -0.70405;0.42832
1066.68871;  101.68870;    -0.84043;0.42788
1067.67370;  101.78739;    -0.97538;0.42744
1068.65869;  101.88556;    -1.10524;0.42699
1069.64367;  101.98283;    -0.60278;0.42655
1070.62866;  102.07940;    -0.33868;0.42611
1071.61365;  102.17584;    -0.19478;0.42566
1072.59864;  102.27264;    -0.10645;0.42522
1073.58363;  102.36998;-5.0421e-002;0.42478
1074.56861;  102.46771;-1.3774e-002;0.42433
1075.55360;  102.56576; 1.1116e-002;0.42389
1076.53859;  102.66412; 2.6670e-002;0.42345
1077.52358;  102.76277; 3.6868e-002;0.42301
1078.50857;  102.86163; 4.4068e-002;0.42257
1079.49355;  102.96058; 4.9028e-002;0.42213
1080.47854;  103.05950; 5.1988e-002;0.42169
1081.46353;  103.15843; 5.4646e-002;0.42125
1082.44852;  103.25721; 5.6265e-002;0.42081
1083.43351;  103.35579; 5.7716e-002;0.42037
1084.41850;  103.45450; 5.8907e-002;0.41993
1085.40348;  103.55337; 5.9056e-002;0.41949
1086.38847;  103.65215; 5.9802e-002;0.41905
1087.37346;  103.75082; 6.0068e-002;0.41861
1088.35845;  103.84953; 6.0031e-002;0.41817
1089.34344;  103.94824; 6.0493e-002;0.41773
1090.32842;  104.04687; 6.0488e-002;0.41729
1091.31341;  104.14529; 6.0172e-002;0.41685
1092.29840;  104.24353; 6.0371e-002;0.41642
1093.28339;  104.34186; 6.1040e-002;0.41598
1094.26838;  104.44024; 6.0836e-002;0.41554
1095.25336;  104.53857; 6.1669e-002;0.41510
1096.23835;  104.63698; 6.1953e-002;0.41467
1097.22334;  104.73545; 6.2356e-002;0.41423
1098.20833;  104.83383; 6.2633e-002;0.41379
1099.19332;  104.93201; 6.2809e-002;0.41336
1099.78431;  104.99062; 6.2664e-002;0.41310