File: Thesis/DSC/Ti6242-Cool.txt
#FILE:Ti6242.ngb-ds3
#FORMAT:NETZSCH5
#FTYPE:ASCII
#IDENTITY:As Received
#DECIMAL:POINT
#SEPARATOR:SEMICOLON
#MTYPE:DSC
#INSTRUMENT:NETZSCH STA 449F3
#PROJECT:MET
#DATE/TIME:04.12.2017 16:45
#CORR. FILE:Ti6242.ngb-bs3
#LABORATORY:DB
#OPERATOR:Sharan
#REMARK:
#SAMPLE:Ti6242
#SAMPLE MASS /mg:57.898
#MATERIAL:
#REFERENCE:Shalini
#REFERENCE MASS /mg:0.002
#TYPE OF CRUCIBLE:DSC/TG pan Al2O3
#SAMPLE CRUCIBLE MASS /mg:0.0
#REFERENCE CRUCIBLE MASS /mg:0.0
#CORR. CODE:020
#EXO:+1
#RANGE:1100/10.0(K/min)/  25
#SEGMENT:S2/2

##Temp./oC;Time/min;DSC/(mW/mg);Sensit./(uV/mW)
  72.34600;212.49250; 2.6300e-002;0.95047
  73.24510;212.26973; 2.6937e-002;0.95007
  74.14420;212.04601; 2.7323e-002;0.94968
  75.04330;211.82779; 2.7807e-002;0.94928
  75.94240;211.61299; 2.8370e-002;0.94888
  76.84151;211.40066; 2.8929e-002;0.94848
  77.74061;211.18960; 2.9309e-002;0.94809
  78.63971;210.98530; 2.9672e-002;0.94769
  79.53881;210.78121; 3.0207e-002;0.94729
  80.43791;210.58162; 3.0677e-002;0.94689
  81.33701;210.38473; 3.1116e-002;0.94649
  82.23611;210.19102; 3.1631e-002;0.94609
  83.13521;209.99867; 3.2243e-002;0.94568
  84.03431;209.81114; 3.2655e-002;0.94528
  84.93341;209.62403; 3.3184e-002;0.94488
  85.83252;209.44037; 3.3718e-002;0.94448
  86.73162;209.25932; 3.4196e-002;0.94407
  87.63072;209.08172; 3.4635e-002;0.94367
  88.52982;208.90460; 3.5172e-002;0.94326
  89.42892;208.73188; 3.5521e-002;0.94286
  90.32802;208.55962; 3.6016e-002;0.94245
  91.22712;208.39276; 3.6394e-002;0.94204
  92.12622;208.22498; 3.6896e-002;0.94164
  93.02532;208.05984; 3.7363e-002;0.94123
  93.92442;207.89725; 3.7672e-002;0.94082
  94.82353;207.73748; 3.8136e-002;0.94041
  95.72263;207.57553; 3.8616e-002;0.94000
  96.62173;207.41942; 3.8902e-002;0.93959
  97.52083;207.26341; 3.9387e-002;0.93918
  98.41993;207.10861; 3.9766e-002;0.93877
  99.31903;206.95654; 4.0128e-002;0.93836
 100.21813;206.80664; 4.0645e-002;0.93794
 101.11723;206.65668; 4.0955e-002;0.93753
 102.01633;206.50957; 4.1469e-002;0.93712
 102.91544;206.36254; 4.1837e-002;0.93670
 103.81454;206.21850; 4.2231e-002;0.93629
 104.71364;206.07513; 4.2714e-002;0.93588
 105.61274;205.93371; 4.3100e-002;0.93546
 106.51184;205.79256; 4.3588e-002;0.93504
 107.41094;205.65441; 4.4023e-002;0.93463
 108.31004;205.51704; 4.4501e-002;0.93421
 109.20914;205.37962; 4.4932e-002;0.93379
 110.10824;205.24411; 4.5325e-002;0.93337
 111.00734;205.10891; 4.5691e-002;0.93296
 111.90645;204.97687; 4.6154e-002;0.93254
 112.80555;204.84440; 4.6539e-002;0.93212
 113.70465;204.71376; 4.7029e-002;0.93170
 114.60375;204.58324; 4.7471e-002;0.93128
 115.50285;204.45503; 4.8005e-002;0.93085
 116.40195;204.32699; 4.8391e-002;0.93043
 117.30105;204.20099; 4.8866e-002;0.93001
 118.20015;204.07562; 4.9347e-002;0.92959
 119.09925;203.95171; 4.9755e-002;0.92916
 119.99835;203.82850; 5.0253e-002;0.92874
 120.89746;203.70667; 5.0504e-002;0.92832
 121.79656;203.58549; 5.0904e-002;0.92789
 122.69566;203.46536; 5.1267e-002;0.92747
 123.59476;203.34660; 5.1667e-002;0.92704
 124.49386;203.22871; 5.1903e-002;0.92661
 125.39296;203.11218; 5.2160e-002;0.92619
 126.29206;202.99631; 5.2605e-002;0.92576
 127.19116;202.88152; 5.3037e-002;0.92533
 128.09026;202.76752; 5.3399e-002;0.92490
 128.98936;202.65252; 5.4136e-002;0.92447
 129.88847;202.54117; 5.4599e-002;0.92404
 130.78757;202.42923; 5.5113e-002;0.92361
 131.68667;202.31873; 5.5608e-002;0.92318
 132.58577;202.20889; 5.5910e-002;0.92275
 133.48487;202.10015; 5.6254e-002;0.92232
 134.38397;201.99140; 5.6619e-002;0.92189
 135.28307;201.88351; 5.6952e-002;0.92146
 136.18217;201.77676; 5.7257e-002;0.92103
 137.08127;201.67040; 5.7611e-002;0.92059
 137.98037;201.56483; 5.7829e-002;0.92016
 138.87948;201.46059; 5.7993e-002;0.91972
 139.77858;201.35646; 5.8060e-002;0.91929
 140.67768;201.25269; 5.8382e-002;0.91885
 141.57678;201.15046; 5.8563e-002;0.91842
 142.47588;201.04872; 5.8828e-002;0.91798
 143.37498;200.94695; 5.8974e-002;0.91755
 144.27408;200.84645; 5.9455e-002;0.91711
 145.17318;200.74627; 5.9631e-002;0.91667
 146.07228;200.64708; 5.9997e-002;0.91623
 146.97138;200.54786; 6.0378e-002;0.91580
 147.87049;200.45043; 6.0592e-002;0.91536
 148.76959;200.35202; 6.0779e-002;0.91492
 149.66869;200.25396; 6.1083e-002;0.91448
 150.56779;200.15739; 6.1132e-002;0.91404
 151.46689;200.06067; 6.1478e-002;0.91360
 152.36599;199.96535; 6.1618e-002;0.91316
 153.26509;199.86944; 6.2094e-002;0.91271
 154.16419;199.77457; 6.2190e-002;0.91227
 155.06329;199.67973; 6.2286e-002;0.91183
 155.96239;199.58519; 6.2574e-002;0.91139
 156.86150;199.49128; 6.2729e-002;0.91094
 157.76060;199.39848; 6.2817e-002;0.91050
 158.65970;199.30527; 6.3024e-002;0.91005
 159.55880;199.21266; 6.3047e-002;0.90961
 160.45790;199.11925; 6.3237e-002;0.90916
 161.35700;199.02679; 6.3469e-002;0.90872
 162.25610;198.93465; 6.3300e-002;0.90827
 163.15520;198.84343; 6.3478e-002;0.90783
 164.05430;198.75124; 6.3647e-002;0.90738
 164.95340;198.65910; 6.3436e-002;0.90693
 165.85251;198.56751; 6.3442e-002;0.90648
 166.75161;198.47639; 6.3278e-002;0.90604
 167.65071;198.38550; 6.3254e-002;0.90559
 168.54981;198.29477; 6.3077e-002;0.90514
 169.44891;198.20403; 6.3081e-002;0.90469
 170.34801;198.11363; 6.3142e-002;0.90424
 171.24711;198.02261; 6.3117e-002;0.90379
 172.14621;197.93123; 6.3170e-002;0.90334
 173.04531;197.84107; 6.3149e-002;0.90289
 173.94442;197.74988; 6.3274e-002;0.90244
 174.84352;197.65939; 6.3299e-002;0.90198
 175.74262;197.56872; 6.3329e-002;0.90153
 176.64172;197.47790; 6.3182e-002;0.90108
 177.54082;197.38790; 6.3129e-002;0.90063
 178.43992;197.29686; 6.3185e-002;0.90017
 179.33902;197.20644; 6.3136e-002;0.89972
 180.23812;197.11596; 6.3274e-002;0.89926
 181.13722;197.02559; 6.3304e-002;0.89881
 182.03632;196.93560; 6.2984e-002;0.89835
 182.93543;196.84528; 6.2835e-002;0.89790
 183.83453;196.75446; 6.2979e-002;0.89744
 184.73363;196.66364; 6.3224e-002;0.89698
 185.63273;196.57335; 6.3234e-002;0.89653
 186.53183;196.48313; 6.3132e-002;0.89607
 187.43093;196.39230; 6.3282e-002;0.89561
 188.33003;196.30141; 6.3306e-002;0.89516
 189.22913;196.21134; 6.3272e-002;0.89470
 190.12823;196.12076; 6.3167e-002;0.89424
 191.02733;196.02983; 6.3150e-002;0.89378
 191.92644;195.93972; 6.3190e-002;0.89332
 192.82554;195.84896; 6.3123e-002;0.89286
 193.72464;195.75890; 6.3080e-002;0.89240
 194.62374;195.66880; 6.3144e-002;0.89194
 195.52284;195.57820; 6.3119e-002;0.89148
 196.42194;195.48756; 6.3169e-002;0.89102
 197.32104;195.39653; 6.3204e-002;0.89055
 198.22014;195.30622; 6.3138e-002;0.89009
 199.11924;195.21511; 6.3116e-002;0.88963
 200.01834;195.12498; 6.3107e-002;0.88917
 200.91745;195.03441; 6.2986e-002;0.88870
 201.81655;194.94355; 6.2978e-002;0.88824
 202.71565;194.85351; 6.2760e-002;0.88777
 203.61475;194.76378; 6.2592e-002;0.88731
 204.51385;194.67237; 6.2568e-002;0.88685
 205.41295;194.58225; 6.2467e-002;0.88638
 206.31205;194.49196; 6.2397e-002;0.88591
 207.21115;194.40138; 6.2348e-002;0.88545
 208.11025;194.31095; 6.2371e-002;0.88498
 209.00935;194.22063; 6.2266e-002;0.88452
 209.90846;194.13003; 6.2160e-002;0.88405
 210.80756;194.04000; 6.2306e-002;0.88358
 211.70666;193.94928; 6.2446e-002;0.88311
 212.60576;193.85896; 6.2548e-002;0.88265
 213.50486;193.76845; 6.2376e-002;0.88218
 214.40396;193.67809; 6.2380e-002;0.88171
 215.30306;193.58785; 6.2179e-002;0.88124
 216.20216;193.49693; 6.2192e-002;0.88077
 217.10126;193.40662; 6.1963e-002;0.88030
 218.00036;193.31671; 6.1679e-002;0.87983
 218.89947;193.22668; 6.1622e-002;0.87936
 219.79857;193.13589; 6.1712e-002;0.87889
 220.69767;193.04568; 6.1564e-002;0.87842
 221.59677;192.95563; 6.1458e-002;0.87795
 222.49587;192.86475; 6.0937e-002;0.87747
 223.39497;192.77488; 6.0847e-002;0.87700
 224.29407;192.68475; 6.0768e-002;0.87653
 225.19317;192.59463; 6.0663e-002;0.87606
 226.09227;192.50421; 6.0439e-002;0.87558
 226.99137;192.41359; 6.0306e-002;0.87511
 227.89048;192.32355; 6.0121e-002;0.87464
 228.78958;192.23323; 5.9981e-002;0.87416
 229.68868;192.14297; 5.9847e-002;0.87369
 230.58778;192.05295; 5.9745e-002;0.87321
 231.48688;191.96291; 5.9703e-002;0.87274
 232.38598;191.87257; 5.9779e-002;0.87226
 233.28508;191.78237; 5.9629e-002;0.87179
 234.18418;191.69197; 5.9522e-002;0.87131
 235.08328;191.60196; 5.9448e-002;0.87083
 235.98238;191.51188; 5.9413e-002;0.87036
 236.88149;191.42190; 5.9380e-002;0.86988
 237.78059;191.33111; 5.9284e-002;0.86940
 238.67969;191.24114; 5.9254e-002;0.86892
 239.57879;191.15108; 5.9259e-002;0.86845
 240.47789;191.06084; 5.9310e-002;0.86797
 241.37699;190.97126; 5.9135e-002;0.86749
 242.27609;190.88130; 5.9002e-002;0.86701
 243.17519;190.79149; 5.8846e-002;0.86653
 244.07429;190.70175; 5.8717e-002;0.86605
 244.97340;190.61198; 5.7907e-002;0.86557
 245.87250;190.52111; 5.7766e-002;0.86509
 246.77160;190.43098; 5.7603e-002;0.86461
 247.67070;190.34118; 5.7691e-002;0.86413
 248.56980;190.25038; 5.7681e-002;0.86365
 249.46890;190.16028; 5.7565e-002;0.86317
 250.36800;190.07055; 5.7248e-002;0.86269
 251.26710;189.98041; 5.7189e-002;0.86221
 252.16620;189.89087; 5.7055e-002;0.86172
 253.06530;189.80015; 5.6876e-002;0.86124
 253.96441;189.71022; 5.6678e-002;0.86076
 254.86351;189.61926; 5.6537e-002;0.86028
 255.76261;189.52889; 5.6598e-002;0.85979
 256.66171;189.43888; 5.6475e-002;0.85931
 257.56081;189.34869; 5.6253e-002;0.85883
 258.45991;189.25883; 5.6063e-002;0.85834
 259.35901;189.16897; 5.5974e-002;0.85786
 260.25811;189.07851; 5.5851e-002;0.85737
 261.15721;188.98740; 5.5956e-002;0.85689
 262.05631;188.89746; 5.5843e-002;0.85640
 262.95542;188.80762; 5.5614e-002;0.85592
 263.85452;188.71764; 5.5419e-002;0.85543
 264.75362;188.62662; 5.5462e-002;0.85495
 265.65272;188.53683; 5.5784e-002;0.85446
 266.55182;188.44673; 5.6035e-002;0.85397
 267.45092;188.35649; 5.5924e-002;0.85349
 268.35002;188.26595; 5.5923e-002;0.85300
 269.24912;188.17626; 5.5831e-002;0.85251
 270.14822;188.08540; 5.5975e-002;0.85202
 271.04732;187.99531; 5.5707e-002;0.85154
 271.94643;187.90495; 5.5757e-002;0.85105
 272.84553;187.81474; 5.5338e-002;0.85056
 273.74463;187.72491; 5.5196e-002;0.85007
 274.64373;187.63462; 5.4982e-002;0.84958
 275.54283;187.54415; 5.4823e-002;0.84909
 276.44193;187.45392; 5.4659e-002;0.84860
 277.34103;187.36321; 5.4606e-002;0.84811
 278.24013;187.27310; 5.4552e-002;0.84762
 279.13923;187.18307; 5.4272e-002;0.84713
 280.03833;187.09298; 5.4136e-002;0.84664
 280.93744;187.00272; 5.3977e-002;0.84615
 281.83654;186.91224; 5.3962e-002;0.84566
 282.73564;186.82204; 5.3852e-002;0.84517
 283.63474;186.73201; 5.3589e-002;0.84468
 284.53384;186.64198; 5.3587e-002;0.84419
 285.43294;186.55169; 5.3492e-002;0.84370
 286.33204;186.46119; 5.3312e-002;0.84320
 287.23114;186.37159; 5.3296e-002;0.84271
 288.13024;186.28081; 5.3164e-002;0.84222
 289.02934;186.19093; 5.2933e-002;0.84173
 289.92845;186.10114; 5.2823e-002;0.84123
 290.82755;186.01073; 5.2832e-002;0.84074
 291.72665;185.92039; 5.2613e-002;0.84025
 292.62575;185.83005; 5.2492e-002;0.83975
 293.52485;185.73940; 5.2381e-002;0.83926
 294.42395;185.64972; 5.2303e-002;0.83877
 295.32305;185.56001; 5.2160e-002;0.83827
 296.22215;185.46899; 5.2077e-002;0.83778
 297.12125;185.37921; 5.2045e-002;0.83728
 298.02035;185.28914; 5.1920e-002;0.83679
 298.91946;185.19860; 5.1505e-002;0.83629
 299.81856;185.10840; 5.1286e-002;0.83580
 300.71766;185.01980; 5.1113e-002;0.83530
 301.61676;184.92827; 5.1050e-002;0.83481
 302.51586;184.83855; 5.1064e-002;0.83431
 303.41496;184.74803; 5.1000e-002;0.83381
 304.31406;184.65796; 5.0847e-002;0.83332
 305.21316;184.56773; 5.0612e-002;0.83282
 306.11226;184.47797; 5.0491e-002;0.83232
 307.01136;184.38808; 5.0474e-002;0.83183
 307.91047;184.29785; 5.0347e-002;0.83133
 308.80957;184.20734; 5.0307e-002;0.83083
 309.70867;184.11759; 5.0163e-002;0.83033
 310.60777;184.02663; 5.0129e-002;0.82984
 311.50687;183.93632; 4.9809e-002;0.82934
 312.40597;183.84705; 4.9617e-002;0.82884
 313.30507;183.75676; 4.9669e-002;0.82834
 314.20417;183.66631; 4.9437e-002;0.82784
 315.10327;183.57599; 4.9247e-002;0.82734
 316.00237;183.48589; 4.9437e-002;0.82685
 316.90148;183.39551; 4.9021e-002;0.82635
 317.80058;183.30633; 4.9002e-002;0.82585
 318.69968;183.21626; 4.8857e-002;0.82535
 319.59878;183.12607; 4.8547e-002;0.82485
 320.49788;183.03624; 4.8530e-002;0.82435
 321.39698;182.94525; 4.8377e-002;0.82385
 322.29608;182.85557; 4.8222e-002;0.82335
 323.19518;182.76530; 4.8101e-002;0.82285
 324.09428;182.67514; 4.7931e-002;0.82235
 324.99339;182.58568; 4.7557e-002;0.82185
 325.89249;182.49581; 4.7393e-002;0.82134
 326.79159;182.40586; 4.7261e-002;0.82084
 327.69069;182.31523; 4.7176e-002;0.82034
 328.58979;182.22505; 4.6900e-002;0.81984
 329.48889;182.13511; 4.6833e-002;0.81934
 330.38799;182.04522; 4.6573e-002;0.81884
 331.28709;181.95473; 4.6556e-002;0.81833
 332.18619;181.86530; 4.6256e-002;0.81783
 333.08529;181.77487; 4.6422e-002;0.81733
 333.98440;181.68459; 4.6101e-002;0.81683
 334.88350;181.59462; 4.5922e-002;0.81633
 335.78260;181.50419; 4.5830e-002;0.81582
 336.68170;181.41422; 4.5639e-002;0.81532
 337.58080;181.32439; 4.5395e-002;0.81482
 338.47990;181.23460; 4.5125e-002;0.81431
 339.37900;181.14454; 4.5055e-002;0.81381
 340.27810;181.05503; 4.4854e-002;0.81331
 341.17720;180.96524; 4.4639e-002;0.81280
 342.07630;180.87537; 4.4610e-002;0.81230
 342.97541;180.78469; 4.4395e-002;0.81179
 343.87451;180.69529; 4.4178e-002;0.81129
 344.77361;180.60516; 4.4125e-002;0.81079
 345.67271;180.51512; 4.3934e-002;0.81028
 346.57181;180.42538; 4.3723e-002;0.80978
 347.47091;180.33510; 4.3386e-002;0.80927
 348.37001;180.24520; 4.3174e-002;0.80877
 349.26911;180.15484; 4.2918e-002;0.80826
 350.16821;180.06455; 4.2718e-002;0.80776
 351.06731;179.97513; 4.2389e-002;0.80725
 351.96642;179.88537; 4.2088e-002;0.80674
 352.86552;179.79471; 4.1820e-002;0.80624
 353.76462;179.70458; 4.1621e-002;0.80573
 354.66372;179.61451; 4.1374e-002;0.80523
 355.56282;179.52490; 4.1166e-002;0.80472
 356.46192;179.43493; 4.0832e-002;0.80421
 357.36102;179.34394; 4.0621e-002;0.80371
 358.26012;179.25391; 4.0266e-002;0.80320
 359.15922;179.16413; 4.0173e-002;0.80270
 360.05832;179.07412; 3.9891e-002;0.80219
 360.95743;178.98417; 3.9890e-002;0.80168
 361.85653;178.89357; 3.9551e-002;0.80117
 362.75563;178.80353; 3.9469e-002;0.80067
 363.65473;178.71305; 3.9372e-002;0.80016
 364.55383;178.62343; 3.8995e-002;0.79965
 365.45293;178.53241; 3.9013e-002;0.79915
 366.35203;178.44253; 3.8807e-002;0.79864
 367.25113;178.35225; 3.8451e-002;0.79813
 368.15023;178.26209; 3.8146e-002;0.79762
 369.04933;178.17172; 3.8018e-002;0.79711
 369.94844;178.08170; 3.7871e-002;0.79661
 370.84754;177.99210; 3.7573e-002;0.79610
 371.74664;177.90168; 3.7556e-002;0.79559
 372.64574;177.81187; 3.7215e-002;0.79508
 373.54484;177.72199; 3.7183e-002;0.79457
 374.44394;177.63175; 3.7034e-002;0.79406
 375.34304;177.54161; 3.6827e-002;0.79356
 376.24214;177.45164; 3.6893e-002;0.79305
 377.14124;177.36110; 3.6627e-002;0.79254
 378.04034;177.27096; 3.6478e-002;0.79203
 378.93945;177.18151; 3.6454e-002;0.79152
 379.83855;177.09069; 3.6160e-002;0.79101
 380.73765;177.00058; 3.5949e-002;0.79050
 381.63675;176.91011; 3.5888e-002;0.78999
 382.53585;176.82029; 3.5690e-002;0.78948
 383.43495;176.72994; 3.5374e-002;0.78897
 384.33405;176.64020; 3.5330e-002;0.78846
 385.23315;176.55015; 3.4972e-002;0.78795
 386.13225;176.45972; 3.4727e-002;0.78744
 387.03135;176.36954; 3.4546e-002;0.78693
 387.93046;176.27986; 3.4454e-002;0.78642
 388.82956;176.18930; 3.4288e-002;0.78591
 389.72866;176.09949; 3.3992e-002;0.78540
 390.62776;176.00941; 3.4132e-002;0.78489
 391.52686;175.91916; 3.3952e-002;0.78438
 392.42596;175.82942; 3.3803e-002;0.78387
 393.32506;175.73911; 3.3593e-002;0.78336
 394.22416;175.64894; 3.3581e-002;0.78285
 395.12326;175.55874; 3.3488e-002;0.78234
 396.02237;175.46872; 3.3165e-002;0.78183
 396.92147;175.37836; 3.3239e-002;0.78132
 397.82057;175.28839; 3.3412e-002;0.78080
 398.71967;175.19836; 3.3422e-002;0.78029
 399.61877;175.10855; 3.3297e-002;0.77978
 400.51787;175.01815; 3.3130e-002;0.77927
 401.41697;174.92787; 3.3061e-002;0.77876
 402.31607;174.83798; 3.2859e-002;0.77825
 403.21517;174.74755; 3.2835e-002;0.77774
 404.11427;174.65774; 3.2582e-002;0.77722
 405.01338;174.56763; 3.2313e-002;0.77671
 405.91248;174.47721; 3.2118e-002;0.77620
 406.81158;174.38701; 3.1805e-002;0.77569
 407.71068;174.29745; 3.1523e-002;0.77518
 408.60978;174.20723; 3.1252e-002;0.77467
 409.50888;174.11701; 3.1051e-002;0.77415
 410.40798;174.02668; 3.0777e-002;0.77364
 411.30708;173.93712; 3.0243e-002;0.77313
 412.20618;173.84672; 3.0111e-002;0.77262
 413.10528;173.75664; 2.9965e-002;0.77211
 414.00439;173.66735; 2.9482e-002;0.77159
 414.90349;173.57669; 2.9327e-002;0.77108
 415.80259;173.48654; 2.9088e-002;0.77057
 416.70169;173.39659; 2.8787e-002;0.77006
 417.60079;173.30668; 2.8693e-002;0.76954
 418.49989;173.21746; 2.8476e-002;0.76903
 419.39899;173.12736; 2.8332e-002;0.76852
 420.29809;173.03720; 2.8052e-002;0.76801
 421.19719;172.94704; 2.7951e-002;0.76749
 422.09629;172.85702; 2.7882e-002;0.76698
 422.99540;172.76727; 2.7643e-002;0.76647
 423.89450;172.67717; 2.7503e-002;0.76595
 424.79360;172.58763; 2.7410e-002;0.76544
 425.69270;172.49740; 2.7090e-002;0.76493
 426.59180;172.40743; 2.6978e-002;0.76441
 427.49090;172.31746; 2.6663e-002;0.76390
 428.39000;172.22780; 2.6433e-002;0.76339
 429.28910;172.13781; 2.6172e-002;0.76288
 430.18820;172.04815; 2.5652e-002;0.76236
 431.08730;171.95781; 2.5408e-002;0.76185
 431.98641;171.86775; 2.5489e-002;0.76134
 432.88551;171.77793; 2.5282e-002;0.76082
 433.78461;171.68883; 2.5164e-002;0.76031
 434.68371;171.59870; 2.4673e-002;0.75980
 435.58281;171.50935; 2.4505e-002;0.75928
 436.48191;171.41898; 2.4486e-002;0.75877
 437.38101;171.32896; 2.4138e-002;0.75826
 438.28011;171.23986; 2.3847e-002;0.75774
 439.17921;171.14931; 2.3669e-002;0.75723
 440.07831;171.05872; 2.3405e-002;0.75671
 440.97742;170.96946; 2.3194e-002;0.75620
 441.87652;170.87941; 2.2983e-002;0.75569
 442.77562;170.78968; 2.2756e-002;0.75517
 443.67472;170.69934; 2.2611e-002;0.75466
 444.57382;170.60951; 2.2311e-002;0.75415
 445.47292;170.51933; 2.2293e-002;0.75363
 446.37202;170.42937; 2.1975e-002;0.75312
 447.27112;170.33879; 2.1770e-002;0.75261
 448.17022;170.24917; 2.1708e-002;0.75209
 449.06932;170.15887; 2.1424e-002;0.75158
 449.96843;170.06856; 2.1411e-002;0.75106
 450.86753;169.97847; 2.1250e-002;0.75055
 451.76663;169.88838; 2.1079e-002;0.75004
 452.66573;169.79844; 2.0783e-002;0.74952
 453.56483;169.70817; 2.0622e-002;0.74901
 454.46393;169.61851; 2.0356e-002;0.74849
 455.36303;169.52837; 2.0107e-002;0.74798
 456.26213;169.43755; 2.0006e-002;0.74747
 457.16123;169.34796; 1.9756e-002;0.74695
 458.06033;169.25826; 1.9514e-002;0.74644
 458.95944;169.16788; 1.9429e-002;0.74593
 459.85854;169.07782; 1.9112e-002;0.74541
 460.75764;168.98809; 1.8843e-002;0.74490
 461.65674;168.89848; 1.8683e-002;0.74438
 462.55584;168.80823; 1.8242e-002;0.74387
 463.45494;168.71822; 1.8223e-002;0.74336
 464.35404;168.62829; 1.8048e-002;0.74284
 465.25314;168.53858; 1.7868e-002;0.74233
 466.15224;168.44842; 1.7585e-002;0.74181
 467.05135;168.35883; 1.7264e-002;0.74130
 467.95045;168.26875; 1.6933e-002;0.74079
 468.84955;168.17874; 1.6873e-002;0.74027
 469.74865;168.08860; 1.6722e-002;0.73976
 470.64775;167.99894; 1.6398e-002;0.73924
 471.54685;167.90877; 1.5893e-002;0.73873
 472.44595;167.81877; 1.5819e-002;0.73822
 473.34505;167.72895; 1.5699e-002;0.73770
 474.24415;167.63930; 1.5444e-002;0.73719
 475.14325;167.54897; 1.5439e-002;0.73667
 476.04236;167.45905; 1.5162e-002;0.73616
 476.94146;167.36910; 1.4920e-002;0.73565
 477.84056;167.27918; 1.4519e-002;0.73513
 478.73966;167.18901; 1.4564e-002;0.73462
 479.63876;167.09802; 1.4117e-002;0.73411
 480.53786;167.00811; 1.3770e-002;0.73359
 481.43696;166.91796; 1.3907e-002;0.73308
 482.33606;166.82777; 1.3722e-002;0.73256
 483.23516;166.73713; 1.3489e-002;0.73205
 484.13426;166.64748; 1.3329e-002;0.73154
 485.03337;166.55758; 1.3020e-002;0.73102
 485.93247;166.46707; 1.2906e-002;0.73051
 486.83157;166.37665; 1.3024e-002;0.73000
 487.73067;166.28707; 1.2639e-002;0.72948
 488.62977;166.19638; 1.2627e-002;0.72897
 489.52887;166.10632; 1.2267e-002;0.72845
 490.42797;166.01612; 1.2129e-002;0.72794
 491.32707;165.92600; 1.1957e-002;0.72743
 492.22617;165.83670; 1.1715e-002;0.72691
 493.12527;165.74560; 1.1412e-002;0.72640
 494.02438;165.65539; 1.1251e-002;0.72589
 494.92348;165.56569; 1.0972e-002;0.72537
 495.82258;165.47536; 1.0886e-002;0.72486
 496.72168;165.38562; 1.0709e-002;0.72435
 497.62078;165.29552; 1.0502e-002;0.72383
 498.51988;165.20551; 1.0366e-002;0.72332
 499.41898;165.11521; 9.9177e-003;0.72281
 500.31808;165.02491; 9.7573e-003;0.72229
 501.21718;164.93479; 9.5709e-003;0.72178
 502.11628;164.84517; 9.4656e-003;0.72127
 503.01539;164.75516; 9.3423e-003;0.72075
 503.91449;164.66484; 9.1185e-003;0.72024
 504.81359;164.57549; 8.9373e-003;0.71973
 505.71269;164.48538; 8.7558e-003;0.71921
 506.61179;164.39520; 8.5933e-003;0.71870
 507.51089;164.30513; 8.1905e-003;0.71819
 508.40999;164.21464; 8.0671e-003;0.71768
 509.30909;164.12535; 8.0546e-003;0.71716
 510.20819;164.03517; 7.6132e-003;0.71665
 511.10729;163.94521; 7.6677e-003;0.71614
 512.00640;163.85528; 7.4364e-003;0.71562
 512.90550;163.76505; 7.3465e-003;0.71511
 513.80460;163.67506; 7.1398e-003;0.71460
 514.70370;163.58546; 7.0133e-003;0.71409
 515.60280;163.49554; 6.6099e-003;0.71357
 516.50190;163.40506; 6.6616e-003;0.71306
 517.40100;163.31524; 6.3358e-003;0.71255
 518.30010;163.22585; 6.0145e-003;0.71204
 519.19920;163.13600; 5.9986e-003;0.71152
 520.09830;163.04601; 5.6894e-003;0.71101
 520.99741;162.95644; 5.7337e-003;0.71050
 521.89651;162.86645; 5.5125e-003;0.70999
 522.79561;162.77650; 5.2016e-003;0.70948
 523.69471;162.68581; 5.1299e-003;0.70896
 524.59381;162.59643; 5.0279e-003;0.70845
 525.49291;162.50630; 4.6920e-003;0.70794
 526.39201;162.41686; 4.6909e-003;0.70743
 527.29111;162.32659; 4.3774e-003;0.70692
 528.19021;162.23704; 4.2939e-003;0.70640
 529.08931;162.14767; 3.9347e-003;0.70589
 529.98842;162.05712; 3.6382e-003;0.70538
 530.88752;161.96751; 3.6469e-003;0.70487
 531.78662;161.87791; 3.4041e-003;0.70436
 532.68572;161.78818; 3.1294e-003;0.70385
 533.58482;161.69783; 3.1715e-003;0.70334
 534.48392;161.60822; 2.6866e-003;0.70282
 535.38302;161.51834; 2.7063e-003;0.70231
 536.28212;161.42823; 2.4904e-003;0.70180
 537.18122;161.33825; 2.4587e-003;0.70129
 538.08033;161.24763; 1.9857e-003;0.70078
 538.97943;161.15747; 1.7323e-003;0.70027
 539.87853;161.06790; 1.6271e-003;0.69976
 540.77763;160.97771; 1.6002e-003;0.69925
 541.67673;160.88753; 1.1703e-003;0.69874
 542.57583;160.79769; 1.1029e-003;0.69823
 543.47493;160.70754; 8.5750e-004;0.69772
 544.37403;160.61740; 6.7432e-004;0.69720
 545.27313;160.52750; 5.4896e-004;0.69669
 546.17223;160.43796; 4.7501e-004;0.69618
 547.07134;160.34817; 3.1782e-004;0.69567
 547.97044;160.25792;-1.5207e-005;0.69516
 548.86954;160.16775;-2.7188e-004;0.69465
 549.76864;160.07725;-4.5594e-004;0.69414
 550.66774;159.98685;-6.1813e-004;0.69363
 551.56684;159.89643;-7.6967e-004;0.69312
 552.46594;159.80669;-9.7491e-004;0.69261
 553.36504;159.71668;-1.1891e-003;0.69210
 554.26414;159.62664;-1.4382e-003;0.69159
 555.16324;159.53664;-1.7073e-003;0.69108
 556.06235;159.44693;-1.9652e-003;0.69057
 556.96145;159.35733;-2.0814e-003;0.69007
 557.86055;159.26713;-2.2556e-003;0.68956
 558.75965;159.17680;-2.3782e-003;0.68905
 559.65875;159.08680;-2.6539e-003;0.68854
 560.55785;158.99676;-2.7269e-003;0.68803
 561.45695;158.90606;-2.8183e-003;0.68752
 562.35605;158.81658;-2.9929e-003;0.68701
 563.25515;158.72640;-3.1286e-003;0.68650
 564.15425;158.63617;-3.4955e-003;0.68599
 565.05336;158.54604;-3.6321e-003;0.68548
 565.95246;158.45576;-3.7895e-003;0.68498
 566.85156;158.36571;-3.9660e-003;0.68447
 567.75066;158.27511;-4.3004e-003;0.68396
 568.64976;158.18494;-4.5247e-003;0.68345
 569.54886;158.09433;-4.5041e-003;0.68294
 570.44796;158.00409;-4.6189e-003;0.68244
 571.34706;157.91418;-4.8111e-003;0.68193
 572.24616;157.82403;-5.0277e-003;0.68142
 573.14526;157.73383;-5.1280e-003;0.68091
 574.04437;157.64350;-5.2376e-003;0.68040
 574.94347;157.55374;-5.5069e-003;0.67990
 575.84257;157.46386;-5.4468e-003;0.67939
 576.74167;157.37394;-5.9101e-003;0.67888
 577.64077;157.28415;-5.9810e-003;0.67837
 578.53987;157.19426;-6.3257e-003;0.67787
 579.43897;157.10365;-6.3823e-003;0.67736
 580.33807;157.01384;-6.5948e-003;0.67685
 581.23717;156.92371;-6.7968e-003;0.67635
 582.13627;156.83371;-6.7397e-003;0.67584
 583.03538;156.74386;-6.7771e-003;0.67533
 583.93448;156.65456;-6.8970e-003;0.67483
 584.83358;156.56432;-7.0804e-003;0.67432
 585.73268;156.47381;-7.1401e-003;0.67381
 586.63178;156.38418;-7.3157e-003;0.67331
 587.53088;156.29356;-7.1652e-003;0.67280
 588.42998;156.20379;-7.3039e-003;0.67230
 589.32908;156.11434;-7.2687e-003;0.67179
 590.22818;156.02341;-7.2782e-003;0.67128
 591.12728;155.93362;-7.2198e-003;0.67078
 592.02639;155.84363;-7.2802e-003;0.67027
 592.92549;155.75343;-7.9315e-003;0.66977
 593.82459;155.66344;-7.9243e-003;0.66926
 594.72369;155.57316;-8.1783e-003;0.66876
 595.62279;155.48292;-8.3983e-003;0.66825
 596.52189;155.39332;-8.2064e-003;0.66775
 597.42099;155.30308;-8.7629e-003;0.66724
 598.32009;155.21339;-8.7737e-003;0.66674
 599.21919;155.12395;-8.9517e-003;0.66623
 600.11829;155.03439;-8.9737e-003;0.66573
 601.01740;154.94375;-9.1751e-003;0.66522
 601.91650;154.85307;-9.2898e-003;0.66472
 602.81560;154.76353;-9.5793e-003;0.66421
 603.71470;154.67362;-9.5462e-003;0.66371
 604.61380;154.58387;-9.6770e-003;0.66321
 605.51290;154.49385;-1.0025e-002;0.66270
 606.41200;154.40398;-1.0090e-002;0.66220
 607.31110;154.31411;-1.0216e-002;0.66170
 608.21020;154.22405;-1.0665e-002;0.66119
 609.10930;154.13386;-1.0652e-002;0.66069
 610.00841;154.04431;-1.0811e-002;0.66019
 610.90751;153.95405;-1.0888e-002;0.65968
 611.80661;153.86439;-1.1174e-002;0.65918
 612.70571;153.77444;-1.1453e-002;0.65868
 613.60481;153.68441;-1.1560e-002;0.65817
 614.50391;153.59490;-1.1885e-002;0.65767
 615.40301;153.50422;-1.1983e-002;0.65717
 616.30211;153.41485;-1.2151e-002;0.65667
 617.20121;153.32485;-1.2160e-002;0.65616
 618.10032;153.23495;-1.2310e-002;0.65566
 618.99942;153.14420;-1.2365e-002;0.65516
 619.89852;153.05418;-1.2750e-002;0.65466
 620.79762;152.96409;-1.2689e-002;0.65416
 621.69672;152.87377;-1.2969e-002;0.65366
 622.59582;152.78423;-1.3074e-002;0.65315
 623.49492;152.69417;-1.3346e-002;0.65265
 624.39402;152.60403;-1.3472e-002;0.65215
 625.29312;152.51462;-1.3681e-002;0.65165
 626.19222;152.42390;-1.3705e-002;0.65115
 627.09133;152.33433;-1.3852e-002;0.65065
 627.99043;152.24454;-1.4139e-002;0.65015
 628.88953;152.15462;-1.4027e-002;0.64965
 629.78863;152.06471;-1.4286e-002;0.64915
 630.68773;151.97584;-1.4383e-002;0.64865
 631.58683;151.88569;-1.4376e-002;0.64815
 632.48593;151.79601;-1.4346e-002;0.64765
 633.38503;151.70630;-1.4357e-002;0.64715
 634.28413;151.61661;-1.4662e-002;0.64665
 635.18323;151.52721;-1.4795e-002;0.64615
 636.08234;151.43671;-1.4782e-002;0.64565
 636.98144;151.34680;-1.4877e-002;0.64515
 637.88054;151.25763;-1.4959e-002;0.64465
 638.77964;151.16748;-1.4926e-002;0.64415
 639.67874;151.07752;-1.5020e-002;0.64365
 640.57784;150.98741;-1.5023e-002;0.64315
 641.47694;150.89722;-1.5127e-002;0.64266
 642.37604;150.80717;-1.5056e-002;0.64216
 643.27514;150.71652;-1.5088e-002;0.64166
 644.17424;150.62628;-1.5168e-002;0.64116
 645.07335;150.53606;-1.5243e-002;0.64066
 645.97245;150.44617;-1.5463e-002;0.64016
 646.87155;150.35606;-1.5433e-002;0.63967
 647.77065;150.26567;-1.5525e-002;0.63917
 648.66975;150.17552;-1.5721e-002;0.63867
 649.56885;150.08542;-1.5694e-002;0.63817
 650.46795;149.99577;-1.5766e-002;0.63768
 651.36705;149.90538;-1.5800e-002;0.63718
 652.26615;149.81506;-1.6037e-002;0.63668
 653.16525;149.72544;-1.5905e-002;0.63619
 654.06436;149.63538;-1.5877e-002;0.63569
 654.96346;149.54497;-1.6285e-002;0.63519
 655.86256;149.45449;-1.6262e-002;0.63470
 656.76166;149.36456;-1.6303e-002;0.63420
 657.66076;149.27420;-1.6207e-002;0.63371
 658.55986;149.18418;-1.6205e-002;0.63321
 659.45896;149.09429;-1.6055e-002;0.63271
 660.35806;149.00430;-1.6228e-002;0.63222
 661.25716;148.91369;-1.6170e-002;0.63172
 662.15626;148.82383;-1.6150e-002;0.63123
 663.05537;148.73384;-1.6472e-002;0.63073
 663.95447;148.64323;-1.6471e-002;0.63024
 664.85357;148.55355;-1.6209e-002;0.62974
 665.75267;148.46307;-1.6347e-002;0.62925
 666.65177;148.37263;-1.6262e-002;0.62876
 667.55087;148.28292;-1.6400e-002;0.62826
 668.44997;148.19311;-1.6474e-002;0.62777
 669.34907;148.10341;-1.6327e-002;0.62727
 670.24817;148.01337;-1.6500e-002;0.62678
 671.14727;147.92337;-1.6495e-002;0.62629
 672.04638;147.83334;-1.6486e-002;0.62579
 672.94548;147.74341;-1.6711e-002;0.62530
 673.84458;147.65268;-1.6703e-002;0.62481
 674.74368;147.56317;-1.6763e-002;0.62431
 675.64278;147.47317;-1.6655e-002;0.62382
 676.54188;147.38302;-1.6657e-002;0.62333
 677.44098;147.29306;-1.6744e-002;0.62284
 678.34008;147.20273;-1.6793e-002;0.62234
 679.23918;147.11262;-1.6677e-002;0.62185
 680.13828;147.02247;-1.6860e-002;0.62136
 681.03739;146.93344;-1.6854e-002;0.62087
 681.93649;146.84344;-1.6730e-002;0.62038
 682.83559;146.75326;-1.6737e-002;0.61988
 683.73469;146.66328;-1.6787e-002;0.61939
 684.63379;146.57313;-1.6699e-002;0.61890
 685.53289;146.48309;-1.6809e-002;0.61841
 686.43199;146.39321;-1.6837e-002;0.61792
 687.33109;146.30367;-1.6969e-002;0.61743
 688.23019;146.21377;-1.7237e-002;0.61694
 689.12930;146.12407;-1.7026e-002;0.61645
 690.02840;146.03455;-1.6819e-002;0.61596
 690.92750;145.94424;-1.6965e-002;0.61547
 691.82660;145.85387;-1.7049e-002;0.61498
 692.72570;145.76437;-1.6989e-002;0.61449
 693.62480;145.67481;-1.7197e-002;0.61400
 694.52390;145.58533;-1.6969e-002;0.61351
 695.42300;145.49500;-1.7332e-002;0.61302
 696.32210;145.40531;-1.7255e-002;0.61253
 697.22120;145.31447;-1.7083e-002;0.61204
 698.12031;145.22455;-1.7281e-002;0.61155
 699.01941;145.13482;-1.7258e-002;0.61106
 699.91851;145.04446;-1.7395e-002;0.61058
 700.81761;144.95454;-1.7454e-002;0.61009
 701.71671;144.86487;-1.7403e-002;0.60960
 702.61581;144.77452;-1.7503e-002;0.60911
 703.51491;144.68486;-1.7293e-002;0.60862
 704.41401;144.59450;-1.7370e-002;0.60814
 705.31311;144.50534;-1.7482e-002;0.60765
 706.21221;144.41563;-1.7234e-002;0.60716
 707.11132;144.32537;-1.7530e-002;0.60668
 708.01042;144.23557;-1.7570e-002;0.60619
 708.90952;144.14540;-1.7510e-002;0.60570
 709.80862;144.05591;-1.7550e-002;0.60522
 710.70772;143.96554;-1.7648e-002;0.60473
 711.60682;143.87587;-1.7861e-002;0.60424
 712.50592;143.78600;-1.7878e-002;0.60376
 713.40502;143.69645;-1.7774e-002;0.60327
 714.30412;143.60670;-1.7676e-002;0.60279
 715.20322;143.51672;-1.8058e-002;0.60230
 716.10233;143.42621;-1.8135e-002;0.60182
 717.00143;143.33684;-1.7825e-002;0.60133
 717.90053;143.24706;-1.7770e-002;0.60085
 718.79963;143.15688;-1.7687e-002;0.60036
 719.69873;143.06725;-1.7617e-002;0.59988
 720.59783;142.97723;-1.7293e-002;0.59939
 721.49693;142.88762;-1.7424e-002;0.59891
 722.39603;142.79757;-1.7424e-002;0.59842
 723.29513;142.70755;-1.7395e-002;0.59794
 724.19423;142.61773;-1.7231e-002;0.59746
 725.09334;142.52773;-1.7297e-002;0.59697
 725.99244;142.43809;-1.7128e-002;0.59649
 726.89154;142.34793;-1.7120e-002;0.59601
 727.79064;142.25803;-1.6951e-002;0.59552
 728.68974;142.16802;-1.6940e-002;0.59504
 729.58884;142.07790;-1.7091e-002;0.59456
 730.48794;141.98806;-1.6583e-002;0.59408
 731.38704;141.89857;-1.6151e-002;0.59359
 732.28614;141.80839;-1.6034e-002;0.59311
 733.18524;141.71860;-1.5996e-002;0.59263
 734.08435;141.62853;-1.5873e-002;0.59215
 734.98345;141.53854;-1.5630e-002;0.59167
 735.88255;141.44864;-1.5625e-002;0.59119
 736.78165;141.35851;-1.5457e-002;0.59071
 737.68075;141.26799;-1.5215e-002;0.59022
 738.57985;141.17789;-1.5106e-002;0.58974
 739.47895;141.08812;-1.5132e-002;0.58926
 740.37805;140.99755;-1.4726e-002;0.58878
 741.27715;140.90765;-1.4726e-002;0.58830
 742.17625;140.81762;-1.4424e-002;0.58782
 743.07536;140.72762;-1.4347e-002;0.58734
 743.97446;140.63782;-1.4260e-002;0.58686
 744.87356;140.54756;-1.4070e-002;0.58638
 745.77266;140.45771;-1.3678e-002;0.58590
 746.67176;140.36789;-1.3137e-002;0.58543
 747.57086;140.27773;-1.3361e-002;0.58495
 748.46996;140.18713;-1.3002e-002;0.58447
 749.36906;140.09705;-1.2888e-002;0.58399
 750.26816;140.00726;-1.2653e-002;0.58351
 751.16726;139.91664;-1.2616e-002;0.58303
 752.06637;139.82663;-1.2501e-002;0.58256
 752.96547;139.73625;-1.2253e-002;0.58208
 753.86457;139.64665;-1.2215e-002;0.58160
 754.76367;139.55636;-1.1852e-002;0.58112
 755.66277;139.46679;-1.1364e-002;0.58065
 756.56187;139.37705;-1.1216e-002;0.58017
 757.46097;139.28680;-1.0960e-002;0.57969
 758.36007;139.19712;-1.0700e-002;0.57922
 759.25917;139.10668;-1.0596e-002;0.57874
 760.15828;139.01652;-1.0492e-002;0.57826
 761.05738;138.92588;-1.0104e-002;0.57779
 761.95648;138.83637;-9.8996e-003;0.57731
 762.85558;138.74666;-9.8290e-003;0.57684
 763.75468;138.65638;-9.7599e-003;0.57636
 764.65378;138.56627;-9.4923e-003;0.57588
 765.55288;138.47633;-9.4593e-003;0.57541
 766.45198;138.38646;-9.4026e-003;0.57493
 767.35108;138.29705;-9.1066e-003;0.57446
 768.25018;138.20738;-9.0065e-003;0.57399
 769.14929;138.11769;-8.9007e-003;0.57351
 770.04839;138.02778;-8.8146e-003;0.57304
 770.94749;137.93802;-8.6916e-003;0.57256
 771.84659;137.84779;-8.5644e-003;0.57209
 772.74569;137.75806;-8.3035e-003;0.57162
 773.64479;137.66803;-8.2161e-003;0.57114
 774.54389;137.57798;-8.4938e-003;0.57067
 775.44299;137.48845;-8.2958e-003;0.57020
 776.34209;137.39812;-8.3044e-003;0.56972
 777.24119;137.30836;-8.2193e-003;0.56925
 778.14030;137.21831;-8.0423e-003;0.56878
 779.03940;137.12876;-7.9952e-003;0.56831
 779.93850;137.03826;-7.7924e-003;0.56784
 780.83760;136.94799;-7.9200e-003;0.56736
 781.73670;136.85776;-7.5817e-003;0.56689
 782.63580;136.76767;-7.7327e-003;0.56642
 783.53490;136.67796;-7.5307e-003;0.56595
 784.43400;136.58720;-7.5084e-003;0.56548
 785.33310;136.49669;-7.7245e-003;0.56501
 786.23220;136.40679;-7.6973e-003;0.56454
 787.13131;136.31690;-7.6103e-003;0.56407
 788.03041;136.22664;-7.6255e-003;0.56360
 788.92951;136.13638;-7.7132e-003;0.56313
 789.82861;136.04595;-7.6121e-003;0.56266
 790.72771;135.95589;-7.7815e-003;0.56219
 791.62681;135.86598;-7.7868e-003;0.56172
 792.52591;135.77599;-7.7250e-003;0.56125
 793.42501;135.68639;-7.7862e-003;0.56078
 794.32411;135.59683;-7.6251e-003;0.56031
 795.22321;135.50711;-7.6386e-003;0.55984
 796.12232;135.41736;-7.3922e-003;0.55937
 797.02142;135.32746;-7.3648e-003;0.55891
 797.92052;135.23730;-7.4595e-003;0.55844
 798.81962;135.14781;-7.5788e-003;0.55797
 799.71872;135.05810;-7.4443e-003;0.55750
 800.61782;134.96820;-7.5230e-003;0.55704
 801.51692;134.87765;-7.4238e-003;0.55657
 802.41602;134.78897;-7.4426e-003;0.55610
 803.31512;134.69825;-7.3526e-003;0.55563
 804.21422;134.60857;-7.4904e-003;0.55517
 805.11333;134.51919;-7.3169e-003;0.55470
 806.01243;134.42852;-7.3063e-003;0.55424
 806.91153;134.33836;-7.5184e-003;0.55377
 807.81063;134.24871;-7.5185e-003;0.55330
 808.70973;134.15826;-7.3699e-003;0.55284
 809.60883;134.06865;-7.4259e-003;0.55237
 810.50793;133.97804;-7.5102e-003;0.55191
 811.40703;133.88873;-7.3553e-003;0.55144
 812.30613;133.79893;-7.5550e-003;0.55098
 813.20523;133.70888;-7.4707e-003;0.55051
 814.10434;133.61908;-7.3786e-003;0.55005
 815.00344;133.52927;-7.5291e-003;0.54958
 815.90254;133.43941;-7.4153e-003;0.54912
 816.80164;133.34949;-7.4919e-003;0.54866
 817.70074;133.25962;-7.2349e-003;0.54819
 818.59984;133.16910;-7.3133e-003;0.54773
 819.49894;133.07957;-7.3028e-003;0.54727
 820.39804;132.98922;-7.0860e-003;0.54680
 821.29714;132.89875;-7.0928e-003;0.54634
 822.19624;132.80853;-7.0130e-003;0.54588
 823.09535;132.71848;-6.7740e-003;0.54542
 823.99445;132.62840;-7.0207e-003;0.54495
 824.89355;132.53875;-6.8159e-003;0.54449
 825.79265;132.44796;-6.9449e-003;0.54403
 826.69175;132.35818;-6.6585e-003;0.54357
 827.59085;132.26791;-6.7727e-003;0.54311
 828.48995;132.17800;-6.7488e-003;0.54265
 829.38905;132.08778;-6.2929e-003;0.54219
 830.28815;131.99780;-6.4242e-003;0.54172
 831.18725;131.90743;-6.5969e-003;0.54126
 832.08636;131.81754;-6.4402e-003;0.54080
 832.98546;131.72719;-6.3600e-003;0.54034
 833.88456;131.63705;-6.3183e-003;0.53988
 834.78366;131.54690;-6.1423e-003;0.53942
 835.68276;131.45662;-6.0936e-003;0.53896
 836.58186;131.36642;-6.0152e-003;0.53851
 837.48096;131.27614;-6.2217e-003;0.53805
 838.38006;131.18632;-5.9247e-003;0.53759
 839.27916;131.09623;-5.7152e-003;0.53713
 840.17827;131.00642;-5.8746e-003;0.53667
 841.07737;130.91659;-5.4301e-003;0.53621
 841.97647;130.82645;-5.5805e-003;0.53575
 842.87557;130.73674;-5.2882e-003;0.53530
 843.77467;130.64664;-4.9538e-003;0.53484
 844.67377;130.55728;-5.0349e-003;0.53438
 845.57287;130.46731;-4.9232e-003;0.53392
 846.47197;130.37727;-4.7427e-003;0.53347
 847.37107;130.28731;-4.8666e-003;0.53301
 848.27017;130.19762;-4.7348e-003;0.53255
 849.16928;130.10707;-4.3458e-003;0.53210
 850.06838;130.01730;-4.3618e-003;0.53164
 850.96748;129.92671;-4.3535e-003;0.53119
 851.86658;129.83649;-4.2486e-003;0.53073
 852.76568;129.74617;-4.0417e-003;0.53027
 853.66478;129.65594;-3.9321e-003;0.52982
 854.56388;129.56638;-3.5725e-003;0.52936
 855.46298;129.47591;-3.2883e-003;0.52891
 856.36208;129.38518;-3.4884e-003;0.52845
 857.26118;129.29508;-3.2212e-003;0.52800
 858.16029;129.20489;-3.1599e-003;0.52755
 859.05939;129.11382;-3.1434e-003;0.52709
 859.95849;129.02326;-2.9054e-003;0.52664
 860.85759;128.93353;-2.7874e-003;0.52618
 861.75669;128.84307;-2.8058e-003;0.52573
 862.65579;128.75271;-2.6101e-003;0.52528
 863.55489;128.66301;-2.6125e-003;0.52482
 864.45399;128.57231;-2.2375e-003;0.52437
 865.35309;128.48240;-2.2896e-003;0.52392
 866.25219;128.39241;-1.8634e-003;0.52347
 867.15130;128.30242;-1.8890e-003;0.52301
 868.05040;128.21307;-1.6635e-003;0.52256
 868.94950;128.12327;-1.6309e-003;0.52211
 869.84860;128.03354;-1.3458e-003;0.52166
 870.74770;127.94366;-1.0083e-003;0.52121
 871.64680;127.85414;-8.5115e-004;0.52076
 872.54590;127.76421;-9.8016e-004;0.52031
 873.44500;127.67451;-4.6591e-004;0.51985
 874.34410;127.58447;-6.0111e-004;0.51940
 875.24320;127.49475;-8.2713e-005;0.51895
 876.14231;127.40530; 1.2862e-004;0.51850
 877.04141;127.31503;-1.3849e-005;0.51805
 877.94051;127.22503; 3.9361e-004;0.51760
 878.83961;127.13543; 8.1720e-004;0.51716
 879.73871;127.04559; 8.8852e-004;0.51671
 880.63781;126.95541; 1.2785e-003;0.51626
 881.53691;126.86612; 1.5065e-003;0.51581
 882.43601;126.77593; 1.9412e-003;0.51536
 883.33511;126.68614; 2.2254e-003;0.51491
 884.23421;126.59650; 2.2269e-003;0.51446
 885.13332;126.50631; 2.5383e-003;0.51401
 886.03242;126.41667; 2.7537e-003;0.51357
 886.93152;126.32690; 3.1641e-003;0.51312
 887.83062;126.23665; 3.3153e-003;0.51267
 888.72972;126.14642; 3.5502e-003;0.51222
 889.62882;126.05683; 3.8116e-003;0.51178
 890.52792;125.96725; 4.2292e-003;0.51133
 891.42702;125.87680; 4.9204e-003;0.51088
 892.32612;125.78687; 5.1559e-003;0.51044
 893.22522;125.69726; 5.5902e-003;0.50999
 894.12433;125.60702; 5.6890e-003;0.50955
 895.02343;125.51669; 6.1307e-003;0.50910
 895.92253;125.42685; 6.8071e-003;0.50866
 896.82163;125.33683; 7.3079e-003;0.50821
 897.72073;125.24657; 7.8327e-003;0.50777
 898.61983;125.15665; 8.1485e-003;0.50732
 899.51893;125.06609; 8.9643e-003;0.50688
 900.41803;124.97570; 9.7052e-003;0.50643
 901.31713;124.88653; 1.0425e-002;0.50599
 902.21623;124.79653; 1.1603e-002;0.50554
 903.11534;124.70665; 1.2409e-002;0.50510
 904.01444;124.61623; 1.3705e-002;0.50466
 904.91354;124.52607; 1.4973e-002;0.50421
 905.81264;124.43663; 1.6341e-002;0.50377
 906.71174;124.34679; 1.8269e-002;0.50333
 907.61084;124.25728; 2.0104e-002;0.50288
 908.50994;124.16771; 2.2201e-002;0.50244
 909.40904;124.07778; 2.4646e-002;0.50200
 910.30814;123.98825; 2.6821e-002;0.50156
 911.20725;123.89869; 2.9792e-002;0.50111
 912.10635;123.80884; 3.2825e-002;0.50067
 913.00545;123.71991; 3.5589e-002;0.50023
 913.90455;123.62961; 3.8831e-002;0.49979
 914.80365;123.53987; 4.1595e-002;0.49935
 915.70275;123.45033; 4.4696e-002;0.49891
 916.60185;123.36016; 4.7330e-002;0.49847
 917.50095;123.27052; 5.0788e-002;0.49803
 918.40005;123.17989; 5.3350e-002;0.49759
 919.29915;123.09023; 5.5974e-002;0.49715
 920.19826;123.00010; 5.8468e-002;0.49671
 921.09736;122.91024; 6.0674e-002;0.49627
 921.99646;122.82027; 6.2719e-002;0.49583
 922.89556;122.73019; 6.4393e-002;0.49539
 923.79466;122.63994; 6.6141e-002;0.49495
 924.69376;122.55041; 6.7323e-002;0.49451
 925.59286;122.46032; 6.8445e-002;0.49407
 926.49196;122.37008; 6.9587e-002;0.49364
 927.39106;122.27979; 7.0050e-002;0.49320
 928.29016;122.18990; 7.0417e-002;0.49276
 929.18927;122.10034; 7.0594e-002;0.49232
 930.08837;122.00976; 7.0529e-002;0.49188
 930.98747;121.92014; 7.0342e-002;0.49145
 931.88657;121.82982; 7.0290e-002;0.49101
 932.78567;121.73949; 6.9783e-002;0.49057
 933.68477;121.64958; 6.9336e-002;0.49014
 934.58387;121.55948; 6.8889e-002;0.48970
 935.48297;121.46892; 6.8191e-002;0.48926
 936.38207;121.37904; 6.7636e-002;0.48883
 937.28117;121.28935; 6.6564e-002;0.48839
 938.18028;121.19901; 6.5731e-002;0.48796
 939.07938;121.10904; 6.4971e-002;0.48752
 939.97848;121.01927; 6.3901e-002;0.48709
 940.87758;120.92907; 6.2575e-002;0.48665
 941.77668;120.83862; 6.1668e-002;0.48622
 942.67578;120.74854; 6.0551e-002;0.48578
 943.57488;120.65855; 5.9546e-002;0.48535
 944.47398;120.56807; 5.8432e-002;0.48491
 945.37308;120.47785; 5.6981e-002;0.48448
 946.27218;120.38761; 5.5673e-002;0.48405
 947.17129;120.29763; 5.4944e-002;0.48361
 948.07039;120.20750; 5.3922e-002;0.48318
 948.96949;120.11787; 5.2986e-002;0.48275
 949.86859;120.02728; 5.1794e-002;0.48232
 950.76769;119.93774; 5.0409e-002;0.48188
 951.66679;119.84785; 4.9484e-002;0.48145
 952.56589;119.75828; 4.8213e-002;0.48102
 953.46499;119.66860; 4.7331e-002;0.48059
 954.36409;119.57894; 4.6019e-002;0.48015
 955.26319;119.48961; 4.5247e-002;0.47972
 956.16230;119.39992; 4.4425e-002;0.47929
 957.06140;119.30984; 4.3262e-002;0.47886
 957.96050;119.21986; 4.2323e-002;0.47843
 958.85960;119.13044; 4.1565e-002;0.47800
 959.75870;119.04052; 4.0234e-002;0.47757
 960.65780;118.94992; 3.9393e-002;0.47714
 961.55690;118.86010; 3.8212e-002;0.47671
 962.45600;118.77003; 3.7229e-002;0.47628
 963.35510;118.68058; 3.6381e-002;0.47585
 964.25420;118.59035; 3.5589e-002;0.47542
 965.15331;118.50112; 3.4801e-002;0.47499
 966.05241;118.41137; 3.3921e-002;0.47456
 966.95151;118.32206; 3.3235e-002;0.47413
 967.85061;118.23195; 3.2349e-002;0.47370
 968.74971;118.14287; 3.1648e-002;0.47328
 969.64881;118.05335; 3.0972e-002;0.47285
 970.54791;117.96345; 3.0169e-002;0.47242
 971.44701;117.87335; 2.9402e-002;0.47199
 972.34611;117.78411; 2.8613e-002;0.47157
 973.24521;117.69421; 2.8035e-002;0.47114
 974.14432;117.60415; 2.7437e-002;0.47071
 975.04342;117.51436; 2.6816e-002;0.47028
 975.94252;117.42505; 2.6375e-002;0.46986
 976.84162;117.33479; 2.5606e-002;0.46943
 977.74072;117.24469; 2.4760e-002;0.46900
 978.63982;117.15510; 2.4010e-002;0.46858
 979.53892;117.06501; 2.3694e-002;0.46815
 980.43802;116.97603; 2.3295e-002;0.46773
 981.33712;116.88597; 2.2388e-002;0.46730
 982.23623;116.79711; 2.2109e-002;0.46688
 983.13533;116.70701; 2.1475e-002;0.46645
 984.03443;116.61733; 2.1303e-002;0.46603
 984.93353;116.52722; 2.0580e-002;0.46560
 985.83263;116.43674; 2.0203e-002;0.46518
 986.73173;116.34722; 1.9996e-002;0.46475
 987.63083;116.25645; 1.9209e-002;0.46433
 988.52993;116.16609; 1.9315e-002;0.46391
 989.42903;116.07605; 1.8369e-002;0.46348
 990.32813;115.98607; 1.8302e-002;0.46306
 991.22724;115.89589; 1.7633e-002;0.46264
 992.12634;115.80485; 1.6722e-002;0.46221
 993.02544;115.71359; 1.6339e-002;0.46179
 993.92454;115.62343; 1.6178e-002;0.46137
 994.82364;115.53264; 1.5407e-002;0.46095
 995.72274;115.44169; 1.4935e-002;0.46053
 996.62184;115.35137; 1.4024e-002;0.46010
 997.52094;115.25998; 1.3476e-002;0.45968
 998.42004;115.16893; 1.3053e-002;0.45926
 999.31914;115.07874; 1.2602e-002;0.45884
1000.21825;114.98926; 1.2333e-002;0.45842
1001.11735;114.89939; 1.1573e-002;0.45800
1002.01645;114.81016; 1.1417e-002;0.45758
1002.91555;114.72120; 1.1262e-002;0.45716
1003.81465;114.63134; 1.0963e-002;0.45674
1004.71375;114.54307; 1.0489e-002;0.45632
1005.61285;114.45381; 1.0105e-002;0.45590
1006.51195;114.36407; 9.5023e-003;0.45548
1007.41105;114.27433; 9.0677e-003;0.45506
1008.31015;114.18501; 8.6206e-003;0.45464
1009.20926;114.09532; 8.6720e-003;0.45422
1010.10836;114.00603; 8.4819e-003;0.45380
1011.00746;113.91577; 7.8183e-003;0.45338
1011.90656;113.82574; 7.6801e-003;0.45297
1012.80566;113.73596; 7.4587e-003;0.45255
1013.70476;113.64561; 7.1416e-003;0.45213
1014.60386;113.55557; 6.9108e-003;0.45171
1015.50296;113.46555; 6.4247e-003;0.45130
1016.40206;113.37510; 6.1324e-003;0.45088
1017.30116;113.28509; 5.8149e-003;0.45046
1018.20027;113.19547; 5.6853e-003;0.45004
1019.09937;113.10577; 5.5687e-003;0.44963
1019.99847;113.01658; 5.9452e-003;0.44921
1020.89757;112.92696; 5.8554e-003;0.44880
1021.79667;112.83710; 5.5334e-003;0.44838
1022.69577;112.74703; 5.4122e-003;0.44796
1023.59487;112.65732; 5.2945e-003;0.44755
1024.49397;112.56713; 4.8996e-003;0.44713
1025.39307;112.47720; 4.8003e-003;0.44672
1026.29217;112.38734; 4.7850e-003;0.44630
1027.19128;112.29706; 4.1939e-003;0.44589
1028.09038;112.20751; 3.1118e-003;0.44547
1028.98948;112.11680; 4.2695e-003;0.44506
1029.88858;112.02689; 4.2945e-003;0.44465
1030.78768;111.93730; 3.8009e-003;0.44423
1031.68678;111.84733; 3.9046e-003;0.44382
1032.58588;111.75717; 3.9798e-003;0.44341
1033.48498;111.66745; 4.7156e-003;0.44299
1034.38408;111.57774; 4.3584e-003;0.44258
1035.28318;111.48824; 4.5748e-003;0.44217
1036.18229;111.39824; 4.0159e-003;0.44175
1037.08139;111.30817; 3.6012e-003;0.44134
1037.98049;111.21872; 3.1477e-003;0.44093
1038.87959;111.12832; 3.2925e-003;0.44052
1039.77869;111.03872; 3.2975e-003;0.44011
1040.67779;110.94879; 3.1472e-003;0.43969
1041.57689;110.85879; 3.2457e-003;0.43928
1042.47599;110.76907; 3.3638e-003;0.43887
1043.37509;110.67892; 3.3660e-003;0.43846
1044.27419;110.58820; 3.6696e-003;0.43805
1045.17330;110.49816; 3.3408e-003;0.43764
1046.07240;110.40778; 3.4444e-003;0.43723
1046.97150;110.31768; 3.3012e-003;0.43682
1047.87060;110.22714; 3.6589e-003;0.43641
1048.76970;110.13699; 3.8165e-003;0.43600
1049.66880;110.04677; 3.2827e-003;0.43559
1050.56790;109.95705; 3.7402e-003;0.43518
1051.46700;109.86770; 3.5621e-003;0.43477
1052.36610;109.77728; 3.9483e-003;0.43436
1053.26521;109.68725; 3.7829e-003;0.43396
1054.16431;109.59687; 3.5864e-003;0.43355
1055.06341;109.50696; 3.6615e-003;0.43314
1055.96251;109.41702; 3.7620e-003;0.43273
1056.86161;109.32779; 3.6179e-003;0.43232
1057.76071;109.23842; 3.8075e-003;0.43192
1058.65981;109.14908; 3.6949e-003;0.43151
1059.55891;109.05952; 3.4784e-003;0.43110
1060.45801;108.97046; 3.5569e-003;0.43069
1061.35711;108.88168; 3.8921e-003;0.43029
1062.25622;108.79323; 3.9084e-003;0.42988
1063.15532;108.70400; 3.9704e-003;0.42947
1064.05442;108.61491; 4.5595e-003;0.42907
1064.95352;108.52569; 5.0104e-003;0.42866
1065.85262;108.43666; 5.8271e-003;0.42826
1066.75172;108.34742; 6.1029e-003;0.42785
1067.65082;108.25762; 6.5889e-003;0.42745
1068.54992;108.16688; 7.1596e-003;0.42704
1069.44902;108.07575; 7.7817e-003;0.42664
1070.34812;107.98360; 8.2096e-003;0.42623
1071.24723;107.89135; 8.9748e-003;0.42583
1072.14633;107.79768; 9.5344e-003;0.42542
1073.04543;107.70230; 9.7353e-003;0.42502
1073.94453;107.60634; 9.4391e-003;0.42461
1074.84363;107.50886; 8.8218e-003;0.42421
1075.74273;107.41057; 8.0860e-003;0.42381
1076.64183;107.31142; 6.5394e-003;0.42340
1077.54093;107.21266; 5.0522e-003;0.42300
1078.44003;107.11423; 3.0562e-003;0.42260
1079.33913;107.01753; 5.6052e-004;0.42220
1080.23824;106.92319;-2.5901e-003;0.42179
1081.13734;106.83124;-5.2604e-003;0.42139
1082.03644;106.74269;-8.5481e-003;0.42099
1082.93554;106.65778;-1.1436e-002;0.42059
1083.83464;106.57623;-1.4323e-002;0.42019
1084.73374;106.49797;-1.6465e-002;0.41978
1085.63284;106.42303;-1.7716e-002;0.41938
1086.53194;106.35129;-1.8970e-002;0.41898
1087.43104;106.28193;-1.9688e-002;0.41858
1088.33014;106.21462;-1.8926e-002;0.41818
1089.22925;106.14907;-1.7818e-002;0.41778
1090.12835;106.08542;-1.6131e-002;0.41738
1091.02745;106.02249;-1.3177e-002;0.41698
1091.92655;105.96070;-9.1867e-003;0.41658
1092.82565;105.89870;-4.0143e-003;0.41618
1093.72475;105.83699; 2.2054e-003;0.41578
1094.62385;105.77432; 9.4703e-003;0.41538
1095.52295;105.70950; 1.8882e-002;0.41498
1096.42205;105.64243; 2.9283e-002;0.41459
1097.32115;105.57119; 4.2181e-002;0.41419
1098.22026;105.49243; 5.7337e-002;0.41379
1099.11936;105.40050; 7.5910e-002;0.41339
1099.82579;105.30551; 9.5121e-002;0.41308