File: Thesis/DSC/Ti6242-Heat.txt
##Temp./oC;Time/min;DSC/(mW/mg);Sensit./(uV/mW)
  49.32300;0.0000e+000;-2.8553e-002;0.96038
  50.30782;    0.21087;-2.8300e-002;0.95997
  51.29265;    0.40591;-2.8341e-002;0.95955
  52.27747;    0.57438;-2.9430e-002;0.95913
  53.26229;    0.72532;-3.0960e-002;0.95872
  54.24711;    0.86529;-3.3031e-002;0.95830
  55.23193;    0.99784;-3.5233e-002;0.95788
  56.21676;    1.12482;-3.7221e-002;0.95746
  57.20158;    1.24667;-3.9048e-002;0.95704
  58.18640;    1.36385;-4.0875e-002;0.95661
  59.17122;    1.47697;-4.2668e-002;0.95619
  60.15605;    1.58668;-4.4464e-002;0.95577
  61.14087;    1.69351;-4.5920e-002;0.95534
  62.12569;    1.79787;-4.7605e-002;0.95492
  63.11051;    1.89969;-4.9143e-002;0.95449
  64.09533;    1.99926;-5.0527e-002;0.95407
  65.08016;    2.09724;-5.1932e-002;0.95364
  66.06498;    2.19387;-5.3184e-002;0.95321
  67.04980;    2.28911;-5.4406e-002;0.95278
  68.03462;    2.38307;-5.5817e-002;0.95235
  69.01945;    2.47594;-5.6970e-002;0.95192
  70.00427;    2.56768;-5.7801e-002;0.95149
  70.98909;    2.65833;-5.8986e-002;0.95106
  71.97391;    2.74807;-6.0065e-002;0.95063
  72.95873;    2.83711;-6.1009e-002;0.95020
  73.94356;    2.92533;-6.1807e-002;0.94976
  74.92838;    3.01286;-6.2623e-002;0.94933
  75.91320;    3.10004;-6.3395e-002;0.94889
  76.89802;    3.18695;-6.4050e-002;0.94846
  77.88285;    3.27336;-6.4704e-002;0.94802
  78.86767;    3.35914;-6.5184e-002;0.94759
  79.85249;    3.44447;-6.6717e-002;0.94715
  80.83731;    3.52962;-6.7313e-002;0.94671
  81.82213;    3.61462;-6.7684e-002;0.94627
  82.80696;    3.69938;-6.8058e-002;0.94583
  83.79178;    3.78400;-6.8257e-002;0.94539
  84.77660;    3.86849;-6.8600e-002;0.94495
  85.76142;    3.95268;-6.9075e-002;0.94451
  86.74624;    4.03659;-6.9442e-002;0.94406
  87.73107;    4.12039;-6.9633e-002;0.94362
  88.71589;    4.20428;-7.0018e-002;0.94318
  89.70071;    4.28812;-7.0421e-002;0.94273
  90.68553;    4.37178;-7.0694e-002;0.94229
  91.67036;    4.45539;-7.0913e-002;0.94184
  92.65518;    4.53918;-7.0216e-002;0.94140
  93.64000;    4.62329;-7.0190e-002;0.94095
  94.62482;    4.70753;-7.0279e-002;0.94050
  95.60964;    4.79190;-7.0487e-002;0.94005
  96.59447;    4.87651;-7.0600e-002;0.93960
  97.57929;    4.96140;-7.0702e-002;0.93915
  98.56411;    5.04664;-7.0695e-002;0.93870
  99.54893;    5.13230;-7.0519e-002;0.93825
 100.53376;    5.21831;-7.0463e-002;0.93780
 101.51858;    5.30470;-7.0413e-002;0.93735
 102.50340;    5.39143;-7.0369e-002;0.93689
 103.48822;    5.47830;-7.0092e-002;0.93644
 104.47304;    5.56529;-7.0076e-002;0.93599
 105.45787;    5.65266;-6.9834e-002;0.93553
 106.44269;    5.74048;-6.9728e-002;0.93508
 107.42751;    5.82875;-6.9546e-002;0.93462
 108.41233;    5.91754;-6.9535e-002;0.93416
 109.39716;    6.00687;-6.9392e-002;0.93370
 110.38198;    6.09677;-6.9286e-002;0.93325
 111.36680;    6.18710;-6.9137e-002;0.93279
 112.35162;    6.27768;-6.8772e-002;0.93233
 113.33644;    6.36852;-6.8759e-002;0.93187
 114.32127;    6.45986;-6.8518e-002;0.93141
 115.30609;    6.55188;-6.8389e-002;0.93095
 116.29091;    6.64445;-6.8160e-002;0.93048
 117.27573;    6.73741;-6.8081e-002;0.93002
 118.26055;    6.83087;-6.7653e-002;0.92956
 119.24538;    6.92489;-6.7231e-002;0.92909
 120.23020;    7.01939;-6.6707e-002;0.92863
 121.21502;    7.11409;-6.6551e-002;0.92817
 122.19984;    7.20879;-6.6197e-002;0.92770
 123.18467;    7.30369;-6.5881e-002;0.92723
 124.16949;    7.39917;-6.5481e-002;0.92677
 125.15431;    7.49516;-6.5084e-002;0.92630
 126.13913;    7.59137;-6.4752e-002;0.92583
 127.12395;    7.68769;-6.4352e-002;0.92536
 128.10878;    7.78413;-6.3927e-002;0.92489
 129.09360;    7.88073;-6.3334e-002;0.92442
 130.07842;    7.97738;-6.3155e-002;0.92395
 131.06324;    8.07411;-6.3200e-002;0.92348
 132.04807;    8.17117;-6.2759e-002;0.92301
 133.03289;    8.26863;-6.2862e-002;0.92254
 134.01771;    8.36638;-6.2807e-002;0.92207
 135.00253;    8.46442;-6.2617e-002;0.92159
 135.98735;    8.56270;-6.2242e-002;0.92112
 136.97218;    8.66108;-6.1912e-002;0.92064
 137.95700;    8.75957;-6.1609e-002;0.92017
 138.94182;    8.85824;-6.1034e-002;0.91969
 139.92664;    8.95702;-6.0856e-002;0.91922
 140.91147;    9.05582;-6.0631e-002;0.91874
 141.89629;    9.15458;-6.0284e-002;0.91826
 142.88111;    9.25342;-5.9771e-002;0.91779
 143.86593;    9.35255;-5.9583e-002;0.91731
 144.85075;    9.45188;-5.9262e-002;0.91683
 145.83558;    9.55121;-5.8946e-002;0.91635
 146.82040;    9.65050;-5.8697e-002;0.91587
 147.80522;    9.74986;-5.8603e-002;0.91539
 148.79004;    9.84931;-5.8502e-002;0.91491
 149.77486;    9.94873;-5.8449e-002;0.91443
 150.75969;   10.04811;-5.8213e-002;0.91394
 151.74451;   10.14755;-5.8084e-002;0.91346
 152.72933;   10.24700;-5.8027e-002;0.91298
 153.71415;   10.34661;-5.7734e-002;0.91249
 154.69898;   10.44644;-5.7823e-002;0.91201
 155.68380;   10.54602;-5.7754e-002;0.91152
 156.66862;   10.64538;-5.7683e-002;0.91104
 157.65344;   10.74484;-5.7511e-002;0.91055
 158.63826;   10.84443;-5.7604e-002;0.91007
 159.62309;   10.94410;-5.7471e-002;0.90958
 160.60791;   11.04380;-5.7443e-002;0.90909
 161.59273;   11.14347;-5.7228e-002;0.90860
 162.57755;   11.24315;-5.7170e-002;0.90811
 163.56238;   11.34279;-5.7157e-002;0.90762
 164.54720;   11.44233;-5.7211e-002;0.90713
 165.53202;   11.54188;-5.7097e-002;0.90664
 166.51684;   11.64145;-5.7105e-002;0.90615
 167.50166;   11.74084;-5.6947e-002;0.90566
 168.48649;   11.84010;-5.7052e-002;0.90517
 169.47131;   11.93944;-5.6875e-002;0.90468
 170.45613;   12.03905;-5.6839e-002;0.90419
 171.44095;   12.13869;-5.6899e-002;0.90369
 172.42578;   12.23789;-5.6653e-002;0.90320
 173.41060;   12.33677;-5.6801e-002;0.90270
 174.39542;   12.43557;-5.6811e-002;0.90221
 175.38024;   12.53431;-5.6779e-002;0.90171
 176.36506;   12.63304;-5.6615e-002;0.90122
 177.34989;   12.73190;-5.6582e-002;0.90072
 178.33471;   12.83085;-5.6671e-002;0.90022
 179.31953;   12.92957;-5.6564e-002;0.89973
 180.30435;   13.02807;-5.6514e-002;0.89923
 181.28917;   13.12670;-5.6449e-002;0.89873
 182.27400;   13.22554;-5.6514e-002;0.89823
 183.25882;   13.32446;-5.6494e-002;0.89773
 184.24364;   13.42315;-5.6325e-002;0.89723
 185.22846;   13.52151;-5.6168e-002;0.89673
 186.21329;   13.61974;-5.6225e-002;0.89623
 187.19811;   13.71791;-5.6177e-002;0.89573
 188.18293;   13.81605;-5.5932e-002;0.89523
 189.16775;   13.91418;-5.5897e-002;0.89473
 190.15257;   14.01233;-5.5832e-002;0.89423
 191.13740;   14.11044;-5.5940e-002;0.89372
 192.12222;   14.20850;-5.5759e-002;0.89322
 193.10704;   14.30658;-5.5545e-002;0.89271
 194.09186;   14.40489;-5.5610e-002;0.89221
 195.07669;   14.50345;-5.5519e-002;0.89171
 196.06151;   14.60196;-5.5365e-002;0.89120
 197.04633;   14.70033;-5.5299e-002;0.89069
 198.03115;   14.79870;-5.5215e-002;0.89019
 199.01597;   14.89718;-5.5280e-002;0.88968
 200.00080;   14.99575;-5.5103e-002;0.88917
 200.98562;   15.09429;-5.4945e-002;0.88867
 201.97044;   15.19266;-5.4867e-002;0.88816
 202.95526;   15.29078;-5.4840e-002;0.88765
 203.94009;   15.38896;-5.4664e-002;0.88714
 204.92491;   15.48759;-5.4601e-002;0.88663
 205.90973;   15.58634;-5.4427e-002;0.88612
 206.89455;   15.68489;-5.4369e-002;0.88561
 207.87937;   15.78348;-5.4147e-002;0.88510
 208.86420;   15.88205;-5.4254e-002;0.88459
 209.84902;   15.98062;-5.4110e-002;0.88408
 210.83384;   16.07933;-5.3996e-002;0.88357
 211.81866;   16.17799;-5.3855e-002;0.88306
 212.80348;   16.27677;-5.3798e-002;0.88254
 213.78831;   16.37567;-5.3787e-002;0.88203
 214.77313;   16.47433;-5.3665e-002;0.88152
 215.75795;   16.57287;-5.3487e-002;0.88100
 216.74277;   16.67168;-5.3212e-002;0.88049
 217.72760;   16.77091;-5.2934e-002;0.87997
 218.71242;   16.87022;-5.2832e-002;0.87946
 219.69724;   16.96914;-5.2578e-002;0.87894
 220.68206;   17.06771;-5.2422e-002;0.87843
 221.66688;   17.16633;-5.2429e-002;0.87791
 222.65171;   17.26518;-5.2266e-002;0.87739
 223.63653;   17.36412;-5.2092e-002;0.87687
 224.62135;   17.46304;-5.2070e-002;0.87636
 225.60617;   17.56193;-5.2037e-002;0.87584
 226.59100;   17.66079;-5.1961e-002;0.87532
 227.57582;   17.75969;-5.2015e-002;0.87480
 228.56064;   17.85862;-5.1758e-002;0.87428
 229.54546;   17.95762;-5.1752e-002;0.87376
 230.53028;   18.05674;-5.1684e-002;0.87324
 231.51511;   18.15581;-5.1586e-002;0.87272
 232.49993;   18.25469;-5.1506e-002;0.87220
 233.48475;   18.35343;-5.1383e-002;0.87168
 234.46957;   18.45206;-5.1264e-002;0.87116
 235.45439;   18.55060;-5.1189e-002;0.87064
 236.43922;   18.64933;-5.1080e-002;0.87011
 237.42404;   18.74841;-5.1141e-002;0.86959
 238.40886;   18.84736;-5.0993e-002;0.86907
 239.39368;   18.94583;-5.0833e-002;0.86855
 240.37851;   19.04416;-5.0834e-002;0.86802
 241.36333;   19.14266;-5.0764e-002;0.86750
 242.34815;   19.24142;-5.0721e-002;0.86697
 243.33297;   19.34010;-5.0507e-002;0.86645
 244.31779;   19.43860;-5.0311e-002;0.86592
 245.30262;   19.53732;-5.0317e-002;0.86540
 246.28744;   19.63616;-5.0266e-002;0.86487
 247.27226;   19.73479;-5.0052e-002;0.86434
 248.25708;   19.83330;-4.9929e-002;0.86382
 249.24191;   19.93179;-4.9825e-002;0.86329
 250.22673;   20.03025;-4.9655e-002;0.86276
 251.21155;   20.12869;-4.9568e-002;0.86224
 252.19637;   20.22733;-4.9358e-002;0.86171
 253.18119;   20.32622;-4.9046e-002;0.86118
 254.16602;   20.42502;-4.8703e-002;0.86065
 255.15084;   20.52370;-4.8517e-002;0.86012
 256.13566;   20.62243;-4.8290e-002;0.85959
 257.12048;   20.72130;-4.7865e-002;0.85906
 258.10531;   20.82005;-4.7657e-002;0.85853
 259.09013;   20.91852;-4.7532e-002;0.85800
 260.07495;   21.01711;-4.7638e-002;0.85747
 261.05977;   21.11596;-4.7566e-002;0.85694
 262.04459;   21.21487;-4.7409e-002;0.85641
 263.02942;   21.31386;-4.7263e-002;0.85588
 264.01424;   21.41292;-4.7139e-002;0.85535
 264.99906;   21.51177;-4.7054e-002;0.85481
 265.98388;   21.61035;-4.7192e-002;0.85428
 266.96870;   21.70891;-4.7080e-002;0.85375
 267.95353;   21.80763;-4.6965e-002;0.85321
 268.93835;   21.90643;-4.6842e-002;0.85268
 269.92317;   22.00504;-4.6770e-002;0.85215
 270.90799;   22.10348;-4.6745e-002;0.85161
 271.89282;   22.20204;-4.6604e-002;0.85108
 272.87764;   22.30070;-4.6542e-002;0.85054
 273.86246;   22.39927;-4.6531e-002;0.85001
 274.84728;   22.49776;-4.6256e-002;0.84947
 275.83210;   22.59606;-4.6365e-002;0.84894
 276.81693;   22.69411;-4.6184e-002;0.84840
 277.80175;   22.79219;-4.6195e-002;0.84786
 278.78657;   22.89030;-4.6129e-002;0.84733
 279.77139;   22.98831;-4.5952e-002;0.84679
 280.75622;   23.08631;-4.5796e-002;0.84625
 281.74104;   23.18442;-4.5694e-002;0.84571
 282.72586;   23.28259;-4.5619e-002;0.84518
 283.71068;   23.38067;-4.5529e-002;0.84464
 284.69550;   23.47871;-4.5404e-002;0.84410
 285.68033;   23.57693;-4.5206e-002;0.84356
 286.66515;   23.67524;-4.5163e-002;0.84302
 287.64997;   23.77350;-4.5280e-002;0.84248
 288.63479;   23.87187;-4.5114e-002;0.84194
 289.61962;   23.97047;-4.4825e-002;0.84140
 290.60444;   24.06924;-4.4808e-002;0.84086
 291.58926;   24.16806;-4.4564e-002;0.84032
 292.57408;   24.26679;-4.4359e-002;0.83978
 293.55890;   24.36533;-4.4227e-002;0.83924
 294.54373;   24.46374;-4.4290e-002;0.83870
 295.52855;   24.56206;-4.3996e-002;0.83816
 296.51337;   24.66027;-4.3813e-002;0.83762
 297.49819;   24.75858;-4.3738e-002;0.83708
 298.48301;   24.85735;-4.3351e-002;0.83653
 299.46784;   24.95639;-4.3203e-002;0.83599
 300.45266;   25.05524;-4.2970e-002;0.83545
 301.43748;   25.15395;-4.2889e-002;0.83491
 302.42230;   25.25272;-4.2697e-002;0.83436
 303.40713;   25.35157;-4.2497e-002;0.83382
 304.39195;   25.45027;-4.2318e-002;0.83327
 305.37677;   25.54883;-4.2186e-002;0.83273
 306.36159;   25.64752;-4.1831e-002;0.83219
 307.34641;   25.74640;-4.1799e-002;0.83164
 308.33124;   25.84516;-4.1546e-002;0.83110
 309.31606;   25.94379;-4.1410e-002;0.83055
 310.30088;   26.04254;-4.1126e-002;0.83001
 311.28570;   26.14127;-4.1057e-002;0.82946
 312.27053;   26.23995;-4.0888e-002;0.82892
 313.25535;   26.33871;-4.0759e-002;0.82837
 314.24017;   26.43740;-4.0526e-002;0.82782
 315.22499;   26.53581;-4.0247e-002;0.82728
 316.20981;   26.63417;-4.0207e-002;0.82673
 317.19464;   26.73270;-4.0142e-002;0.82618
 318.17946;   26.83124;-4.0013e-002;0.82564
 319.16428;   26.92995;-3.9751e-002;0.82509
 320.14910;   27.02899;-3.9585e-002;0.82454
 321.13393;   27.12806;-3.9522e-002;0.82399
 322.11875;   27.22687;-3.9142e-002;0.82345
 323.10357;   27.32540;-3.9029e-002;0.82290
 324.08839;   27.42385;-3.8907e-002;0.82235
 325.07321;   27.52243;-3.8855e-002;0.82180
 326.05804;   27.62126;-3.8463e-002;0.82125
 327.04286;   27.72015;-3.8374e-002;0.82070
 328.02768;   27.81891;-3.8333e-002;0.82015
 329.01250;   27.91768;-3.7973e-002;0.81960
 329.99732;   28.01649;-3.8069e-002;0.81906
 330.98215;   28.11513;-3.7996e-002;0.81851
 331.96697;   28.21355;-3.7698e-002;0.81796
 332.95179;   28.31191;-3.7572e-002;0.81740
 333.93661;   28.41041;-3.7452e-002;0.81685
 334.92144;   28.50903;-3.7343e-002;0.81630
 335.90626;   28.60760;-3.7108e-002;0.81575
 336.89108;   28.70607;-3.7101e-002;0.81520
 337.87590;   28.80454;-3.6897e-002;0.81465
 338.86072;   28.90307;-3.6730e-002;0.81410
 339.84555;   29.00162;-3.6499e-002;0.81355
 340.83037;   29.10016;-3.6322e-002;0.81300
 341.81519;   29.19888;-3.6199e-002;0.81244
 342.80001;   29.29770;-3.5904e-002;0.81189
 343.78484;   29.39627;-3.5928e-002;0.81134
 344.76966;   29.49471;-3.5786e-002;0.81079
 345.75448;   29.59322;-3.5698e-002;0.81023
 346.73930;   29.69173;-3.5528e-002;0.80968
 347.72412;   29.79018;-3.5356e-002;0.80913
 348.70895;   29.88870;-3.5141e-002;0.80858
 349.69377;   29.98732;-3.5175e-002;0.80802
 350.67859;   30.08599;-3.5103e-002;0.80747
 351.66341;   30.18470;-3.4917e-002;0.80691
 352.64824;   30.28325;-3.4809e-002;0.80636
 353.63306;   30.38153;-3.4626e-002;0.80581
 354.61788;   30.47981;-3.4334e-002;0.80525
 355.60270;   30.57827;-3.4140e-002;0.80470
 356.58752;   30.67675;-3.3936e-002;0.80414
 357.57235;   30.77525;-3.3758e-002;0.80359
 358.55717;   30.87385;-3.3765e-002;0.80303
 359.54199;   30.97262;-3.3642e-002;0.80248
 360.52681;   31.07134;-3.3477e-002;0.80192
 361.51163;   31.16977;-3.3216e-002;0.80137
 362.49646;   31.26811;-3.3207e-002;0.80081
 363.48128;   31.36646;-3.2916e-002;0.80026
 364.46610;   31.46465;-3.2849e-002;0.79970
 365.45092;   31.56284;-3.2631e-002;0.79915
 366.43575;   31.66115;-3.2436e-002;0.79859
 367.42057;   31.75950;-3.2287e-002;0.79803
 368.40539;   31.85796;-3.1948e-002;0.79748
 369.39021;   31.95647;-3.2010e-002;0.79692
 370.37503;   32.05491;-3.1819e-002;0.79636
 371.35986;   32.15346;-3.1727e-002;0.79581
 372.34468;   32.25205;-3.1434e-002;0.79525
 373.32950;   32.35058;-3.1337e-002;0.79469
 374.31432;   32.44909;-3.1165e-002;0.79414
 375.29915;   32.54756;-3.0903e-002;0.79358
 376.28397;   32.64603;-3.0824e-002;0.79302
 377.26879;   32.74457;-3.0771e-002;0.79247
 378.25361;   32.84318;-3.0419e-002;0.79191
 379.23843;   32.94184;-3.0263e-002;0.79135
 380.22326;   33.04047;-3.0210e-002;0.79079
 381.20808;   33.13901;-3.0005e-002;0.79023
 382.19290;   33.23753;-2.9846e-002;0.78968
 383.17772;   33.33612;-2.9555e-002;0.78912
 384.16255;   33.43480;-2.9453e-002;0.78856
 385.14737;   33.53351;-2.9216e-002;0.78800
 386.13219;   33.63222;-2.9131e-002;0.78744
 387.11701;   33.73090;-2.8955e-002;0.78688
 388.10183;   33.82966;-2.8927e-002;0.78632
 389.08666;   33.92857;-2.8586e-002;0.78577
 390.07148;   34.02742;-2.8488e-002;0.78521
 391.05630;   34.12623;-2.8348e-002;0.78465
 392.04112;   34.22515;-2.8314e-002;0.78409
 393.02594;   34.32403;-2.8110e-002;0.78353
 394.01077;   34.42276;-2.7800e-002;0.78297
 394.99559;   34.52148;-2.7563e-002;0.78241
 395.98041;   34.62018;-2.7439e-002;0.78185
 396.96523;   34.71880;-2.7445e-002;0.78129
 397.95006;   34.81749;-2.7305e-002;0.78073
 398.93488;   34.91623;-2.6990e-002;0.78017
 399.91970;   35.01507;-2.6931e-002;0.77961
 400.90452;   35.11405;-2.6846e-002;0.77905
 401.88934;   35.21300;-2.6572e-002;0.77849
 402.87417;   35.31177;-2.6382e-002;0.77793
 403.85899;   35.41032;-2.6155e-002;0.77737
 404.84381;   35.50872;-2.6077e-002;0.77681
 405.82863;   35.60719;-2.5802e-002;0.77625
 406.81346;   35.70592;-2.5526e-002;0.77569
 407.79828;   35.80475;-2.5308e-002;0.77513
 408.78310;   35.90332;-2.5280e-002;0.77457
 409.76792;   36.00187;-2.4967e-002;0.77401
 410.75274;   36.10063;-2.4862e-002;0.77345
 411.73757;   36.19932;-2.4540e-002;0.77288
 412.72239;   36.29767;-2.4316e-002;0.77232
 413.70721;   36.39594;-2.4274e-002;0.77176
 414.69203;   36.49440;-2.3985e-002;0.77120
 415.67685;   36.59290;-2.3636e-002;0.77064
 416.66168;   36.69128;-2.3494e-002;0.77008
 417.64650;   36.78954;-2.3483e-002;0.76952
 418.63132;   36.88781;-2.3181e-002;0.76896
 419.61614;   36.98611;-2.3030e-002;0.76839
 420.60097;   37.08434;-2.3014e-002;0.76783
 421.58579;   37.18260;-2.2642e-002;0.76727
 422.57061;   37.28103;-2.2519e-002;0.76671
 423.55543;   37.37951;-2.2177e-002;0.76615
 424.54025;   37.47780;-2.1991e-002;0.76559
 425.52508;   37.57596;-2.1905e-002;0.76502
 426.50990;   37.67425;-2.1736e-002;0.76446
 427.49472;   37.77278;-2.1461e-002;0.76390
 428.47954;   37.87144;-2.1331e-002;0.76334
 429.46437;   37.97013;-2.1162e-002;0.76278
 430.44919;   38.06875;-2.0943e-002;0.76221
 431.43401;   38.16728;-2.0709e-002;0.76165
 432.41883;   38.26567;-2.0558e-002;0.76109
 433.40365;   38.36412;-2.0498e-002;0.76053
 434.38848;   38.46272;-2.0139e-002;0.75996
 435.37330;   38.56132;-2.0126e-002;0.75940
 436.35812;   38.65982;-1.9794e-002;0.75884
 437.34294;   38.75837;-1.8825e-002;0.75828
 438.32777;   38.85684;-1.8156e-002;0.75771
 439.31259;   38.95507;-1.7956e-002;0.75715
 440.29741;   39.05325;-1.7626e-002;0.75659
 441.28223;   39.15149;-1.7968e-002;0.75603
 442.26705;   39.24980;-1.7876e-002;0.75546
 443.25188;   39.34822;-1.7696e-002;0.75490
 444.23670;   39.44678;-1.7434e-002;0.75434
 445.22152;   39.54546;-1.7264e-002;0.75378
 446.20634;   39.64394;-1.7172e-002;0.75321
 447.19116;   39.74215;-1.6844e-002;0.75265
 448.17599;   39.84040;-1.6573e-002;0.75209
 449.16081;   39.93878;-1.6421e-002;0.75153
 450.14563;   40.03725;-1.6143e-002;0.75096
 451.13045;   40.13583;-1.5955e-002;0.75040
 452.11528;   40.23444;-1.5717e-002;0.74984
 453.10010;   40.33292;-1.5498e-002;0.74927
 454.08492;   40.43149;-1.5172e-002;0.74871
 455.06974;   40.53022;-1.4918e-002;0.74815
 456.05456;   40.62881;-1.4560e-002;0.74759
 457.03939;   40.72736;-1.4350e-002;0.74702
 458.02421;   40.82606;-1.4233e-002;0.74646
 459.00903;   40.92487;-1.3894e-002;0.74590
 459.99385;   41.02355;-1.3614e-002;0.74533
 460.97868;   41.12197;-1.3553e-002;0.74477
 461.96350;   41.22024;-1.3173e-002;0.74421
 462.94832;   41.31859;-1.2942e-002;0.74365
 463.93314;   41.41716;-1.2744e-002;0.74308
 464.91796;   41.51573;-1.2424e-002;0.74252
 465.90279;   41.61413;-1.1888e-002;0.74196
 466.88761;   41.71253;-1.1670e-002;0.74139
 467.87243;   41.81103;-1.1235e-002;0.74083
 468.85725;   41.90953;-1.1076e-002;0.74027
 469.84208;   42.00806;-1.0889e-002;0.73970
 470.82690;   42.10668;-1.0804e-002;0.73914
 471.81172;   42.20543;-1.0582e-002;0.73858
 472.79654;   42.30401;-1.0520e-002;0.73802
 473.78136;   42.40222;-1.0314e-002;0.73745
 474.76619;   42.50047;-1.0334e-002;0.73689
 475.75101;   42.59895;-1.0371e-002;0.73633
 476.73583;   42.69741;-1.0220e-002;0.73576
 477.72065;   42.79585;-1.0055e-002;0.73520
 478.70547;   42.89443;-9.6599e-003;0.73464
 479.69030;   42.99304;-9.4773e-003;0.73408
 480.67512;   43.09144;-9.2687e-003;0.73351
 481.65994;   43.18974;-9.0254e-003;0.73295
 482.64476;   43.28811;-9.0166e-003;0.73239
 483.62959;   43.38653;-9.4359e-003;0.73182
 484.61441;   43.48505;-9.0377e-003;0.73126
 485.59923;   43.58358;-8.9787e-003;0.73070
 486.58405;   43.68211;-8.8473e-003;0.73014
 487.56887;   43.78079;-9.0126e-003;0.72957
 488.55370;   43.87961;-8.5854e-003;0.72901
 489.53852;   43.97837;-8.3644e-003;0.72845
 490.52334;   44.07699;-8.3088e-003;0.72789
 491.50816;   44.17567;-8.1067e-003;0.72732
 492.49299;   44.27460;-7.9083e-003;0.72676
 493.47781;   44.37354;-7.9869e-003;0.72620
 494.46263;   44.47231;-7.8633e-003;0.72564
 495.44745;   44.57101;-7.5672e-003;0.72507
 496.43227;   44.66979;-7.3135e-003;0.72451
 497.41710;   44.76857;-7.2173e-003;0.72395
 498.40192;   44.86732;-6.9394e-003;0.72339
 499.38674;   44.96619;-6.6529e-003;0.72283
 500.37156;   45.06508;-6.3762e-003;0.72226
 501.35639;   45.16369;-6.0249e-003;0.72170
 502.34121;   45.26215;-5.7166e-003;0.72114
 503.32603;   45.36051;-5.7568e-003;0.72058
 504.31085;   45.45885;-5.6002e-003;0.72001
 505.29567;   45.55742;-5.3431e-003;0.71945
 506.28050;   45.65610;-5.1652e-003;0.71889
 507.26532;   45.75466;-5.0028e-003;0.71833
 508.25014;   45.85309;-4.8658e-003;0.71777
 509.23496;   45.95133;-4.6268e-003;0.71721
 510.21978;   46.04948;-4.5229e-003;0.71664
 511.20461;   46.14780;-4.0826e-003;0.71608
 512.18943;   46.24641;-4.0893e-003;0.71552
 513.17425;   46.34516;-3.8981e-003;0.71496
 514.15907;   46.44363;-3.7788e-003;0.71440
 515.14390;   46.54190;-3.7284e-003;0.71384
 516.12872;   46.64034;-3.5477e-003;0.71327
 517.11354;   46.73897;-3.5447e-003;0.71271
 518.09836;   46.83769;-3.3509e-003;0.71215
 519.08318;   46.93629;-3.0395e-003;0.71159
 520.06801;   47.03474;-2.9239e-003;0.71103
 521.05283;   47.13313;-2.6777e-003;0.71047
 522.03765;   47.23168;-2.4939e-003;0.70991
 523.02247;   47.33052;-2.3031e-003;0.70935
 524.00730;   47.42932;-1.9645e-003;0.70879
 524.99212;   47.52778;-1.8874e-003;0.70823
 525.97694;   47.62598;-1.6387e-003;0.70766
 526.96176;   47.72411;-1.4905e-003;0.70710
 527.94658;   47.82238;-1.0893e-003;0.70654
 528.93141;   47.92077;-9.3747e-004;0.70598
 529.91623;   48.01905;-7.5003e-004;0.70542
 530.90105;   48.11730;-3.5515e-004;0.70486
 531.88587;   48.21562;-2.1234e-004;0.70430
 532.87070;   48.31389;-4.1617e-006;0.70374
 533.85552;   48.41217;-1.0306e-004;0.70318
 534.84034;   48.51055; 2.6341e-004;0.70262
 535.82516;   48.60889; 2.4531e-004;0.70206
 536.80998;   48.70710; 3.9562e-004;0.70150
 537.79481;   48.80529; 9.2299e-004;0.70094
 538.77963;   48.90360; 1.0310e-003;0.70038
 539.76445;   49.00202; 1.3124e-003;0.69982
 540.74927;   49.10039; 1.6969e-003;0.69926
 541.73409;   49.19868; 1.9720e-003;0.69870
 542.71892;   49.29697; 2.1380e-003;0.69814
 543.70374;   49.39530; 2.1162e-003;0.69759
 544.68856;   49.49366; 2.6072e-003;0.69703
 545.67338;   49.59194; 2.7472e-003;0.69647
 546.65821;   49.69021; 2.7081e-003;0.69591
 547.64303;   49.78845; 2.7855e-003;0.69535
 548.62785;   49.88670; 2.9968e-003;0.69479
 549.61267;   49.98502; 3.3230e-003;0.69423
 550.59749;   50.08327; 3.2667e-003;0.69367
 551.58232;   50.18149; 3.8115e-003;0.69311
 552.56714;   50.27994; 3.6721e-003;0.69256
 553.55196;   50.37860; 3.8843e-003;0.69200
 554.53678;   50.47715; 4.0045e-003;0.69144
 555.52161;   50.57550; 4.1835e-003;0.69088
 556.50643;   50.67378; 4.2715e-003;0.69032
 557.49125;   50.77211; 4.6485e-003;0.68977
 558.47607;   50.87058; 5.0923e-003;0.68921
 559.46089;   50.96924; 5.0952e-003;0.68865
 560.44572;   51.06784; 5.4495e-003;0.68809
 561.43054;   51.16621; 5.3919e-003;0.68753
 562.41536;   51.26442; 5.7548e-003;0.68698
 563.40018;   51.36253; 5.9407e-003;0.68642
 564.38501;   51.46059; 6.2243e-003;0.68586
 565.36983;   51.55865; 6.2569e-003;0.68531
 566.35465;   51.65691; 6.4464e-003;0.68475
 567.33947;   51.75526; 6.6879e-003;0.68419
 568.32429;   51.85364; 6.7115e-003;0.68364
 569.30912;   51.95208; 6.8966e-003;0.68308
 570.29394;   52.05048; 7.2061e-003;0.68252
 571.27876;   52.14885; 7.3378e-003;0.68197
 572.26358;   52.24729; 7.5488e-003;0.68141
 573.24840;   52.34589; 7.8041e-003;0.68085
 574.23323;   52.44479; 7.8648e-003;0.68030
 575.21805;   52.54378; 8.0882e-003;0.67974
 576.20287;   52.64253; 8.3570e-003;0.67919
 577.18769;   52.74118; 8.5001e-003;0.67863
 578.17252;   52.83975; 8.9027e-003;0.67807
 579.15734;   52.93824; 8.8833e-003;0.67752
 580.14216;   53.03684; 9.2246e-003;0.67696
 581.12698;   53.13558; 9.5588e-003;0.67641
 582.11180;   53.23434; 9.6786e-003;0.67585
 583.09663;   53.33306; 9.6777e-003;0.67530
 584.08145;   53.43167; 1.0005e-002;0.67474
 585.06627;   53.53025; 9.9680e-003;0.67419
 586.05109;   53.62890; 1.0192e-002;0.67363
 587.03592;   53.72768; 1.0343e-002;0.67308
 588.02074;   53.82659; 1.0562e-002;0.67253
 589.00556;   53.92547; 1.0733e-002;0.67197
 589.99038;   54.02426; 1.1006e-002;0.67142
 590.97520;   54.12299; 1.1116e-002;0.67086
 591.96003;   54.22156; 1.1459e-002;0.67031
 592.94485;   54.31997; 1.1824e-002;0.66976
 593.92967;   54.41842; 1.2061e-002;0.66920
 594.91449;   54.51694; 1.2336e-002;0.66865
 595.89931;   54.61542; 1.2608e-002;0.66810
 596.88414;   54.71381; 1.2929e-002;0.66754
 597.86896;   54.81214; 1.2999e-002;0.66699
 598.85378;   54.91041; 1.3207e-002;0.66644
 599.83860;   55.00868; 1.3144e-002;0.66588
 600.82343;   55.10693; 1.3488e-002;0.66533
 601.80825;   55.20515; 1.3561e-002;0.66478
 602.79307;   55.30344; 1.3690e-002;0.66423
 603.77789;   55.40185; 1.3726e-002;0.66368
 604.76271;   55.50018; 1.3812e-002;0.66312
 605.74754;   55.59838; 1.3825e-002;0.66257
 606.73236;   55.69673; 1.3893e-002;0.66202
 607.71718;   55.79519; 1.3985e-002;0.66147
 608.70200;   55.89362; 1.4255e-002;0.66092
 609.68683;   55.99221; 1.4333e-002;0.66037
 610.67165;   56.09092; 1.4360e-002;0.65981
 611.65647;   56.18955; 1.4507e-002;0.65926
 612.64129;   56.28815; 1.4328e-002;0.65871
 613.62611;   56.38684; 1.4615e-002;0.65816
 614.61094;   56.48553; 1.4787e-002;0.65761
 615.59576;   56.58416; 1.4759e-002;0.65706
 616.58058;   56.68293; 1.5454e-002;0.65651
 617.56540;   56.78175; 1.5433e-002;0.65596
 618.55023;   56.88037; 1.5824e-002;0.65541
 619.53505;   56.97888; 1.5945e-002;0.65486
 620.51987;   57.07736; 1.6063e-002;0.65431
 621.50469;   57.17585; 1.6461e-002;0.65376
 622.48951;   57.27436; 1.6596e-002;0.65321
 623.47434;   57.37275; 1.6776e-002;0.65266
 624.45916;   57.47096; 1.6992e-002;0.65212
 625.44398;   57.56911; 1.7101e-002;0.65157
 626.42880;   57.66741; 1.7284e-002;0.65102
 627.41362;   57.76597; 1.7012e-002;0.65047
 628.39845;   57.86446; 1.7190e-002;0.64992
 629.38327;   57.96272; 1.7429e-002;0.64937
 630.36809;   58.06097; 1.7357e-002;0.64882
 631.35291;   58.15938; 1.7543e-002;0.64828
 632.33774;   58.25798; 1.7566e-002;0.64773
 633.32256;   58.35658; 1.7754e-002;0.64718
 634.30738;   58.45506; 1.7821e-002;0.64663
 635.29220;   58.55348; 1.8032e-002;0.64609
 636.27702;   58.65186; 1.8389e-002;0.64554
 637.26185;   58.75035; 1.8489e-002;0.64499
 638.24667;   58.84892; 1.8509e-002;0.64445
 639.23149;   58.94735; 1.8808e-002;0.64390
 640.21631;   59.04572; 1.9202e-002;0.64335
 641.20114;   59.14403; 1.9371e-002;0.64281
 642.18596;   59.24230; 1.9492e-002;0.64226
 643.17078;   59.34068; 1.9613e-002;0.64172
 644.15560;   59.43911; 1.9662e-002;0.64117
 645.14042;   59.53759; 1.9656e-002;0.64063
 646.12525;   59.63616; 2.0112e-002;0.64008
 647.11007;   59.73463; 2.0097e-002;0.63953
 648.09489;   59.83292; 2.0517e-002;0.63899
 649.07971;   59.93112; 2.0389e-002;0.63845
 650.06454;   60.02937; 2.0785e-002;0.63790
 651.04936;   60.12772; 2.0881e-002;0.63736
 652.03418;   60.22600; 2.1102e-002;0.63681
 653.01900;   60.32411; 2.1206e-002;0.63627
 654.00382;   60.42216; 2.1483e-002;0.63572
 654.98865;   60.52021; 2.1535e-002;0.63518
 655.97347;   60.61832; 2.1499e-002;0.63464
 656.95829;   60.71670; 2.1634e-002;0.63409
 657.94311;   60.81537; 2.1615e-002;0.63355
 658.92793;   60.91408; 2.1854e-002;0.63301
 659.91276;   61.01266; 2.2233e-002;0.63246
 660.89758;   61.11099; 2.2202e-002;0.63192
 661.88240;   61.20917; 2.2514e-002;0.63138
 662.86722;   61.30751; 2.2618e-002;0.63084
 663.85205;   61.40607; 2.2979e-002;0.63030
 664.83687;   61.50467; 2.3388e-002;0.62975
 665.82169;   61.60329; 2.3603e-002;0.62921
 666.80651;   61.70181; 2.3724e-002;0.62867
 667.79133;   61.80030; 2.3879e-002;0.62813
 668.77616;   61.89892; 2.3854e-002;0.62759
 669.76098;   61.99743; 2.3976e-002;0.62705
 670.74580;   62.09580; 2.4411e-002;0.62651
 671.73062;   62.19429; 2.5467e-002;0.62597
 672.71545;   62.29295; 2.5580e-002;0.62543
 673.70027;   62.39171; 2.4346e-002;0.62489
 674.68509;   62.49049; 2.4374e-002;0.62435
 675.66991;   62.58913; 2.4203e-002;0.62381
 676.65473;   62.68756; 2.4523e-002;0.62327
 677.63956;   62.78600; 2.4731e-002;0.62273
 678.62438;   62.88455; 2.5226e-002;0.62219
 679.60920;   62.98321; 2.5332e-002;0.62165
 680.59402;   63.08192; 2.5625e-002;0.62111
 681.57885;   63.18073; 2.5928e-002;0.62057
 682.56367;   63.27964; 2.5993e-002;0.62003
 683.54849;   63.37861; 2.6352e-002;0.61949
 684.53331;   63.47758; 2.6685e-002;0.61896
 685.51813;   63.57640; 2.7016e-002;0.61842
 686.50296;   63.67501; 2.7525e-002;0.61788
 687.48778;   63.77349; 2.7642e-002;0.61734
 688.47260;   63.87195; 2.7826e-002;0.61681
 689.45742;   63.97046; 2.7985e-002;0.61627
 690.44224;   64.06890; 2.8522e-002;0.61573
 691.42707;   64.16723; 2.9236e-002;0.61520
 692.41189;   64.26567; 2.9686e-002;0.61466
 693.39671;   64.36431; 3.0099e-002;0.61412
 694.38153;   64.46312; 3.0368e-002;0.61359
 695.36636;   64.56190; 3.0636e-002;0.61305
 696.35118;   64.66051; 3.0820e-002;0.61251
 697.33600;   64.75900; 3.0710e-002;0.61198
 698.32082;   64.85746; 3.1280e-002;0.61144
 699.30564;   64.95598; 3.2355e-002;0.61091
 700.29047;   65.05450; 3.2615e-002;0.61037
 701.27529;   65.15291; 3.3177e-002;0.60984
 702.26011;   65.25108; 3.3660e-002;0.60931
 703.24493;   65.34913; 3.3855e-002;0.60877
 704.22976;   65.44724; 3.4289e-002;0.60824
 705.21458;   65.54530; 3.4662e-002;0.60770
 706.19940;   65.64318; 3.5005e-002;0.60717
 707.18422;   65.74104; 3.4235e-002;0.60664
 708.16904;   65.83908; 3.4277e-002;0.60610
 709.15387;   65.93727; 3.4230e-002;0.60557
 710.13869;   66.03547; 3.4564e-002;0.60504
 711.12351;   66.13368; 3.4723e-002;0.60450
 712.10833;   66.23204; 3.5129e-002;0.60397
 713.09316;   66.33054; 3.5754e-002;0.60344
 714.07798;   66.42888; 3.5655e-002;0.60291
 715.06280;   66.52723; 3.6252e-002;0.60238
 716.04762;   66.62586; 3.6510e-002;0.60185
 717.03244;   66.72435; 3.6850e-002;0.60131
 718.01727;   66.82249; 3.7515e-002;0.60078
 719.00209;   66.92063; 3.7993e-002;0.60025
 719.98691;   67.01904; 3.8141e-002;0.59972
 720.97173;   67.11752; 3.8503e-002;0.59919
 721.95655;   67.21584; 3.8824e-002;0.59866
 722.94138;   67.31402; 3.9110e-002;0.59813
 723.92620;   67.41223; 3.9553e-002;0.59760
 724.91102;   67.51054; 3.9952e-002;0.59707
 725.89584;   67.60878; 4.0308e-002;0.59654
 726.88067;   67.70700; 4.0747e-002;0.59601
 727.86549;   67.80531; 4.1021e-002;0.59548
 728.85031;   67.90360; 4.1373e-002;0.59496
 729.83513;   68.00173; 4.1731e-002;0.59443
 730.81995;   68.09988; 4.2110e-002;0.59390
 731.80478;   68.19821; 4.2500e-002;0.59337
 732.78960;   68.29651; 4.2874e-002;0.59284
 733.77442;   68.39468; 4.3358e-002;0.59231
 734.75924;   68.49293; 4.3594e-002;0.59179
 735.74407;   68.59129; 4.4154e-002;0.59126
 736.72889;   68.68979; 4.4234e-002;0.59073
 737.71371;   68.78848; 4.4376e-002;0.59021
 738.69853;   68.88727; 4.4859e-002;0.58968
 739.68335;   68.98609; 4.5160e-002;0.58915
 740.66818;   69.08486; 4.5445e-002;0.58863
 741.65300;   69.18358; 4.5956e-002;0.58810
 742.63782;   69.28218; 4.6432e-002;0.58758
 743.62264;   69.38082; 4.6568e-002;0.58705
 744.60747;   69.47960; 4.7382e-002;0.58653
 745.59229;   69.57823; 4.7922e-002;0.58600
 746.57711;   69.67685; 4.8346e-002;0.58548
 747.56193;   69.77565; 4.8656e-002;0.58495
 748.54675;   69.87441; 4.8888e-002;0.58443
 749.53158;   69.97302; 4.9427e-002;0.58390
 750.51640;   70.07150; 4.9960e-002;0.58338
 751.50122;   70.16998; 5.0190e-002;0.58286
 752.48604;   70.26861; 5.0229e-002;0.58233
 753.47086;   70.36745; 5.0602e-002;0.58181
 754.45569;   70.46630; 5.0734e-002;0.58129
 755.44051;   70.56484; 5.0807e-002;0.58076
 756.42533;   70.66315; 5.1507e-002;0.58024
 757.41015;   70.76150; 5.1520e-002;0.57972
 758.39498;   70.85991; 5.2008e-002;0.57920
 759.37980;   70.95833; 5.2132e-002;0.57868
 760.36462;   71.05670; 5.2536e-002;0.57815
 761.34944;   71.15486; 5.2956e-002;0.57763
 762.33426;   71.25293; 5.2952e-002;0.57711
 763.31909;   71.35128; 5.3232e-002;0.57659
 764.30391;   71.44993; 5.3458e-002;0.57607
 765.28873;   71.54870; 5.3695e-002;0.57555
 766.27355;   71.64751; 5.4031e-002;0.57503
 767.25838;   71.74634; 5.4152e-002;0.57451
 768.24320;   71.84502; 5.4482e-002;0.57399
 769.22802;   71.94347; 5.4665e-002;0.57347
 770.21284;   72.04190; 5.5439e-002;0.57295
 771.19766;   72.14048; 5.5592e-002;0.57243
 772.18249;   72.23904; 5.5847e-002;0.57191
 773.16731;   72.33743; 5.5967e-002;0.57139
 774.15213;   72.43590; 5.6601e-002;0.57088
 775.13695;   72.53464; 5.6518e-002;0.57036
 776.12177;   72.63336; 5.6632e-002;0.56984
 777.10660;   72.73186; 5.6773e-002;0.56932
 778.09142;   72.83028; 5.6991e-002;0.56881
 779.07624;   72.92883; 5.7157e-002;0.56829
 780.06106;   73.02756; 5.7228e-002;0.56777
 781.04589;   73.12629; 5.7540e-002;0.56725
 782.03071;   73.22485; 5.8006e-002;0.56674
 783.01553;   73.32335; 5.8414e-002;0.56622
 784.00035;   73.42190; 5.8234e-002;0.56571
 784.98517;   73.52035; 5.8687e-002;0.56519
 785.97000;   73.61854; 5.8924e-002;0.56467
 786.95482;   73.71662; 5.9211e-002;0.56416
 787.93964;   73.81476; 5.9547e-002;0.56364
 788.92446;   73.91302; 5.9832e-002;0.56313
 789.90929;   74.01141; 6.0040e-002;0.56261
 790.89411;   74.10985; 5.9847e-002;0.56210
 791.87893;   74.20823; 6.0146e-002;0.56159
 792.86375;   74.30663; 6.0265e-002;0.56107
 793.84857;   74.40519; 6.0454e-002;0.56056
 794.83340;   74.50389; 6.0637e-002;0.56005
 795.81822;   74.60258; 6.0734e-002;0.55953
 796.80304;   74.70120; 6.0728e-002;0.55902
 797.78786;   74.79984; 6.0755e-002;0.55851
 798.77269;   74.89860; 6.0762e-002;0.55799
 799.75751;   74.99734; 6.0888e-002;0.55748
 800.74233;   75.09599; 6.1131e-002;0.55697
 801.72715;   75.19470; 6.1424e-002;0.55646
 802.71197;   75.29329; 6.1460e-002;0.55595
 803.69680;   75.39161; 6.1634e-002;0.55544
 804.68162;   75.48997; 6.1954e-002;0.55493
 805.66644;   75.58853; 6.1940e-002;0.55441
 806.65126;   75.68708; 6.2161e-002;0.55390
 807.63608;   75.78543; 6.2358e-002;0.55339
 808.62091;   75.88378; 6.2571e-002;0.55288
 809.60573;   75.98222; 6.2977e-002;0.55237
 810.59055;   76.08054; 6.2818e-002;0.55186
 811.57537;   76.17882; 6.3156e-002;0.55136
 812.56020;   76.27726; 6.3257e-002;0.55085
 813.54502;   76.37591; 6.3139e-002;0.55034
 814.52984;   76.47465; 6.3333e-002;0.54983
 815.51466;   76.57334; 6.3737e-002;0.54932
 816.49948;   76.67182; 6.4017e-002;0.54881
 817.48431;   76.77008; 6.4167e-002;0.54830
 818.46913;   76.86844; 6.4465e-002;0.54780
 819.45395;   76.96692; 6.4458e-002;0.54729
 820.43877;   77.06531; 6.4563e-002;0.54678
 821.42360;   77.16354; 6.4820e-002;0.54628
 822.40842;   77.26156; 6.4971e-002;0.54577
 823.39324;   77.35944; 6.5284e-002;0.54526
 824.37806;   77.45720; 6.5470e-002;0.54476
 825.36288;   77.55492; 6.5578e-002;0.54425
 826.34771;   77.65286; 6.5649e-002;0.54375
 827.33253;   77.75113; 6.5936e-002;0.54324
 828.31735;   77.84952; 6.6009e-002;0.54273
 829.30217;   77.94785; 6.6327e-002;0.54223
 830.28700;   78.04621; 6.6840e-002;0.54173
 831.27182;   78.14461; 6.7061e-002;0.54122
 832.25664;   78.24294; 6.6895e-002;0.54072
 833.24146;   78.34132; 6.7489e-002;0.54021
 834.22628;   78.43978; 6.7827e-002;0.53971
 835.21111;   78.53823; 6.8167e-002;0.53921
 836.19593;   78.63669; 6.8638e-002;0.53870
 837.18075;   78.73525; 6.8542e-002;0.53820
 838.16557;   78.83375; 6.8915e-002;0.53770
 839.15039;   78.93206; 6.8924e-002;0.53719
 840.13522;   79.03033; 6.9039e-002;0.53669
 841.12004;   79.12871; 6.8925e-002;0.53619
 842.10486;   79.22725; 6.8781e-002;0.53569
 843.08968;   79.32589; 6.8923e-002;0.53519
 844.07451;   79.42459; 6.9391e-002;0.53469
 845.05933;   79.52323; 6.9539e-002;0.53419
 846.04415;   79.62175; 7.0043e-002;0.53368
 847.02897;   79.72027; 7.0189e-002;0.53318
 848.01379;   79.81881; 7.0343e-002;0.53268
 848.99862;   79.91739; 7.0071e-002;0.53218
 849.98344;   80.01603; 6.9942e-002;0.53168
 850.96826;   80.11459; 7.0171e-002;0.53119
 851.95308;   80.21297; 7.0398e-002;0.53069
 852.93791;   80.31118; 7.0489e-002;0.53019
 853.92273;   80.40951; 7.0329e-002;0.52969
 854.90755;   80.50799; 7.0821e-002;0.52919
 855.89237;   80.60654; 7.0809e-002;0.52869
 856.87719;   80.70522; 7.1129e-002;0.52819
 857.86202;   80.80391; 7.0964e-002;0.52770
 858.84684;   80.90254; 7.0838e-002;0.52720
 859.83166;   81.00131; 7.0674e-002;0.52670
 860.81648;   81.10009; 7.0870e-002;0.52620
 861.80131;   81.19877; 7.0741e-002;0.52571
 862.78613;   81.29761; 7.0758e-002;0.52521
 863.77095;   81.39658; 7.1046e-002;0.52472
 864.75577;   81.49535; 7.1133e-002;0.52422
 865.74059;   81.59392; 7.1408e-002;0.52372
 866.72542;   81.69246; 7.1621e-002;0.52323
 867.71024;   81.79107; 7.1403e-002;0.52273
 868.69506;   81.88971; 7.1485e-002;0.52224
 869.67988;   81.98831; 7.1545e-002;0.52174
 870.66470;   82.08679; 7.1721e-002;0.52125
 871.64953;   82.18511; 7.2128e-002;0.52076
 872.63435;   82.28327; 7.2236e-002;0.52026
 873.61917;   82.38136; 7.2518e-002;0.51977
 874.60399;   82.47956; 7.2791e-002;0.51927
 875.58882;   82.57780; 7.2970e-002;0.51878
 876.57364;   82.67586; 7.3164e-002;0.51829
 877.55846;   82.77395; 7.3546e-002;0.51780
 878.54328;   82.87222; 7.3864e-002;0.51730
 879.52810;   82.97038; 7.3814e-002;0.51681
 880.51293;   83.06856; 7.4275e-002;0.51632
 881.49775;   83.16703; 7.4491e-002;0.51583
 882.48257;   83.26564; 7.4652e-002;0.51534
 883.46739;   83.36419; 7.4523e-002;0.51484
 884.45222;   83.46274; 7.4363e-002;0.51435
 885.43704;   83.56147; 7.4497e-002;0.51386
 886.42186;   83.66020; 7.4255e-002;0.51337
 887.40668;   83.75883; 7.4189e-002;0.51288
 888.39150;   83.85739; 7.3736e-002;0.51239
 889.37633;   83.95593; 7.3741e-002;0.51190
 890.36115;   84.05443; 7.3449e-002;0.51141
 891.34597;   84.15283; 7.2858e-002;0.51092
 892.33079;   84.25123; 7.3014e-002;0.51044
 893.31562;   84.34969; 7.2873e-002;0.50995
 894.30044;   84.44814; 7.2559e-002;0.50946
 895.28526;   84.54651; 7.2211e-002;0.50897
 896.27008;   84.64469; 7.1804e-002;0.50848
 897.25490;   84.74276; 7.1834e-002;0.50800
 898.23973;   84.84104; 7.1198e-002;0.50751
 899.22455;   84.93953; 7.0759e-002;0.50702
 900.20937;   85.03780; 7.0415e-002;0.50653
 901.19419;   85.13569; 7.0373e-002;0.50605
 902.17901;   85.23334; 7.0296e-002;0.50556
 903.16384;   85.33081; 7.0074e-002;0.50508
 904.14866;   85.42820; 6.9665e-002;0.50459
 905.13348;   85.52567; 6.9746e-002;0.50410
 906.11830;   85.62335; 6.9259e-002;0.50362
 907.10313;   85.72121; 6.8573e-002;0.50313
 908.08795;   85.81916; 6.7776e-002;0.50265
 909.07277;   85.91734; 6.7034e-002;0.50216
 910.05759;   86.01577; 6.6261e-002;0.50168
 911.04241;   86.11425; 6.5643e-002;0.50120
 912.02724;   86.21271; 6.4959e-002;0.50071
 913.01206;   86.31119; 6.4196e-002;0.50023
 913.99688;   86.40979; 6.3546e-002;0.49975
 914.98170;   86.50860; 6.2843e-002;0.49926
 915.96653;   86.60754; 6.2192e-002;0.49878
 916.95135;   86.70637; 6.1461e-002;0.49830
 917.93617;   86.80501; 6.0745e-002;0.49781
 918.92099;   86.90371; 6.0595e-002;0.49733
 919.90581;   87.00252; 6.0018e-002;0.49685
 920.89064;   87.10117; 5.9335e-002;0.49637
 921.87546;   87.19963; 5.8724e-002;0.49589
 922.86028;   87.29802; 5.8091e-002;0.49541
 923.84510;   87.39636; 5.7700e-002;0.49493
 924.82992;   87.49476; 5.6996e-002;0.49445
 925.81475;   87.59329; 5.6235e-002;0.49397
 926.79957;   87.69191; 5.5731e-002;0.49349
 927.78439;   87.79060; 5.4701e-002;0.49301
 928.76921;   87.88925; 5.4041e-002;0.49253
 929.75404;   87.98774; 5.3541e-002;0.49205
 930.73886;   88.08617; 5.3000e-002;0.49157
 931.72368;   88.18470; 5.1945e-002;0.49109
 932.70850;   88.28333; 5.1462e-002;0.49061
 933.69332;   88.38185; 5.0864e-002;0.49013
 934.67815;   88.48008; 5.0163e-002;0.48965
 935.66297;   88.57816; 4.9423e-002;0.48918
 936.64779;   88.67629; 4.8772e-002;0.48870
 937.63261;   88.77445; 4.7688e-002;0.48822
 938.61744;   88.87258; 4.6994e-002;0.48775
 939.60226;   88.97064; 4.6465e-002;0.48727
 940.58708;   89.06864; 4.5974e-002;0.48679
 941.57190;   89.16657; 4.5250e-002;0.48632
 942.55672;   89.26455; 4.4523e-002;0.48584
 943.54155;   89.36275; 4.3638e-002;0.48536
 944.52637;   89.46104; 4.3038e-002;0.48489
 945.51119;   89.55934; 4.2271e-002;0.48441
 946.49601;   89.65784; 4.1535e-002;0.48394
 947.48084;   89.75655; 4.0529e-002;0.48346
 948.46566;   89.85537; 4.0086e-002;0.48299
 949.45048;   89.95426; 3.9501e-002;0.48252
 950.43530;   90.05311; 3.8490e-002;0.48204
 951.42012;   90.15204; 3.7856e-002;0.48157
 952.40495;   90.25110; 3.6838e-002;0.48110
 953.38977;   90.34996; 3.6354e-002;0.48062
 954.37459;   90.44874; 3.5489e-002;0.48015
 955.35941;   90.54774; 3.5144e-002;0.47968
 956.34423;   90.64681; 3.4537e-002;0.47920
 957.32906;   90.74575; 3.3605e-002;0.47873
 958.31388;   90.84458; 3.3029e-002;0.47826
 959.29870;   90.94329; 3.2546e-002;0.47779
 960.28352;   91.04181; 3.2013e-002;0.47732
 961.26835;   91.14032; 3.1224e-002;0.47685
 962.25317;   91.23906; 3.0986e-002;0.47638
 963.23799;   91.33791; 3.0672e-002;0.47591
 964.22281;   91.43667; 3.0460e-002;0.47543
 965.20763;   91.53527; 3.0406e-002;0.47496
 966.19246;   91.63369; 2.9879e-002;0.47449
 967.17728;   91.73203; 2.9855e-002;0.47403
 968.16210;   91.83040; 2.9556e-002;0.47356
 969.14692;   91.92882; 2.9430e-002;0.47309
 970.13175;   92.02728; 2.9045e-002;0.47262
 971.11657;   92.12570; 2.8802e-002;0.47215
 972.10139;   92.22408; 2.8229e-002;0.47168
 973.08621;   92.32252; 2.8772e-002;0.47121
 974.07103;   92.42098; 2.9093e-002;0.47075
 975.05586;   92.51950; 2.9246e-002;0.47028
 976.04068;   92.61820; 2.9747e-002;0.46981
 977.02550;   92.71688; 3.0212e-002;0.46934
 978.01032;   92.81540; 3.0755e-002;0.46888
 978.99515;   92.91394; 3.1393e-002;0.46841
 979.97997;   93.01252; 3.2577e-002;0.46794
 980.96479;   93.11104; 3.3598e-002;0.46748
 981.94961;   93.20960; 3.5100e-002;0.46701
 982.93443;   93.30820; 3.6462e-002;0.46655
 983.91926;   93.40668; 3.7885e-002;0.46608
 984.90408;   93.50493; 3.9918e-002;0.46562
 985.88890;   93.60308; 4.1841e-002;0.46515
 986.87372;   93.70139; 4.4287e-002;0.46469
 987.85854;   93.79983; 4.6095e-002;0.46422
 988.84337;   93.89814; 4.8194e-002;0.46376
 989.82819;   93.99631; 4.9601e-002;0.46330
 990.81301;   94.09447; 5.0948e-002;0.46283
 991.79783;   94.19266; 5.1781e-002;0.46237
 992.78266;   94.29100; 5.2333e-002;0.46191
 993.76748;   94.38936; 5.2580e-002;0.46144
 994.75230;   94.48761; 5.2840e-002;0.46098
 995.73712;   94.58584; 5.2842e-002;0.46052
 996.72194;   94.68419; 5.2651e-002;0.46006
 997.70677;   94.78264; 5.2402e-002;0.45959
 998.69159;   94.88119; 5.2322e-002;0.45913
 999.67641;   94.97983; 5.2255e-002;0.45867
1000.66123;   95.07843; 5.1646e-002;0.45821
1001.64606;   95.17689; 5.1700e-002;0.45775
1002.63088;   95.27520; 5.1283e-002;0.45729
1003.61570;   95.37355; 5.1025e-002;0.45683
1004.60052;   95.47213; 5.0634e-002;0.45637
1005.58534;   95.57088; 5.0385e-002;0.45591
1006.57017;   95.66961; 5.0134e-002;0.45545
1007.55499;   95.76834; 4.9930e-002;0.45499
1008.53981;   95.86725; 4.9811e-002;0.45453
1009.52463;   95.96611; 5.0016e-002;0.45407
1010.50946;   96.06474; 5.0222e-002;0.45362
1011.49428;   96.16333; 5.0248e-002;0.45316
1012.47910;   96.26207; 5.0567e-002;0.45270
1013.46392;   96.36093; 5.0653e-002;0.45224
1014.44874;   96.45968; 5.1013e-002;0.45178
1015.43357;   96.55829; 5.1039e-002;0.45133
1016.41839;   96.65695; 5.1292e-002;0.45087
1017.40321;   96.75559; 5.2027e-002;0.45041
1018.38803;   96.85410; 5.2634e-002;0.44996
1019.37285;   96.95242; 5.3038e-002;0.44950
1020.35768;   97.05056; 5.4116e-002;0.44905
1021.34250;   97.14861; 5.5320e-002;0.44859
1022.32732;   97.24684; 5.6694e-002;0.44813
1023.31214;   97.34520; 5.7710e-002;0.44768
1024.29697;   97.44323; 5.9369e-002;0.44722
1025.28179;   97.54103; 6.1020e-002;0.44677
1026.26661;   97.63900; 6.2428e-002;0.44632
1027.25143;   97.73705; 6.4521e-002;0.44586
1028.23625;   97.83505; 6.6391e-002;0.44541
1029.22108;   97.93313; 6.8610e-002;0.44495
1030.20590;   98.03132; 7.0847e-002;0.44450
1031.19072;   98.12951; 7.2579e-002;0.44405
1032.17554;   98.22767; 7.4764e-002;0.44359
1033.16037;   98.32597; 7.6587e-002;0.44314
1034.14519;   98.42453; 7.8481e-002;0.44269
1035.13001;   98.52313; 8.0442e-002;0.44224
1036.11483;   98.62165; 8.1608e-002;0.44178
1037.09965;   98.72019; 8.3310e-002;0.44133
1038.08448;   98.81876; 8.4351e-002;0.44088
1039.06930;   98.91723; 8.5830e-002;0.44043
1040.05412;   99.01570; 8.7101e-002;0.43998
1041.03894;   99.11427; 8.7838e-002;0.43953
1042.02377;   99.21284; 8.8059e-002;0.43908
1043.00859;   99.31129; 8.8207e-002;0.43863
1043.99341;   99.40975; 8.8557e-002;0.43818
1044.97823;   99.50832; 8.8803e-002;0.43773
1045.96305;   99.60684; 8.9290e-002;0.43728
1046.94788;   99.70535; 8.9467e-002;0.43683
1047.93270;   99.80404; 8.9981e-002;0.43638
1048.91752;   99.90291; 8.9904e-002;0.43593
1049.90234;  100.00172; 9.0697e-002;0.43548
1050.88716;  100.10034; 9.1111e-002;0.43504
1051.87199;  100.19894; 9.1681e-002;0.43459
1052.85681;  100.29762; 9.1672e-002;0.43414
1053.84163;  100.39629; 9.1846e-002;0.43369
1054.82645;  100.49489; 9.1935e-002;0.43325
1055.81128;  100.59352; 9.2315e-002;0.43280
1056.79610;  100.69215; 9.2828e-002;0.43235
1057.78092;  100.79069; 9.3341e-002;0.43191
1058.76574;  100.88923; 9.3747e-002;0.43146
1059.75056;  100.98786; 9.3816e-002;0.43101
1060.73539;  101.08645; 9.4047e-002;0.43057
1061.72021;  101.18481; 9.4488e-002;0.43012
1062.70503;  101.28306; 9.4918e-002;0.42968
1063.68985;  101.38137; 9.5134e-002;0.42923
1064.67468;  101.47970; 9.5113e-002;0.42879
1065.65950;  101.57799; 9.5768e-002;0.42834
1066.64432;  101.67635; 9.6076e-002;0.42790
1067.62914;  101.77473; 9.6348e-002;0.42746
1068.61396;  101.87302; 9.6373e-002;0.42701
1069.59879;  101.97130; 9.6869e-002;0.42657
1070.58361;  102.06960; 9.7440e-002;0.42613
1071.56843;  102.16788; 9.7694e-002;0.42568
1072.55325;  102.26613; 9.8042e-002;0.42524
1073.53808;  102.36453; 9.8514e-002;0.42480
1074.52290;  102.46329; 9.8964e-002;0.42436
1075.50772;  102.56211; 9.8975e-002;0.42391
1076.49254;  102.66069; 9.9502e-002;0.42347
1077.47736;  102.75913;     0.10005;0.42303
1078.46219;  102.85758;     0.10041;0.42259
1079.44701;  102.95606;     0.10093;0.42215
1080.43183;  103.05456;     0.10069;0.42171
1081.41665;  103.15316;     0.10084;0.42127
1082.40147;  103.25181;     0.10130;0.42083
1083.38630;  103.35032;     0.10169;0.42039
1084.37112;  103.44872;     0.10219;0.41995
1085.35594;  103.54720;     0.10282;0.41951
1086.34076;  103.64572;     0.10350;0.41907
1087.32559;  103.74423;     0.10412;0.41863
1088.31041;  103.84276;     0.10395;0.41819
1089.29523;  103.94132;     0.10390;0.41775
1090.28005;  104.03987;     0.10407;0.41731
1091.26487;  104.13841;     0.10481;0.41688
1092.24970;  104.23690;     0.10524;0.41644
1093.23452;  104.33533;     0.10582;0.41600
1094.21934;  104.43380;     0.10626;0.41556
1095.20416;  104.53226;     0.10645;0.41513
1096.18899;  104.63081;     0.10730;0.41469
1097.17381;  104.72944;     0.10767;0.41425
1098.15863;  104.82794;     0.10863;0.41382
1099.14345;  104.92633;     0.10940;0.41338
1099.80000;  104.99245;     0.10996;0.41309